Workbook

Sheet Hdsmth
A1: mrtot | B1: ss1 | C1: ss2 | D1: ss3 | E1: ss4 | F1: ss5 | G1: ss6 | H1: ss7 | I1: ss8 | J1: ss9 | K1: ss10 | L1: ss11 | M1: ss12 | N1: ss13 | O1: ReverseCross | P1: c1_2 | Q1: c2_3 | R1: c3_4 | S1: c4_5 | T1: c5_6 | U1: c6_7 | V1: c7_8 | W1: c8_9 | X1: c9_10 | Y1: c10_11 | Z1: c11_12 | AA1: c12_13 | AB1: ReverseDown | AC1: d1 | AD1: d2 | AE1: d3 | AF1: d4 | AG1: d5 | AH1: d6 | AI1: d7 | AJ1: d8 | AK1: d9 | AL1: d10 | AM1: d11 | AN1: d12 | AO1: d13 | AP1: QA
A2: 0 | B2: 1 | C2: 1 | D2: 1 | E2: 1 | F2: 1 | G2: 1 | H2: 1 | I2: 1 | J2: 1 | K2: 1 | L2: 1 | M2: 1 | N2: 1 | P2: =B2-C2 -> 0 | Q2: =C2-D2 -> 0 | R2: =D2-E2 -> 0 | S2: =E2-F2 -> 0 | T2: =F2-G2 -> 0 | U2: =G2-H2 -> 0 | V2: =H2-I2 -> 0 | W2: =I2-J2 -> 0 | ... AA2: =M2-N2 -> 0 | AC2: =B3-B2 -> 0 | AD2: =C3-C2 -> 0 | AE2: =D3-D2 -> 0 | AF2: =E3-E2 -> 1 | AG2: =F3-F2 -> 1 | AH2: =G3-G2 -> 1 | AI2: =H3-H2 -> 1 | AJ2: =I3-I2 -> 1 | ... AO2: =N3-N2 -> 0 | AP2: RIGHT
A3: 1 | B3: 1 | C3: 1 | D3: 1 | E3: 2 | F3: 2 | G3: 2 | H3: 2 | I3: 2 | J3: 3 | K3: 3 | L3: 2 | M3: 1 | N3: 1 | P3: =B3-C3 -> 0 | Q3: =C3-D3 -> 0 | R3: =D3-E3 -> -1 | S3: =E3-F3 -> 0 | T3: =F3-G3 -> 0 | U3: =G3-H3 -> 0 | V3: =H3-I3 -> 0 | W3: =I3-J3 -> -1 | ... AA3: =M3-N3 -> 0 | AC3: =B4-B3 -> 1 | AD3: =C4-C3 -> 1 | AE3: =D4-D3 -> 1 | AF3: =E4-E3 -> 0 | AG3: =F4-F3 -> 0 | AH3: =G4-G3 -> 0 | AI3: =H4-H3 -> 1 | AJ3: =I4-I3 -> 1 | ... AO3: =N4-N3 -> 3 | AP3: RIGHT
A4: 2 | B4: 2 | C4: 2 | D4: 2 | E4: 2 | F4: 2 | G4: 2 | H4: 3 | I4: 3 | J4: 3 | K4: 3 | L4: 3 | M4: 3 | N4: 4 | P4: =B4-C4 -> 0 | Q4: =C4-D4 -> 0 | R4: =D4-E4 -> 0 | S4: =E4-F4 -> 0 | T4: =F4-G4 -> 0 | U4: =G4-H4 -> -1 | V4: =H4-I4 -> 0 | W4: =I4-J4 -> 0 | ... AA4: =M4-N4 -> -1 | AC4: =B5-B4 -> 0 | AD4: =C5-C4 -> 0 | AE4: =D5-D4 -> 0 | AF4: =E5-E4 -> 1 | AG4: =F5-F4 -> 1 | AH4: =G5-G4 -> 1 | AI4: =H5-H4 -> 0 | AJ4: =I5-I4 -> 0 | ... AO4: =N5-N4 -> 2 | AP4: RIGHT
A5: 3 | B5: 2 | C5: 2 | D5: 2 | E5: 3 | F5: 3 | G5: 3 | H5: 3 | I5: 3 | J5: 4 | K5: 4 | L5: 4 | M5: 5 | N5: 6 | P5: =B5-C5 -> 0 | Q5: =C5-D5 -> 0 | R5: =D5-E5 -> -1 | S5: =E5-F5 -> 0 | T5: =F5-G5 -> 0 | U5: =G5-H5 -> 0 | V5: =H5-I5 -> 0 | W5: =I5-J5 -> -1 | ... AA5: =M5-N5 -> -1 | AC5: =B6-B5 -> 1 | AD5: =C6-C5 -> 1 | AE5: =D6-D5 -> 1 | AF5: =E6-E5 -> 0 | AG5: =F6-F5 -> 0 | AH5: =G6-G5 -> 0 | AI5: =H6-H5 -> 1 | AJ5: =I6-I5 -> 1 | ... AO5: =N6-N5 -> 1 | AP5: RIGHT
A6: 4 | B6: 3 | C6: 3 | D6: 3 | E6: 3 | F6: 3 | G6: 3 | H6: 4 | I6: 4 | J6: 4 | K6: 5 | L6: 5 | M6: 6 | N6: 7 | P6: =B6-C6 -> 0 | Q6: =C6-D6 -> 0 | R6: =D6-E6 -> 0 | S6: =E6-F6 -> 0 | T6: =F6-G6 -> 0 | U6: =G6-H6 -> -1 | V6: =H6-I6 -> 0 | W6: =I6-J6 -> 0 | ... AA6: =M6-N6 -> -1 | AC6: =B7-B6 -> 0 | AD6: =C7-C6 -> 0 | AE6: =D7-D6 -> 0 | AF6: =E7-E6 -> 0 | AG6: =F7-F6 -> 1 | AH6: =G7-G6 -> 1 | AI6: =H7-H6 -> 0 | AJ6: =I7-I6 -> 0 | ... AO6: =N7-N6 -> 0 | AP6: RIGHT
A7: 5 | B7: 3 | C7: 3 | D7: 3 | E7: 3 | F7: 4 | G7: 4 | H7: 4 | I7: 4 | J7: 5 | K7: 5 | L7: 6 | M7: 6 | N7: 7 | P7: =B7-C7 -> 0 | Q7: =C7-D7 -> 0 | R7: =D7-E7 -> 0 | S7: =E7-F7 -> -1 | T7: =F7-G7 -> 0 | U7: =G7-H7 -> 0 | V7: =H7-I7 -> 0 | W7: =I7-J7 -> -1 | ... AA7: =M7-N7 -> -1 | AC7: =B8-B7 -> 1 | AD7: =C8-C7 -> 1 | AE7: =D8-D7 -> 1 | AF7: =E8-E7 -> 1 | AG7: =F8-F7 -> 0 | AH7: =G8-G7 -> 0 | AI7: =H8-H7 -> 0 | AJ7: =I8-I7 -> 1 | ... AO7: =N8-N7 -> 1 | AP7: RIGHT
A8: 6 | B8: 4 | C8: 4 | D8: 4 | E8: 4 | F8: 4 | G8: 4 | H8: 4 | I8: 5 | J8: 5 | K8: 6 | L8: 6 | M8: 7 | N8: 8 | P8: =B8-C8 -> 0 | Q8: =C8-D8 -> 0 | R8: =D8-E8 -> 0 | S8: =E8-F8 -> 0 | T8: =F8-G8 -> 0 | U8: =G8-H8 -> 0 | V8: =H8-I8 -> -1 | W8: =I8-J8 -> 0 | ... AA8: =M8-N8 -> -1 | AC8: =B9-B8 -> 0 | AD8: =C9-C8 -> 0 | AE8: =D9-D8 -> 0 | AF8: =E9-E8 -> 0 | AG8: =F9-F8 -> 0 | AH8: =G9-G8 -> 1 | AI8: =H9-H8 -> 1 | AJ8: =I9-I8 -> 0 | ... AO8: =N9-N8 -> 1 | AP8: RIGHT
A9: 7 | B9: 4 | C9: 4 | D9: 4 | E9: 4 | F9: 4 | G9: 5 | H9: 5 | I9: 5 | J9: 6 | K9: 6 | L9: 7 | M9: 8 | N9: 9 | P9: =B9-C9 -> 0 | Q9: =C9-D9 -> 0 | R9: =D9-E9 -> 0 | S9: =E9-F9 -> 0 | T9: =F9-G9 -> -1 | U9: =G9-H9 -> 0 | V9: =H9-I9 -> 0 | W9: =I9-J9 -> -1 | ... AA9: =M9-N9 -> -1 | AC9: =B10-B9 -> 1 | AD9: =C10-C9 -> 1 | AE9: =D10-D9 -> 1 | AF9: =E10-E9 -> 1 | AG9: =F10-F9 -> 1 | AH9: =G10-G9 -> 0 | AI9: =H10-H9 -> 0 | AJ9: =I10-I9 -> 1 | ... AO9: =N10-N9 -> 0 | AP9: RIGHT
A10: 8 | B10: 5 | C10: 5 | D10: 5 | E10: 5 | F10: 5 | G10: 5 | H10: 5 | I10: 6 | J10: 7 | K10: 7 | L10: 8 | M10: 9 | N10: 9 | P10: =B10-C10 -> 0 | Q10: =C10-D10 -> 0 | R10: =D10-E10 -> 0 | S10: =E10-F10 -> 0 | T10: =F10-G10 -> 0 | U10: =G10-H10 -> 0 | V10: =H10-I10 -> -1 | W10: =I10-J10 -> -1 | ... AA10: =M10-N10 -> 0 | AC10: =B11-B10 -> 0 | AD10: =C11-C10 -> 0 | AE10: =D11-D10 -> 0 | AF10: =E11-E10 -> 0 | AG10: =F11-F10 -> 0 | AH10: =G11-G10 -> 1 | AI10: =H11-H10 -> 1 | AJ10: =I11-I10 -> 1 | ... AO10: =N11-N10 -> 1 | AP10: RIGHT
A11: 9 | B11: 5 | C11: 5 | D11: 5 | E11: 5 | F11: 5 | G11: 6 | H11: 6 | I11: 7 | J11: 7 | K11: 8 | L11: 8 | M11: 9 | N11: 10 | P11: =B11-C11 -> 0 | Q11: =C11-D11 -> 0 | R11: =D11-E11 -> 0 | S11: =E11-F11 -> 0 | T11: =F11-G11 -> -1 | U11: =G11-H11 -> 0 | V11: =H11-I11 -> -1 | W11: =I11-J11 -> 0 | ... AA11: =M11-N11 -> -1 | AC11: =B12-B11 -> 1 | AD11: =C12-C11 -> 1 | AE11: =D12-D11 -> 1 | AF11: =E12-E11 -> 1 | AG11: =F12-F11 -> 1 | AH11: =G12-G11 -> 0 | AI11: =H12-H11 -> 1 | AJ11: =I12-I11 -> 0 | ... AO11: =N12-N11 -> 0 | AP11: RIGHT
A12: 10 | B12: 6 | C12: 6 | D12: 6 | E12: 6 | F12: 6 | G12: 6 | H12: 7 | I12: 7 | J12: 8 | K12: 8 | L12: 9 | M12: 10 | N12: 10 | P12: =B12-C12 -> 0 | Q12: =C12-D12 -> 0 | R12: =D12-E12 -> 0 | S12: =E12-F12 -> 0 | T12: =F12-G12 -> 0 | U12: =G12-H12 -> -1 | V12: =H12-I12 -> 0 | W12: =I12-J12 -> -1 | ... AA12: =M12-N12 -> 0 | AC12: =B13-B12 -> 1 | AD12: =C13-C12 -> 1 | AE12: =D13-D12 -> 0 | AF12: =E13-E12 -> 0 | AG12: =F13-F12 -> 1 | AH12: =G13-G12 -> 1 | AI12: =H13-H12 -> 0 | AJ12: =I13-I12 -> 1 | ... AO12: =N13-N12 -> 1 | AP12: RIGHT
A13: 11 | B13: 7 | C13: 7 | D13: 6 | E13: 6 | F13: 7 | G13: 7 | H13: 7 | I13: 8 | J13: 8 | K13: 9 | L13: 10 | M13: 10 | N13: 11 | P13: =B13-C13 -> 0 | Q13: =C13-D13 -> 1 | R13: =D13-E13 -> 0 | S13: =E13-F13 -> -1 | T13: =F13-G13 -> 0 | U13: =G13-H13 -> 0 | V13: =H13-I13 -> -1 | W13: =I13-J13 -> 0 | ... AA13: =M13-N13 -> -1 | AC13: =B14-B13 -> 0 | AD13: =C14-C13 -> 0 | AE13: =D14-D13 -> 1 | AF13: =E14-E13 -> 1 | AG13: =F14-F13 -> 0 | AH13: =G14-G13 -> 0 | AI13: =H14-H13 -> 1 | AJ13: =I14-I13 -> 0 | ... AO13: =N14-N13 -> 0 | AP13: RIGHT
... A27: 25 | B27: 17 | C27: 17 | D27: 17 | E27: 16 | F27: 16 | G27: 17 | H27: 19 | I27: 19 | J27: 18 | K27: 17 | L27: 17 | M27: 18 | N27: 18 | P27: =B27-C27 -> 0 | Q27: =C27-D27 -> 0 | R27: =D27-E27 -> 1 | S27: =E27-F27 -> 0 | T27: =F27-G27 -> -1 | U27: =G27-H27 -> -2 | V27: =H27-I27 -> 0 | W27: =I27-J27 -> 1 | ... AA27: =M27-N27 -> 0 | AC27: =B28-B27 -> 2 | AD27: =C28-C27 -> 2 | AE27: =D28-D27 -> 2 | AF27: =E28-E27 -> 2 | AG27: =F28-F27 -> 3 | AH27: =G28-G27 -> 2 | AI27: =H28-H27 -> 0 | AJ27: =I28-I27 -> 0 | ... AO27: =N28-N27 -> 1 | AP27: RIGHT
A28: 26 | B28: 19 | C28: 19 | D28: 19 | E28: 18 | F28: 19 | G28: 19 | H28: 19 | I28: 19 | J28: 19 | K28: 19 | L28: 19 | M28: 19 | N28: 19 | P28: =B28-C28 -> 0 | Q28: =C28-D28 -> 0 | R28: =D28-E28 -> 1 | S28: =E28-F28 -> -1 | T28: =F28-G28 -> 0 | U28: =G28-H28 -> 0 | V28: =H28-I28 -> 0 | W28: =I28-J28 -> 0 | ... AA28: =M28-N28 -> 0 | AP28: RIGHT
A29: N | B29: =SUM(freq!B2:B28) -> 88.165873 | C29: =SUM(freq!C2:C28) -> 79.973924 | D29: =SUM(freq!D2:D28) -> 85.254461 | E29: =SUM(freq!E2:E28) -> 82.006186 | F29: =SUM(freq!F2:F28) -> 84.014426 | G29: =SUM(freq!G2:G28) -> 85.731536 | H29: =SUM(freq!H2:H28) -> 83.185878 | I29: =SUM(freq!I2:I28) -> 89.949547 | ... N29: =SUM(freq!N2:N28) -> 33 | O29: =SUM(B29:N29) -> 1009.2818
A30: MEAN | B30: =freq!B29/B29 -> 9.321253 | C30: =freq!C29/C29 -> 10.530034 | D30: =freq!D29/D29 -> 10.105592 | E30: =freq!E29/E29 -> 9.8165083 | F30: =freq!F29/F29 -> 10.094745 | G30: =freq!G29/G29 -> 9.5419319 | H30: =freq!H29/H29 -> 9.884317 | I30: =freq!I29/I29 -> 9.9989145 | ... O30: =freq!O29/O29 -> 9.9597698
A31: SD | B31: =SQRT((freq!B30-B30^2*B29)/(B29-1)) -> 3.1097966 | C31: =SQRT((freq!C30-C30^2*C29)/(C29-1)) -> 2.8239035 | D31: =SQRT((freq!D30-D30^2*D29)/(D29-1)) -> 2.4539056 | E31: =SQRT((freq!E30-E30^2*E29)/(E29-1)) -> 3.1802863 | F31: =SQRT((freq!F30-F30^2*F29)/(F29-1)) -> 2.9720485 | G31: =SQRT((freq!G30-G30^2*G29)/(G29-1)) -> 2.550384 | H31: =SQRT((freq!H30-H30^2*H29)/(H29-1)) -> 2.9166461 | I31: =SQRT((freq!I30-I30^2*I29)/(I29-1)) -> 2.7771903 | ... O31: =SQRT((freq!O30-O30^2*O29)/(O29-1)) -> 2.9081298
A32: IDEALm | B32: =0.3-ABS(10-ROUND(B30,2)) -> -0.38 | C32: =0.3-ABS(10-ROUND(C30,2)) -> -0.23 | D32: =0.3-ABS(10-ROUND(D30,2)) -> 0.19 | E32: =0.3-ABS(10-ROUND(E30,2)) -> 0.12 | F32: =0.3-ABS(10-ROUND(F30,2)) -> 0.21 | G32: =0.3-ABS(10-ROUND(G30,2)) -> -0.16 | H32: =0.3-ABS(10-ROUND(H30,2)) -> 0.18 | I32: =0.3-ABS(10-ROUND(I30,2)) -> 0.3 | ... O32: =0.3-ABS(10-ROUND(O30,2)) -> 0.26
A33: IDEALs | B33: =0.3-ABS(3-ROUND(B31,2)) -> 0.19 | C33: =0.3-ABS(3-ROUND(C31,2)) -> 0.12 | D33: =0.3-ABS(3-ROUND(D31,2)) -> -0.25 | E33: =0.3-ABS(3-ROUND(E31,2)) -> 0.12 | F33: =0.3-ABS(3-ROUND(F31,2)) -> 0.27 | G33: =0.3-ABS(3-ROUND(G31,2)) -> -0.15 | H33: =0.3-ABS(3-ROUND(H31,2)) -> 0.22 | I33: =0.3-ABS(3-ROUND(I31,2)) -> 0.08 | ... O33: =0.3-ABS(3-ROUND(O31,2)) -> 0.21
A34: STANDARDm | B34: =0.6-ABS(10-ROUND(B30,2)) -> -0.08 | C34: =0.6-ABS(10-ROUND(C30,2)) -> 0.07 | D34: =0.6-ABS(10-ROUND(D30,2)) -> 0.49 | E34: =0.6-ABS(10-ROUND(E30,2)) -> 0.42 | F34: =0.6-ABS(10-ROUND(F30,2)) -> 0.51 | G34: =0.6-ABS(10-ROUND(G30,2)) -> 0.14 | H34: =0.6-ABS(10-ROUND(H30,2)) -> 0.48 | I34: =0.6-ABS(10-ROUND(I30,2)) -> 0.6 | ... O34: =0.6-ABS(10-ROUND(O30,2)) -> 0.56
A35: STANDARDs | B35: =0.3-ABS(3-ROUND(B31,2)) -> 0.19 | C35: =0.3-ABS(3-ROUND(C31,2)) -> 0.12 | D35: =0.3-ABS(3-ROUND(D31,2)) -> -0.25 | E35: =0.3-ABS(3-ROUND(E31,2)) -> 0.12 | F35: =0.3-ABS(3-ROUND(F31,2)) -> 0.27 | G35: =0.3-ABS(3-ROUND(G31,2)) -> -0.15 | H35: =0.3-ABS(3-ROUND(H31,2)) -> 0.22 | I35: =0.3-ABS(3-ROUND(I31,2)) -> 0.08 | ... O35: =0.3-ABS(3-ROUND(O31,2)) -> 0.21
A36: EXCEPIONm | B36: =0.9-ABS(10-ROUND(B30,2)) -> 0.22 | C36: =0.9-ABS(10-ROUND(C30,2)) -> 0.37 | D36: =0.9-ABS(10-ROUND(D30,2)) -> 0.79 | E36: =0.9-ABS(10-ROUND(E30,2)) -> 0.72 | F36: =0.9-ABS(10-ROUND(F30,2)) -> 0.81 | G36: =0.9-ABS(10-ROUND(G30,2)) -> 0.44 | H36: =0.9-ABS(10-ROUND(H30,2)) -> 0.78 | I36: =0.9-ABS(10-ROUND(I30,2)) -> 0.9 | ... O36: =0.9-ABS(10-ROUND(O30,2)) -> 0.86
A37: EXCEPIONs | B37: =0.45-ABS(3-ROUND(B31,2)) -> 0.34 | C37: =0.45-ABS(3-ROUND(C31,2)) -> 0.27 | D37: =0.45-ABS(3-ROUND(D31,2)) -> -0.1 | E37: =0.45-ABS(3-ROUND(E31,2)) -> 0.27 | F37: =0.45-ABS(3-ROUND(F31,2)) -> 0.42 | G37: =0.45-ABS(3-ROUND(G31,2)) -> 0 | H37: =0.45-ABS(3-ROUND(H31,2)) -> 0.37 | I37: =0.45-ABS(3-ROUND(I31,2)) -> 0.23 | ... O37: =0.45-ABS(3-ROUND(O31,2)) -> 0.36
A38: N1 | B38: =SUM(freq!B2:B28) -> 88.165873 | C38: =SUM(freq!C2:C28) -> 79.973924 | D38: =SUM(freq!D2:D28) -> 85.254461 | E38: =SUM(freq!E2:E28) -> 82.006186 | F38: =SUM(freq!F2:F28) -> 84.014426 | G38: =SUM(freq!G2:G28) -> 85.731536 | H38: =SUM(freq!H2:H28) -> 83.185878 | I38: =SUM(freq!I2:I28) -> 89.949547 | ... N38: =SUM(freq!N2:N28) -> 33
A39: MEAN1 | B39: =freq!B29/B38 -> 9.321253 | C39: =freq!C29/C38 -> 10.530034 | D39: =freq!D29/D38 -> 10.105592 | E39: =freq!E29/E38 -> 9.8165083 | F39: =freq!F29/F38 -> 10.094745 | G39: =freq!G29/G38 -> 9.5419319 | H39: =freq!H29/H38 -> 9.884317 | I39: =freq!I29/I38 -> 9.9989145 | ... N39: =freq!N29/N38 -> 10.596287
A40: SD1 | B40: =SQRT((freq!B30-B39^2*B38)/(B38-1)) -> 3.1097966 | C40: =SQRT((freq!C30-C39^2*C38)/(C38-1)) -> 2.8239035 | D40: =SQRT((freq!D30-D39^2*D38)/(D38-1)) -> 2.4539056 | E40: =SQRT((freq!E30-E39^2*E38)/(E38-1)) -> 3.1802863 | F40: =SQRT((freq!F30-F39^2*F38)/(F38-1)) -> 2.9720485 | G40: =SQRT((freq!G30-G39^2*G38)/(G38-1)) -> 2.550384 | H40: =SQRT((freq!H30-H39^2*H38)/(H38-1)) -> 2.9166461 | I40: =SQRT((freq!I30-I39^2*I38)/(I38-1)) -> 2.7771903 | ... N40: =SQRT((freq!N30-N39^2*N38)/(N38-1)) -> 2.7690595

Sheet freq
A1: mrtot | B1: frq1 | C1: frq2 | D1: frq3 | E1: frq4 | F1: frq5 | G1: frq6 | H1: frq7 | I1: frq8 | J1: frq9 | K1: frq10 | L1: frq11 | M1: frq12 | N1: frq13 | O1: SS_Sq | P1: ssq1 | Q1: ssq2 | R1: ssq3 | S1: ssq4 | T1: ssq5 | U1: ssq6 | V1: ssq7 | W1: ssq8 | X1: ssq9 | Y1: ssq10 | Z1: ssq11 | AA1: ssq12 | AB1: ssq13
A2: 0 | B2: . | C2: . | D2: . | E2: . | F2: 1 | G2: . | H2: . | I2: . | J2: . | K2: 1.0015127 | L2: 0.85704793 | M2: . | N2: . | P2: =Hdsmth!B2^2 -> 1 | Q2: =Hdsmth!C2^2 -> 1 | R2: =Hdsmth!D2^2 -> 1 | S2: =Hdsmth!E2^2 -> 1 | T2: =Hdsmth!F2^2 -> 1 | U2: =Hdsmth!G2^2 -> 1 | V2: =Hdsmth!H2^2 -> 1 | W2: =Hdsmth!I2^2 -> 1 | ... AB2: =Hdsmth!N2^2 -> 1
A3: 1 | B3: . | C3: . | D3: . | E3: . | F3: . | G3: 1 | H3: . | I3: . | J3: . | K3: . | L3: . | M3: . | N3: . | P3: =Hdsmth!B3^2 -> 1 | Q3: =Hdsmth!C3^2 -> 1 | R3: =Hdsmth!D3^2 -> 1 | S3: =Hdsmth!E3^2 -> 4 | T3: =Hdsmth!F3^2 -> 4 | U3: =Hdsmth!G3^2 -> 4 | V3: =Hdsmth!H3^2 -> 4 | W3: =Hdsmth!I3^2 -> 4 | ... AB3: =Hdsmth!N3^2 -> 1
A4: 2 | B4: . | C4: . | D4: . | E4: . | F4: . | G4: 1 | H4: . | I4: 1 | J4: . | K4: 1.0015127 | L4: 0.85704793 | M4: . | N4: . | P4: =Hdsmth!B4^2 -> 4 | Q4: =Hdsmth!C4^2 -> 4 | R4: =Hdsmth!D4^2 -> 4 | S4: =Hdsmth!E4^2 -> 4 | T4: =Hdsmth!F4^2 -> 4 | U4: =Hdsmth!G4^2 -> 4 | V4: =Hdsmth!H4^2 -> 9 | W4: =Hdsmth!I4^2 -> 9 | ... AB4: =Hdsmth!N4^2 -> 16
A5: 3 | B5: 1 | C5: 1 | D5: . | E5: 1 | F5: 1 | G5: . | H5: . | I5: . | J5: . | K5: 1.0134928 | L5: 1.0964314 | M5: 2.5290671 | N5: . | P5: =Hdsmth!B5^2 -> 4 | Q5: =Hdsmth!C5^2 -> 4 | R5: =Hdsmth!D5^2 -> 4 | S5: =Hdsmth!E5^2 -> 9 | T5: =Hdsmth!F5^2 -> 9 | U5: =Hdsmth!G5^2 -> 9 | V5: =Hdsmth!H5^2 -> 9 | W5: =Hdsmth!I5^2 -> 9 | ... AB5: =Hdsmth!N5^2 -> 36
A6: 4 | B6: . | C6: . | D6: . | E6: . | F6: . | G6: . | H6: . | I6: . | J6: . | K6: . | L6: 1.9534793 | M6: 0.73668425 | N6: . | P6: =Hdsmth!B6^2 -> 9 | Q6: =Hdsmth!C6^2 -> 9 | R6: =Hdsmth!D6^2 -> 9 | S6: =Hdsmth!E6^2 -> 9 | T6: =Hdsmth!F6^2 -> 9 | U6: =Hdsmth!G6^2 -> 9 | V6: =Hdsmth!H6^2 -> 16 | W6: =Hdsmth!I6^2 -> 16 | ... AB6: =Hdsmth!N6^2 -> 49
A7: 5 | B7: 1 | C7: . | D7: . | E7: 1 | F7: . | G7: 1.1280165 | H7: . | I7: . | J7: 1.0237184 | K7: 2.0150055 | L7: 0.85704793 | M7: 5.3771484 | N7: 1.904606 | P7: =Hdsmth!B7^2 -> 9 | Q7: =Hdsmth!C7^2 -> 9 | R7: =Hdsmth!D7^2 -> 9 | S7: =Hdsmth!E7^2 -> 9 | T7: =Hdsmth!F7^2 -> 16 | U7: =Hdsmth!G7^2 -> 16 | V7: =Hdsmth!H7^2 -> 16 | W7: =Hdsmth!I7^2 -> 16 | ... AB7: =Hdsmth!N7^2 -> 49
A8: 6 | B8: 1.0401201 | C8: . | D8: . | E8: 1.071713 | F8: . | G8: 1.1280165 | H8: 2.9149131 | I8: 1.8256699 | J8: 5.1157478 | K8: 1.0134928 | L8: 3.9069587 | M8: 7.9571045 | N8: 5.956995 | P8: =Hdsmth!B8^2 -> 16 | Q8: =Hdsmth!C8^2 -> 16 | R8: =Hdsmth!D8^2 -> 16 | S8: =Hdsmth!E8^2 -> 16 | T8: =Hdsmth!F8^2 -> 16 | U8: =Hdsmth!G8^2 -> 16 | V8: =Hdsmth!H8^2 -> 16 | W8: =Hdsmth!I8^2 -> 25 | ... AB8: =Hdsmth!N8^2 -> 64
A9: 7 | B9: 3.0292179 | C9: 0.99995337 | D9: 1 | E9: 3.1985798 | F9: . | G9: 1.0272851 | H9: 1.9857722 | I9: 4.6094664 | J9: 2.0710255 | K9: 4.030011 | L9: 2.8105273 | M9: 5.3771484 | N9: 1.904606 | P9: =Hdsmth!B9^2 -> 16 | Q9: =Hdsmth!C9^2 -> 16 | R9: =Hdsmth!D9^2 -> 16 | S9: =Hdsmth!E9^2 -> 16 | T9: =Hdsmth!F9^2 -> 16 | U9: =Hdsmth!G9^2 -> 25 | V9: =Hdsmth!H9^2 -> 25 | W9: =Hdsmth!I9^2 -> 25 | ... AB9: =Hdsmth!N9^2 -> 81
A10: 8 | B10: 0.94663507 | C10: 0.96556613 | D10: 1.1487536 | E10: 1.071713 | F10: 2.9740905 | G10: 0.94618362 | H10: 4.9916753 | I10: 1.8125031 | J10: 7.9668028 | K10: 5.0195436 | L10: 4.1127022 | M10: 8.2063165 | N10: 5.1933882 | P10: =Hdsmth!B10^2 -> 25 | Q10: =Hdsmth!C10^2 -> 25 | R10: =Hdsmth!D10^2 -> 25 | S10: =Hdsmth!E10^2 -> 25 | T10: =Hdsmth!F10^2 -> 25 | U10: =Hdsmth!G10^2 -> 25 | V10: =Hdsmth!H10^2 -> 25 | W10: =Hdsmth!I10^2 -> 36 | ... AB10: =Hdsmth!N10^2 -> 81
A11: 9 | B11: 3.0501614 | C11: 2.0000582 | D11: . | E11: 1.9245786 | F11: 3.0512691 | G11: . | H11: 4.8065507 | I11: 6.69878 | J11: 5.7941051 | K11: 6.1378394 | L11: 1.9534793 | M11: 8.0507583 | N11: 2.8406096 | P11: =Hdsmth!B11^2 -> 25 | Q11: =Hdsmth!C11^2 -> 25 | R11: =Hdsmth!D11^2 -> 25 | S11: =Hdsmth!E11^2 -> 25 | T11: =Hdsmth!F11^2 -> 25 | U11: =Hdsmth!G11^2 -> 36 | V11: =Hdsmth!H11^2 -> 36 | W11: =Hdsmth!I11^2 -> 49 | ... AB11: =Hdsmth!N11^2 -> 100
A12: 10 | B12: 6.8155332 | C12: . | D12: 4.8114257 | E12: 1.1181453 | F12: 1.0979704 | G12: 2.9944319 | H12: 1.9840346 | I12: 4.85748 | J12: 5.1893582 | K12: 5.8788035 | L12: 3.2318568 | M12: 3.0604115 | N12: 1.7335122 | P12: =Hdsmth!B12^2 -> 36 | Q12: =Hdsmth!C12^2 -> 36 | R12: =Hdsmth!D12^2 -> 36 | S12: =Hdsmth!E12^2 -> 36 | T12: =Hdsmth!F12^2 -> 36 | U12: =Hdsmth!G12^2 -> 36 | V12: =Hdsmth!H12^2 -> 49 | W12: =Hdsmth!I12^2 -> 49 | ... AB12: =Hdsmth!N12^2 -> 100
A13: 11 | B13: 5.7945213 | C13: 3.8966554 | D13: 1.9617609 | E13: 4.1529677 | F13: 0.99787929 | G13: 4.1287703 | H13: . | I13: 3.7229652 | J13: 4.8686059 | K13: 7.0617582 | L13: 4.8726079 | M13: 5.1992296 | N13: 1.1409991 | P13: =Hdsmth!B13^2 -> 49 | Q13: =Hdsmth!C13^2 -> 49 | R13: =Hdsmth!D13^2 -> 36 | S13: =Hdsmth!E13^2 -> 36 | T13: =Hdsmth!F13^2 -> 49 | U13: =Hdsmth!G13^2 -> 49 | V13: =Hdsmth!H13^2 -> 49 | W13: =Hdsmth!I13^2 -> 64 | ... AB13: =Hdsmth!N13^2 -> 121
A14: 12 | B14: 5.9789238 | C14: 2.9654765 | D14: 3.9360607 | E14: 4.1528308 | F14: 5.9715991 | G14: 3.0587143 | H14: 3.9715444 | I14: 2.0363813 | J14: 5.990169 | K14: 5.1298592 | L14: 1.1507321 | M14: 0.79946973 | N14: 2.2819982 | P14: =Hdsmth!B14^2 -> 49 | Q14: =Hdsmth!C14^2 -> 49 | R14: =Hdsmth!D14^2 -> 49 | S14: =Hdsmth!E14^2 -> 49 | T14: =Hdsmth!F14^2 -> 49 | U14: =Hdsmth!G14^2 -> 49 | V14: =Hdsmth!H14^2 -> 64 | W14: =Hdsmth!I14^2 -> 64 | ... AB14: =Hdsmth!N14^2 -> 121
A15: 13 | B15: 5.074908 | C15: 3.9612385 | D15: 6.4784024 | E15: 0.96228928 | F15: 2.8477156 | G15: 2.8937005 | H15: . | I15: 4.0504533 | J15: 1.9199407 | K15: 8.2012785 | L15: 4.5458872 | M15: . | N15: . | P15: =Hdsmth!B15^2 -> 64 | Q15: =Hdsmth!C15^2 -> 64 | R15: =Hdsmth!D15^2 -> 64 | S15: =Hdsmth!E15^2 -> 49 | T15: =Hdsmth!F15^2 -> 64 | U15: =Hdsmth!G15^2 -> 64 | V15: =Hdsmth!H15^2 -> 64 | W15: =Hdsmth!I15^2 -> 81 | ... AB15: =Hdsmth!N15^2 -> 144
A16: 14 | B16: 5.0532321 | C16: 3.8964493 | D16: 2.0739097 | E16: 3.076377 | F16: 3.0494375 | G16: 4.9975775 | H16: 2.8925987 | I16: 8.2343418 | J16: 0.92265519 | K16: 4.9761397 | L16: 1.9959245 | M16: 4.11611 | N16: 1.904606 | P16: =Hdsmth!B16^2 -> 64 | Q16: =Hdsmth!C16^2 -> 64 | R16: =Hdsmth!D16^2 -> 64 | S16: =Hdsmth!E16^2 -> 64 | T16: =Hdsmth!F16^2 -> 64 | U16: =Hdsmth!G16^2 -> 64 | V16: =Hdsmth!H16^2 -> 81 | W16: =Hdsmth!I16^2 -> 81 | ... AB16: =Hdsmth!N16^2 -> 144
A17: 15 | B17: 2.8851496 | C17: 6.9876136 | D17: 7.0888021 | E17: 4.0850985 | F17: 6.1851755 | G17: 5.9276433 | H17: 7.8306058 | I17: 6.2439234 | J17: 6.0579296 | K17: 6.9686364 | L17: 9.8283655 | M17: 1.8825893 | N17: 0.69501086 | P17: =Hdsmth!B17^2 -> 81 | Q17: =Hdsmth!C17^2 -> 81 | R17: =Hdsmth!D17^2 -> 81 | S17: =Hdsmth!E17^2 -> 64 | T17: =Hdsmth!F17^2 -> 81 | U17: =Hdsmth!G17^2 -> 81 | V17: =Hdsmth!H17^2 -> 81 | W17: =Hdsmth!I17^2 -> 100 | ... AB17: =Hdsmth!N17^2 -> 144
A18: 16 | B18: 4.0112768 | C18: 3.0304719 | D18: 7.009623 | E18: 2.9670901 | F18: . | G18: 7.7297763 | H18: 4.1435083 | I18: 2.0318101 | J18: 6.0855806 | K18: 5.9536479 | L18: 10.000903 | M18: 2.5799561 | N18: 2.6276731 | P18: =Hdsmth!B18^2 -> 100 | Q18: =Hdsmth!C18^2 -> 81 | R18: =Hdsmth!D18^2 -> 81 | S18: =Hdsmth!E18^2 -> 81 | T18: =Hdsmth!F18^2 -> 81 | U18: =Hdsmth!G18^2 -> 81 | V18: =Hdsmth!H18^2 -> 100 | W18: =Hdsmth!I18^2 -> 121 | ... AB18: =Hdsmth!N18^2 -> 169
A19: 17 | B19: 8.0506925 | C19: 3.060553 | D19: 4.7383752 | E19: 3.0812547 | F19: 8.1648622 | G19: 5.8918575 | H19: 12.063767 | I19: 12.413924 | J19: 7.0879086 | K19: 1.8607726 | L19: 5.9544435 | M19: . | N19: . | P19: =Hdsmth!B19^2 -> 100 | Q19: =Hdsmth!C19^2 -> 100 | R19: =Hdsmth!D19^2 -> 100 | S19: =Hdsmth!E19^2 -> 100 | T19: =Hdsmth!F19^2 -> 100 | U19: =Hdsmth!G19^2 -> 100 | V19: =Hdsmth!H19^2 -> 100 | W19: =Hdsmth!I19^2 -> 121 | ... AB19: =Hdsmth!N19^2 -> 169
A20: 18 | B20: 6.8558099 | C20: 5.0261837 | D20: 7.0024592 | E20: 7.7657575 | F20: 6.0865694 | G20: 8.0048673 | H20: 10.015725 | I20: 8.9281345 | J20: 9.932703 | K20: 3.9913213 | L20: 4.6522685 | M20: 1.536154 | N20: . | P20: =Hdsmth!B20^2 -> 121 | Q20: =Hdsmth!C20^2 -> 121 | R20: =Hdsmth!D20^2 -> 100 | S20: =Hdsmth!E20^2 -> 100 | T20: =Hdsmth!F20^2 -> 100 | U20: =Hdsmth!G20^2 -> 100 | V20: =Hdsmth!H20^2 -> 121 | W20: =Hdsmth!I20^2 -> 144 | ... AB20: =Hdsmth!N20^2 -> 196
A21: 19 | B21: 10.174655 | C21: 9.017969 | D21: 5.8087559 | E21: 4.9267652 | F21: 5.9252656 | G21: 15.048453 | H21: 2.9969939 | I21: 9.2883756 | J21: 5.9124964 | K21: 2.9463741 | L21: 3.0499107 | M21: 0.79946973 | N21: . | P21: =Hdsmth!B21^2 -> 144 | Q21: =Hdsmth!C21^2 -> 121 | R21: =Hdsmth!D21^2 -> 121 | S21: =Hdsmth!E21^2 -> 121 | T21: =Hdsmth!F21^2 -> 121 | U21: =Hdsmth!G21^2 -> 121 | V21: =Hdsmth!H21^2 -> 144 | W21: =Hdsmth!I21^2 -> 169 | ... AB21: =Hdsmth!N21^2 -> 196
A22: 20 | B22: 5.2582955 | C22: 11.108708 | D22: 10.341413 | E22: 13.635575 | F22: 12.888114 | G22: 7.7452621 | H22: 10.286921 | I22: 7.1481627 | J22: . | K22: 3.8647804 | L22: . | M22: . | N22: 1.0385013 | P22: =Hdsmth!B22^2 -> 144 | Q22: =Hdsmth!C22^2 -> 144 | R22: =Hdsmth!D22^2 -> 144 | S22: =Hdsmth!E22^2 -> 121 | T22: =Hdsmth!F22^2 -> 121 | U22: =Hdsmth!G22^2 -> 144 | V22: =Hdsmth!H22^2 -> 144 | W22: =Hdsmth!I22^2 -> 169 | ... AB22: =Hdsmth!N22^2 -> 225
A23: 21 | B23: 5.0347879 | C23: 12.009295 | D23: 6.0683988 | E23: 9.8879436 | F23: 7.0805781 | G23: 4.8360758 | H23: 6.1734633 | I23: 3.0471753 | J23: 2.9936807 | K23: 1.931899 | L23: 3.4706369 | M23: . | N23: 2.2502808 | P23: =Hdsmth!B23^2 -> 169 | Q23: =Hdsmth!C23^2 -> 169 | R23: =Hdsmth!D23^2 -> 144 | S23: =Hdsmth!E23^2 -> 144 | T23: =Hdsmth!F23^2 -> 144 | U23: =Hdsmth!G23^2 -> 144 | V23: =Hdsmth!H23^2 -> 169 | W23: =Hdsmth!I23^2 -> 196 | ... AB23: =Hdsmth!N23^2 -> 225
A24: 22 | B24: 4.1042544 | C24: 6.0217731 | D24: 12.881943 | E24: 6.8481832 | F24: 5.9785731 | G24: 3.0779252 | H24: 3.1261327 | I24: 1 | J24: 1.0473072 | K24: . | L24: 0.98469336 | M24: . | N24: . | P24: =Hdsmth!B24^2 -> 196 | Q24: =Hdsmth!C24^2 -> 196 | R24: =Hdsmth!D24^2 -> 169 | S24: =Hdsmth!E24^2 -> 169 | T24: =Hdsmth!F24^2 -> 169 | U24: =Hdsmth!G24^2 -> 169 | V24: =Hdsmth!H24^2 -> 196 | W24: =Hdsmth!I24^2 -> 225 | ... AB24: =Hdsmth!N24^2 -> 256
A25: 23 | B25: 2.0076986 | C25: 2.9957123 | D25: 0.9461461 | E25: 3.0013665 | F25: 5.8368442 | G25: 2.1669791 | H25: 2.006349 | I25: 1 | J25: 1.0202653 | K25: 1.0569272 | L25: . | M25: 1.0556986 | N25: 0.76360687 | P25: =Hdsmth!B25^2 -> 225 | Q25: =Hdsmth!C25^2 -> 225 | R25: =Hdsmth!D25^2 -> 196 | S25: =Hdsmth!E25^2 -> 196 | T25: =Hdsmth!F25^2 -> 196 | U25: =Hdsmth!G25^2 -> 196 | V25: =Hdsmth!H25^2 -> 225 | W25: =Hdsmth!I25^2 -> 256 | ... AB25: =Hdsmth!N25^2 -> 256
A26: 24 | B26: 1 | C26: 1.0302474 | D26: 1.9582318 | E26: . | F26: 2.9493463 | G26: 1 | H26: . | I26: . | J26: . | K26: 1.943879 | L26: . | M26: 0.73668425 | N26: . | P26: =Hdsmth!B26^2 -> 256 | Q26: =Hdsmth!C26^2 -> 256 | R26: =Hdsmth!D26^2 -> 225 | S26: =Hdsmth!E26^2 -> 225 | T26: =Hdsmth!F26^2 -> 225 | U26: =Hdsmth!G26^2 -> 225 | V26: =Hdsmth!H26^2 -> 289 | W26: =Hdsmth!I26^2 -> 289 | ... AB26: =Hdsmth!N26^2 -> 289
A27: 25 | B27: . | C27: . | D27: . | E27: 1.1181453 | F27: . | G27: . | H27: 0.99532244 | I27: . | J27: . | K27: . | L27: . | M27: . | N27: . | P27: =Hdsmth!B27^2 -> 289 | Q27: =Hdsmth!C27^2 -> 289 | R27: =Hdsmth!D27^2 -> 289 | S27: =Hdsmth!E27^2 -> 256 | T27: =Hdsmth!F27^2 -> 256 | U27: =Hdsmth!G27^2 -> 289 | V27: =Hdsmth!H27^2 -> 361 | W27: =Hdsmth!I27^2 -> 361 | ... AB27: =Hdsmth!N27^2 -> 324
A28: 26 | B28: . | C28: . | D28: . | E28: 1.959812 | F28: 0.92913559 | G28: . | H28: . | I28: . | J28: . | K28: 1.0015127 | L28: 0.85704793 | M28: . | N28: 0.76360687 | P28: =Hdsmth!B28^2 -> 361 | Q28: =Hdsmth!C28^2 -> 361 | R28: =Hdsmth!D28^2 -> 361 | S28: =Hdsmth!E28^2 -> 324 | T28: =Hdsmth!F28^2 -> 361 | U28: =Hdsmth!G28^2 -> 361 | V28: =Hdsmth!H28^2 -> 361 | W28: =Hdsmth!I28^2 -> 361 | ... AB28: =Hdsmth!N28^2 -> 361
B29: =SUMPRODUCT(B2:B28,Hdsmth!B2:B28) -> 821.8164 | C29: =SUMPRODUCT(C2:C28,Hdsmth!C2:C28) -> 842.12814 | D29: =SUMPRODUCT(D2:D28,Hdsmth!D2:D28) -> 861.54682 | E29: =SUMPRODUCT(E2:E28,Hdsmth!E2:E28) -> 805.0144 | F29: =SUMPRODUCT(F2:F28,Hdsmth!F2:F28) -> 848.10424 | G29: =SUMPRODUCT(G2:G28,Hdsmth!G2:G28) -> 818.04448 | H29: =SUMPRODUCT(H2:H28,Hdsmth!H2:H28) -> 822.23559 | I29: =SUMPRODUCT(I2:I28,Hdsmth!I2:I28) -> 899.39782 | ... N29: =SUMPRODUCT(N2:N28,Hdsmth!N2:N28) -> 349.67746 | O29: =SUM(B29:N29) -> 10052.215
B30: =SUMPRODUCT(B2:B28,P2:P28) -> 8503.3253 | C30: =SUMPRODUCT(C2:C28,Q2:Q28) -> 9497.41 | D30: =SUMPRODUCT(D2:D28,R2:R28) -> 9213.7919 | E30: =SUMPRODUCT(E2:E28,S2:S28) -> 8721.7449 | F30: =SUMPRODUCT(F2:F28,T2:T28) -> 9294.6689 | G30: =SUMPRODUCT(G2:G28,U2:U28) -> 8356.8575 | H30: =SUMPRODUCT(H2:H28,V2:V28) -> 8826.378 | I30: =SUMPRODUCT(I2:I28,W2:W28) -> 9679.0507 | ... N30: =SUMPRODUCT(N2:N28,AB2:AB28) -> 3950.6487 | O30: =SUM(B30:N30) -> 108645

Sheet dif
A1: wais5_mr_raw | B1: ss1 | C1: ss2 | D1: ss3 | E1: ss4 | F1: ss5 | G1: ss6 | H1: ss7 | I1: ss8 | J1: ss9 | K1: ss10 | L1: ss11 | M1: ss12 | N1: ss13 | O1: wais5_mr_raw | P1: ss1 | Q1: ss2 | R1: ss3 | S1: ss4 | T1: ss5 | U1: ss6 | V1: ss7 | W1: ss8 | X1: ss9 | Y1: ss10 | Z1: ss11 | AA1: ss12 | AB1: ss13
A2: 0 | B2: 1 | C2: 1 | D2: 1 | E2: 1 | F2: 1 | G2: 1 | H2: 1 | I2: 1 | J2: 1 | K2: 1 | L2: 1 | M2: 1 | N2: 1 | O2: 0 | P2: =Hdsmth!B2-dif!B2 -> 0 | Q2: =Hdsmth!C2-dif!C2 -> 0 | R2: =Hdsmth!D2-dif!D2 -> 0 | S2: =Hdsmth!E2-dif!E2 -> 0 | T2: =Hdsmth!F2-dif!F2 -> 0 | U2: =Hdsmth!G2-dif!G2 -> 0 | V2: =Hdsmth!H2-dif!H2 -> 0 | W2: =Hdsmth!I2-dif!I2 -> 0 | ... AB2: =Hdsmth!N2-dif!N2 -> 0
A3: 1 | B3: 1 | C3: 1 | D3: 1 | E3: 1 | F3: 1 | G3: 1 | H3: 1 | I3: 2 | J3: 2 | K3: 2 | L3: 2 | M3: 2 | N3: 2 | O3: 1 | P3: =Hdsmth!B3-dif!B3 -> 0 | Q3: =Hdsmth!C3-dif!C3 -> 0 | R3: =Hdsmth!D3-dif!D3 -> 0 | S3: =Hdsmth!E3-dif!E3 -> 1 | T3: =Hdsmth!F3-dif!F3 -> 1 | U3: =Hdsmth!G3-dif!G3 -> 1 | V3: =Hdsmth!H3-dif!H3 -> 1 | W3: =Hdsmth!I3-dif!I3 -> 0 | ... AB3: =Hdsmth!N3-dif!N3 -> -1
A4: 2 | B4: 1 | C4: 1 | D4: 1 | E4: 1 | F4: 1 | G4: 1 | H4: 2 | I4: 2 | J4: 2 | K4: 2 | L4: 2 | M4: 2 | N4: 3 | O4: 2 | P4: =Hdsmth!B4-dif!B4 -> 1 | Q4: =Hdsmth!C4-dif!C4 -> 1 | R4: =Hdsmth!D4-dif!D4 -> 1 | S4: =Hdsmth!E4-dif!E4 -> 1 | T4: =Hdsmth!F4-dif!F4 -> 1 | U4: =Hdsmth!G4-dif!G4 -> 1 | V4: =Hdsmth!H4-dif!H4 -> 1 | W4: =Hdsmth!I4-dif!I4 -> 1 | ... AB4: =Hdsmth!N4-dif!N4 -> 1
A5: 3 | B5: 2 | C5: 2 | D5: 2 | E5: 2 | F5: 2 | G5: 2 | H5: 2 | I5: 3 | J5: 3 | K5: 3 | L5: 3 | M5: 3 | N5: 4 | O5: 3 | P5: =Hdsmth!B5-dif!B5 -> 0 | Q5: =Hdsmth!C5-dif!C5 -> 0 | R5: =Hdsmth!D5-dif!D5 -> 0 | S5: =Hdsmth!E5-dif!E5 -> 1 | T5: =Hdsmth!F5-dif!F5 -> 1 | U5: =Hdsmth!G5-dif!G5 -> 1 | V5: =Hdsmth!H5-dif!H5 -> 1 | W5: =Hdsmth!I5-dif!I5 -> 0 | ... AB5: =Hdsmth!N5-dif!N5 -> 2
A6: 4 | B6: 2 | C6: 2 | D6: 2 | E6: 2 | F6: 2 | G6: 2 | H6: 3 | I6: 3 | J6: 3 | K6: 4 | L6: 4 | M6: 4 | N6: 4 | O6: 4 | P6: =Hdsmth!B6-dif!B6 -> 1 | Q6: =Hdsmth!C6-dif!C6 -> 1 | R6: =Hdsmth!D6-dif!D6 -> 1 | S6: =Hdsmth!E6-dif!E6 -> 1 | T6: =Hdsmth!F6-dif!F6 -> 1 | U6: =Hdsmth!G6-dif!G6 -> 1 | V6: =Hdsmth!H6-dif!H6 -> 1 | W6: =Hdsmth!I6-dif!I6 -> 1 | ... AB6: =Hdsmth!N6-dif!N6 -> 3
A7: 5 | B7: 2 | C7: 2 | D7: 2 | E7: 2 | F7: 3 | G7: 3 | H7: 3 | I7: 4 | J7: 4 | K7: 4 | L7: 4 | M7: 4 | N7: 5 | O7: 5 | P7: =Hdsmth!B7-dif!B7 -> 1 | Q7: =Hdsmth!C7-dif!C7 -> 1 | R7: =Hdsmth!D7-dif!D7 -> 1 | S7: =Hdsmth!E7-dif!E7 -> 1 | T7: =Hdsmth!F7-dif!F7 -> 1 | U7: =Hdsmth!G7-dif!G7 -> 1 | V7: =Hdsmth!H7-dif!H7 -> 1 | W7: =Hdsmth!I7-dif!I7 -> 0 | ... AB7: =Hdsmth!N7-dif!N7 -> 2
A8: 6 | B8: 3 | C8: 3 | D8: 3 | E8: 3 | F8: 3 | G8: 3 | H8: 4 | I8: 4 | J8: 4 | K8: 5 | L8: 5 | M8: 5 | N8: 6 | O8: 6 | P8: =Hdsmth!B8-dif!B8 -> 1 | Q8: =Hdsmth!C8-dif!C8 -> 1 | R8: =Hdsmth!D8-dif!D8 -> 1 | S8: =Hdsmth!E8-dif!E8 -> 1 | T8: =Hdsmth!F8-dif!F8 -> 1 | U8: =Hdsmth!G8-dif!G8 -> 1 | V8: =Hdsmth!H8-dif!H8 -> 0 | W8: =Hdsmth!I8-dif!I8 -> 1 | ... AB8: =Hdsmth!N8-dif!N8 -> 2
A9: 7 | B9: 3 | C9: 3 | D9: 3 | E9: 3 | F9: 4 | G9: 4 | H9: 4 | I9: 5 | J9: 5 | K9: 5 | L9: 6 | M9: 6 | N9: 7 | O9: 7 | P9: =Hdsmth!B9-dif!B9 -> 1 | Q9: =Hdsmth!C9-dif!C9 -> 1 | R9: =Hdsmth!D9-dif!D9 -> 1 | S9: =Hdsmth!E9-dif!E9 -> 1 | T9: =Hdsmth!F9-dif!F9 -> 0 | U9: =Hdsmth!G9-dif!G9 -> 1 | V9: =Hdsmth!H9-dif!H9 -> 1 | W9: =Hdsmth!I9-dif!I9 -> 0 | ... AB9: =Hdsmth!N9-dif!N9 -> 2
A10: 8 | B10: 4 | C10: 4 | D10: 4 | E10: 4 | F10: 4 | G10: 4 | H10: 5 | I10: 5 | J10: 6 | K10: 6 | L10: 7 | M10: 7 | N10: 8 | O10: 8 | P10: =Hdsmth!B10-dif!B10 -> 1 | Q10: =Hdsmth!C10-dif!C10 -> 1 | R10: =Hdsmth!D10-dif!D10 -> 1 | S10: =Hdsmth!E10-dif!E10 -> 1 | T10: =Hdsmth!F10-dif!F10 -> 1 | U10: =Hdsmth!G10-dif!G10 -> 1 | V10: =Hdsmth!H10-dif!H10 -> 0 | W10: =Hdsmth!I10-dif!I10 -> 1 | ... AB10: =Hdsmth!N10-dif!N10 -> 1
A11: 9 | B11: 4 | C11: 4 | D11: 4 | E11: 4 | F11: 5 | G11: 5 | H11: 5 | I11: 6 | J11: 7 | K11: 7 | L11: 7 | M11: 8 | N11: 9 | O11: 9 | P11: =Hdsmth!B11-dif!B11 -> 1 | Q11: =Hdsmth!C11-dif!C11 -> 1 | R11: =Hdsmth!D11-dif!D11 -> 1 | S11: =Hdsmth!E11-dif!E11 -> 1 | T11: =Hdsmth!F11-dif!F11 -> 0 | U11: =Hdsmth!G11-dif!G11 -> 1 | V11: =Hdsmth!H11-dif!H11 -> 1 | W11: =Hdsmth!I11-dif!I11 -> 1 | ... AB11: =Hdsmth!N11-dif!N11 -> 1
A12: 10 | B12: 5 | C12: 5 | D12: 5 | E12: 5 | F12: 5 | G12: 6 | H12: 6 | I12: 7 | J12: 7 | K12: 8 | L12: 8 | M12: 9 | N12: 10 | O12: 10 | P12: =Hdsmth!B12-dif!B12 -> 1 | Q12: =Hdsmth!C12-dif!C12 -> 1 | R12: =Hdsmth!D12-dif!D12 -> 1 | S12: =Hdsmth!E12-dif!E12 -> 1 | T12: =Hdsmth!F12-dif!F12 -> 1 | U12: =Hdsmth!G12-dif!G12 -> 0 | V12: =Hdsmth!H12-dif!H12 -> 1 | W12: =Hdsmth!I12-dif!I12 -> 0 | ... AB12: =Hdsmth!N12-dif!N12 -> 0
A13: 11 | B13: 5 | C13: 5 | D13: 5 | E13: 6 | F13: 6 | G13: 7 | H13: 7 | I13: 7 | J13: 8 | K13: 8 | L13: 9 | M13: 10 | N13: 10 | O13: 11 | P13: =Hdsmth!B13-dif!B13 -> 2 | Q13: =Hdsmth!C13-dif!C13 -> 2 | R13: =Hdsmth!D13-dif!D13 -> 1 | S13: =Hdsmth!E13-dif!E13 -> 0 | T13: =Hdsmth!F13-dif!F13 -> 1 | U13: =Hdsmth!G13-dif!G13 -> 0 | V13: =Hdsmth!H13-dif!H13 -> 0 | W13: =Hdsmth!I13-dif!I13 -> 1 | ... AB13: =Hdsmth!N13-dif!N13 -> 1
... A28: 26 | B28: 19 | C28: 19 | D28: 19 | E28: 19 | F28: 19 | G28: 19 | H28: 19 | I28: 19 | J28: 19 | K28: 19 | L28: 19 | M28: 19 | N28: 19 | O28: 26 | P28: =Hdsmth!B28-dif!B28 -> 0 | Q28: =Hdsmth!C28-dif!C28 -> 0 | R28: =Hdsmth!D28-dif!D28 -> 0 | S28: =Hdsmth!E28-dif!E28 -> -1 | T28: =Hdsmth!F28-dif!F28 -> 0 | U28: =Hdsmth!G28-dif!G28 -> 0 | V28: =Hdsmth!H28-dif!H28 -> 0 | W28: =Hdsmth!I28-dif!I28 -> 0 | ... AB28: =Hdsmth!N28-dif!N28 -> 0

Sheet smooth
A1: ss | B1: g1 | C1: g2 | D1: g3 | E1: g4 | F1: g5 | G1: g6 | H1: g7 | I1: g8 | J1: g9 | K1: g10 | L1: g11 | M1: g12 | N1: g13
A2: 1 | B2: =COUNTIF(Hdsmth!B$2:B$28,$A2) -> 2 | C2: =COUNTIF(Hdsmth!C$2:C$28,$A2) -> 2 | D2: =COUNTIF(Hdsmth!D$2:D$28,$A2) -> 2 | E2: =COUNTIF(Hdsmth!E$2:E$28,$A2) -> 1 | F2: =COUNTIF(Hdsmth!F$2:F$28,$A2) -> 1 | G2: =COUNTIF(Hdsmth!G$2:G$28,$A2) -> 1 | H2: =COUNTIF(Hdsmth!H$2:H$28,$A2) -> 1 | I2: =COUNTIF(Hdsmth!I$2:I$28,$A2) -> 1 | ... N2: =COUNTIF(Hdsmth!N$2:N$28,$A2) -> 2
A3: 2 | B3: =COUNTIF(Hdsmth!B$2:B$28,$A3) -> 2 | C3: =COUNTIF(Hdsmth!C$2:C$28,$A3) -> 2 | D3: =COUNTIF(Hdsmth!D$2:D$28,$A3) -> 2 | E3: =COUNTIF(Hdsmth!E$2:E$28,$A3) -> 2 | F3: =COUNTIF(Hdsmth!F$2:F$28,$A3) -> 2 | G3: =COUNTIF(Hdsmth!G$2:G$28,$A3) -> 2 | H3: =COUNTIF(Hdsmth!H$2:H$28,$A3) -> 1 | I3: =COUNTIF(Hdsmth!I$2:I$28,$A3) -> 1 | ... N3: =COUNTIF(Hdsmth!N$2:N$28,$A3) -> 0
A4: 3 | B4: =COUNTIF(Hdsmth!B$2:B$28,$A4) -> 2 | C4: =COUNTIF(Hdsmth!C$2:C$28,$A4) -> 2 | D4: =COUNTIF(Hdsmth!D$2:D$28,$A4) -> 2 | E4: =COUNTIF(Hdsmth!E$2:E$28,$A4) -> 3 | F4: =COUNTIF(Hdsmth!F$2:F$28,$A4) -> 2 | G4: =COUNTIF(Hdsmth!G$2:G$28,$A4) -> 2 | H4: =COUNTIF(Hdsmth!H$2:H$28,$A4) -> 2 | I4: =COUNTIF(Hdsmth!I$2:I$28,$A4) -> 2 | ... N4: =COUNTIF(Hdsmth!N$2:N$28,$A4) -> 0
A5: 4 | B5: =COUNTIF(Hdsmth!B$2:B$28,$A5) -> 2 | C5: =COUNTIF(Hdsmth!C$2:C$28,$A5) -> 2 | D5: =COUNTIF(Hdsmth!D$2:D$28,$A5) -> 2 | E5: =COUNTIF(Hdsmth!E$2:E$28,$A5) -> 2 | F5: =COUNTIF(Hdsmth!F$2:F$28,$A5) -> 3 | G5: =COUNTIF(Hdsmth!G$2:G$28,$A5) -> 2 | H5: =COUNTIF(Hdsmth!H$2:H$28,$A5) -> 3 | I5: =COUNTIF(Hdsmth!I$2:I$28,$A5) -> 2 | ... N5: =COUNTIF(Hdsmth!N$2:N$28,$A5) -> 1
A6: 5 | B6: =COUNTIF(Hdsmth!B$2:B$28,$A6) -> 2 | C6: =COUNTIF(Hdsmth!C$2:C$28,$A6) -> 2 | D6: =COUNTIF(Hdsmth!D$2:D$28,$A6) -> 2 | E6: =COUNTIF(Hdsmth!E$2:E$28,$A6) -> 2 | F6: =COUNTIF(Hdsmth!F$2:F$28,$A6) -> 2 | G6: =COUNTIF(Hdsmth!G$2:G$28,$A6) -> 2 | H6: =COUNTIF(Hdsmth!H$2:H$28,$A6) -> 2 | I6: =COUNTIF(Hdsmth!I$2:I$28,$A6) -> 2 | ... N6: =COUNTIF(Hdsmth!N$2:N$28,$A6) -> 0
A7: 6 | B7: =COUNTIF(Hdsmth!B$2:B$28,$A7) -> 1 | C7: =COUNTIF(Hdsmth!C$2:C$28,$A7) -> 1 | D7: =COUNTIF(Hdsmth!D$2:D$28,$A7) -> 2 | E7: =COUNTIF(Hdsmth!E$2:E$28,$A7) -> 2 | F7: =COUNTIF(Hdsmth!F$2:F$28,$A7) -> 1 | G7: =COUNTIF(Hdsmth!G$2:G$28,$A7) -> 2 | H7: =COUNTIF(Hdsmth!H$2:H$28,$A7) -> 1 | I7: =COUNTIF(Hdsmth!I$2:I$28,$A7) -> 1 | ... N7: =COUNTIF(Hdsmth!N$2:N$28,$A7) -> 1
A8: 7 | B8: =COUNTIF(Hdsmth!B$2:B$28,$A8) -> 2 | C8: =COUNTIF(Hdsmth!C$2:C$28,$A8) -> 2 | D8: =COUNTIF(Hdsmth!D$2:D$28,$A8) -> 1 | E8: =COUNTIF(Hdsmth!E$2:E$28,$A8) -> 2 | F8: =COUNTIF(Hdsmth!F$2:F$28,$A8) -> 2 | G8: =COUNTIF(Hdsmth!G$2:G$28,$A8) -> 2 | H8: =COUNTIF(Hdsmth!H$2:H$28,$A8) -> 2 | I8: =COUNTIF(Hdsmth!I$2:I$28,$A8) -> 2 | ... N8: =COUNTIF(Hdsmth!N$2:N$28,$A8) -> 2
A9: 8 | B9: =COUNTIF(Hdsmth!B$2:B$28,$A9) -> 2 | C9: =COUNTIF(Hdsmth!C$2:C$28,$A9) -> 2 | D9: =COUNTIF(Hdsmth!D$2:D$28,$A9) -> 2 | E9: =COUNTIF(Hdsmth!E$2:E$28,$A9) -> 2 | F9: =COUNTIF(Hdsmth!F$2:F$28,$A9) -> 2 | G9: =COUNTIF(Hdsmth!G$2:G$28,$A9) -> 2 | H9: =COUNTIF(Hdsmth!H$2:H$28,$A9) -> 2 | I9: =COUNTIF(Hdsmth!I$2:I$28,$A9) -> 2 | ... N9: =COUNTIF(Hdsmth!N$2:N$28,$A9) -> 1
A10: 9 | B10: =COUNTIF(Hdsmth!B$2:B$28,$A10) -> 1 | C10: =COUNTIF(Hdsmth!C$2:C$28,$A10) -> 2 | D10: =COUNTIF(Hdsmth!D$2:D$28,$A10) -> 2 | E10: =COUNTIF(Hdsmth!E$2:E$28,$A10) -> 1 | F10: =COUNTIF(Hdsmth!F$2:F$28,$A10) -> 2 | G10: =COUNTIF(Hdsmth!G$2:G$28,$A10) -> 2 | H10: =COUNTIF(Hdsmth!H$2:H$28,$A10) -> 2 | I10: =COUNTIF(Hdsmth!I$2:I$28,$A10) -> 2 | ... N10: =COUNTIF(Hdsmth!N$2:N$28,$A10) -> 2
A11: 10 | B11: =COUNTIF(Hdsmth!B$2:B$28,$A11) -> 2 | C11: =COUNTIF(Hdsmth!C$2:C$28,$A11) -> 1 | D11: =COUNTIF(Hdsmth!D$2:D$28,$A11) -> 2 | E11: =COUNTIF(Hdsmth!E$2:E$28,$A11) -> 2 | F11: =COUNTIF(Hdsmth!F$2:F$28,$A11) -> 2 | G11: =COUNTIF(Hdsmth!G$2:G$28,$A11) -> 2 | H11: =COUNTIF(Hdsmth!H$2:H$28,$A11) -> 2 | I11: =COUNTIF(Hdsmth!I$2:I$28,$A11) -> 1 | ... N11: =COUNTIF(Hdsmth!N$2:N$28,$A11) -> 2
A12: 11 | B12: =COUNTIF(Hdsmth!B$2:B$28,$A12) -> 1 | C12: =COUNTIF(Hdsmth!C$2:C$28,$A12) -> 2 | D12: =COUNTIF(Hdsmth!D$2:D$28,$A12) -> 1 | E12: =COUNTIF(Hdsmth!E$2:E$28,$A12) -> 2 | F12: =COUNTIF(Hdsmth!F$2:F$28,$A12) -> 2 | G12: =COUNTIF(Hdsmth!G$2:G$28,$A12) -> 1 | H12: =COUNTIF(Hdsmth!H$2:H$28,$A12) -> 1 | I12: =COUNTIF(Hdsmth!I$2:I$28,$A12) -> 2 | ... N12: =COUNTIF(Hdsmth!N$2:N$28,$A12) -> 2
A13: 12 | B13: =COUNTIF(Hdsmth!B$2:B$28,$A13) -> 2 | C13: =COUNTIF(Hdsmth!C$2:C$28,$A13) -> 1 | D13: =COUNTIF(Hdsmth!D$2:D$28,$A13) -> 2 | E13: =COUNTIF(Hdsmth!E$2:E$28,$A13) -> 1 | F13: =COUNTIF(Hdsmth!F$2:F$28,$A13) -> 1 | G13: =COUNTIF(Hdsmth!G$2:G$28,$A13) -> 2 | H13: =COUNTIF(Hdsmth!H$2:H$28,$A13) -> 2 | I13: =COUNTIF(Hdsmth!I$2:I$28,$A13) -> 1 | ... N13: =COUNTIF(Hdsmth!N$2:N$28,$A13) -> 3
... A20: 19 | B20: =COUNTIF(Hdsmth!B$2:B$28,$A20) -> 1 | C20: =COUNTIF(Hdsmth!C$2:C$28,$A20) -> 1 | D20: =COUNTIF(Hdsmth!D$2:D$28,$A20) -> 1 | E20: =COUNTIF(Hdsmth!E$2:E$28,$A20) -> 0 | F20: =COUNTIF(Hdsmth!F$2:F$28,$A20) -> 1 | G20: =COUNTIF(Hdsmth!G$2:G$28,$A20) -> 1 | H20: =COUNTIF(Hdsmth!H$2:H$28,$A20) -> 2 | I20: =COUNTIF(Hdsmth!I$2:I$28,$A20) -> 2 | ... N20: =COUNTIF(Hdsmth!N$2:N$28,$A20) -> 1
B22: g1 | C22: g2 | D22: g3 | E22: g4 | F22: g5 | G22: g6 | H22: g7 | I22: g8 | J22: g9 | K22: g10 | L22: g11 | M22: g12 | N22: g13
A23: 1v2 | B23: =B2-B3 -> 0 | C23: =C2-C3 -> 0 | D23: =D2-D3 -> 0 | E23: =E2-E3 -> -1 | F23: =F2-F3 -> -1 | G23: =G2-G3 -> -1 | H23: =H2-H3 -> 0 | I23: =I2-I3 -> 0 | ... N23: =N2-N3 -> 2
A24: 2v3 | B24: =B3-B4 -> 0 | C24: =C3-C4 -> 0 | D24: =D3-D4 -> 0 | E24: =E3-E4 -> -1 | F24: =F3-F4 -> 0 | G24: =G3-G4 -> 0 | H24: =H3-H4 -> -1 | I24: =I3-I4 -> -1 | ... N24: =N3-N4 -> 0
A25: 3v4 | B25: =B4-B5 -> 0 | C25: =C4-C5 -> 0 | D25: =D4-D5 -> 0 | E25: =E4-E5 -> 1 | F25: =F4-F5 -> -1 | G25: =G4-G5 -> 0 | H25: =H4-H5 -> -1 | I25: =I4-I5 -> 0 | ... N25: =N4-N5 -> -1
A26: 4v5 | B26: =B5-B6 -> 0 | C26: =C5-C6 -> 0 | D26: =D5-D6 -> 0 | E26: =E5-E6 -> 0 | F26: =F5-F6 -> 1 | G26: =G5-G6 -> 0 | H26: =H5-H6 -> 1 | I26: =I5-I6 -> 0 | ... N26: =N5-N6 -> 1
A27: 5v6 | B27: =B6-B7 -> 1 | C27: =C6-C7 -> 1 | D27: =D6-D7 -> 0 | E27: =E6-E7 -> 0 | F27: =F6-F7 -> 1 | G27: =G6-G7 -> 0 | H27: =H6-H7 -> 1 | I27: =I6-I7 -> 1 | ... N27: =N6-N7 -> -1
A28: 6v7 | B28: =B7-B8 -> -1 | C28: =C7-C8 -> -1 | D28: =D7-D8 -> 1 | E28: =E7-E8 -> 0 | F28: =F7-F8 -> -1 | G28: =G7-G8 -> 0 | H28: =H7-H8 -> -1 | I28: =I7-I8 -> -1 | ... N28: =N7-N8 -> -1
A29: 7v8 | B29: =B8-B9 -> 0 | C29: =C8-C9 -> 0 | D29: =D8-D9 -> -1 | E29: =E8-E9 -> 0 | F29: =F8-F9 -> 0 | G29: =G8-G9 -> 0 | H29: =H8-H9 -> 0 | I29: =I8-I9 -> 0 | ... N29: =N8-N9 -> 1
A30: 8v9 | B30: =B9-B10 -> 1 | C30: =C9-C10 -> 0 | D30: =D9-D10 -> 0 | E30: =E9-E10 -> 1 | F30: =F9-F10 -> 0 | G30: =G9-G10 -> 0 | H30: =H9-H10 -> 0 | I30: =I9-I10 -> 0 | ... N30: =N9-N10 -> -1
A31: 9v10 | B31: =B10-B11 -> -1 | C31: =C10-C11 -> 1 | D31: =D10-D11 -> 0 | E31: =E10-E11 -> -1 | F31: =F10-F11 -> 0 | G31: =G10-G11 -> 0 | H31: =H10-H11 -> 0 | I31: =I10-I11 -> 1 | ... N31: =N10-N11 -> 0
A32: 10v11 | B32: =B11-B12 -> 1 | C32: =C11-C12 -> -1 | D32: =D11-D12 -> 1 | E32: =E11-E12 -> 0 | F32: =F11-F12 -> 0 | G32: =G11-G12 -> 1 | H32: =H11-H12 -> 1 | I32: =I11-I12 -> -1 | ... N32: =N11-N12 -> 0
A33: 11v12 | B33: =B12-B13 -> -1 | C33: =C12-C13 -> 1 | D33: =D12-D13 -> -1 | E33: =E12-E13 -> 1 | F33: =F12-F13 -> 1 | G33: =G12-G13 -> -1 | H33: =H12-H13 -> -1 | I33: =I12-I13 -> 1 | ... N33: =N12-N13 -> -1
A34: 12v13 | B34: =B13-B14 -> 1 | C34: =C13-C14 -> 0 | D34: =D13-D14 -> 1 | E34: =E13-E14 -> 0 | F34: =F13-F14 -> 0 | G34: =G13-G14 -> 1 | H34: =H13-H14 -> 1 | I34: =I13-I14 -> -1 | ... N34: =N13-N14 -> 1
... A40: 18v19 | B40: =B19-B20 -> -1 | C40: =C19-C20 -> -1 | D40: =D19-D20 -> -1 | E40: =E19-E20 -> 1 | F40: =F19-F20 -> -1 | G40: =G19-G20 -> -1 | H40: =H19-H20 -> -2 | I40: =I19-I20 -> -2 | ... N40: =N19-N20 -> 0
B43: g1v2 | C43: g2v3 | D43: g3v4 | E43: g4v5 | F43: g5v6 | G43: g6v7 | H43: g7v8 | I43: g8v9 | J43: g9v10 | K43: g10v11 | L43: g11v12 | M43: g12v13
A44: 1 | B44: =C2-B2 -> 0 | C44: =D2-C2 -> 0 | D44: =E2-D2 -> -1 | E44: =F2-E2 -> 0 | F44: =G2-F2 -> 0 | G44: =H2-G2 -> 0 | H44: =I2-H2 -> 0 | I44: =J2-I2 -> 0 | ... M44: =N2-M2 -> 0
A45: 2 | B45: =C3-B3 -> 0 | C45: =D3-C3 -> 0 | D45: =E3-D3 -> 0 | E45: =F3-E3 -> 0 | F45: =G3-F3 -> 0 | G45: =H3-G3 -> -1 | H45: =I3-H3 -> 0 | I45: =J3-I3 -> -1 | ... M45: =N3-M3 -> 0
A46: 3 | B46: =C4-B4 -> 0 | C46: =D4-C4 -> 0 | D46: =E4-D4 -> 1 | E46: =F4-E4 -> -1 | F46: =G4-F4 -> 0 | G46: =H4-G4 -> 0 | H46: =I4-H4 -> 0 | I46: =J4-I4 -> 0 | ... M46: =N4-M4 -> -1
A47: 4 | B47: =C5-B5 -> 0 | C47: =D5-C5 -> 0 | D47: =E5-D5 -> 0 | E47: =F5-E5 -> 1 | F47: =G5-F5 -> -1 | G47: =H5-G5 -> 1 | H47: =I5-H5 -> -1 | I47: =J5-I5 -> 0 | ... M47: =N5-M5 -> 1
A48: 5 | B48: =C6-B6 -> 0 | C48: =D6-C6 -> 0 | D48: =E6-D6 -> 0 | E48: =F6-E6 -> 0 | F48: =G6-F6 -> 0 | G48: =H6-G6 -> 0 | H48: =I6-H6 -> 0 | I48: =J6-I6 -> 0 | ... M48: =N6-M6 -> -1
A49: 6 | B49: =C7-B7 -> 0 | C49: =D7-C7 -> 1 | D49: =E7-D7 -> 0 | E49: =F7-E7 -> -1 | F49: =G7-F7 -> 1 | G49: =H7-G7 -> -1 | H49: =I7-H7 -> 0 | I49: =J7-I7 -> 0 | ... M49: =N7-M7 -> -1
A50: 7 | B50: =C8-B8 -> 0 | C50: =D8-C8 -> -1 | D50: =E8-D8 -> 1 | E50: =F8-E8 -> 0 | F50: =G8-F8 -> 0 | G50: =H8-G8 -> 0 | H50: =I8-H8 -> 0 | I50: =J8-I8 -> 0 | ... M50: =N8-M8 -> 1
A51: 8 | B51: =C9-B9 -> 0 | C51: =D9-C9 -> 0 | D51: =E9-D9 -> 0 | E51: =F9-E9 -> 0 | F51: =G9-F9 -> 0 | G51: =H9-G9 -> 0 | H51: =I9-H9 -> 0 | I51: =J9-I9 -> 0 | ... M51: =N9-M9 -> 0
A52: 9 | B52: =C10-B10 -> 1 | C52: =D10-C10 -> 0 | D52: =E10-D10 -> -1 | E52: =F10-E10 -> 1 | F52: =G10-F10 -> 0 | G52: =H10-G10 -> 0 | H52: =I10-H10 -> 0 | I52: =J10-I10 -> -1 | ... M52: =N10-M10 -> 0
A53: 10 | B53: =C11-B11 -> -1 | C53: =D11-C11 -> 1 | D53: =E11-D11 -> 0 | E53: =F11-E11 -> 0 | F53: =G11-F11 -> 0 | G53: =H11-G11 -> 0 | H53: =I11-H11 -> -1 | I53: =J11-I11 -> 1 | ... M53: =N11-M11 -> 0
A54: 11 | B54: =C12-B12 -> 1 | C54: =D12-C12 -> -1 | D54: =E12-D12 -> 1 | E54: =F12-E12 -> 0 | F54: =G12-F12 -> -1 | G54: =H12-G12 -> 0 | H54: =I12-H12 -> 1 | I54: =J12-I12 -> 0 | ... M54: =N12-M12 -> 0
...
