Workbook
Name IDX: QA!$A$1

Sheet control
A1: type | B1: Power | C1: _1 | D1: _2 | E1: _3 | F1: _4 | G1: _5 | H1: _6 | I1: _7 | J1: _8 | K1: _9 | L1: _10 | M1: _11 | N1: _12 | O1: _13
A2: Obs | B2: . | C2: 21.083333 | D2: 23.227778 | E2: 25.905556 | F2: 26.55 | G2: 27.127778 | H2: 27.266667 | I2: 28.75 | J2: 28.111111 | K2: 28.394444 | L2: 28.21 | M2: 28.85 | N2: 26.11 | O2: 25.3
A3: mean | B3: 3 | C3: 22.5236 | D3: 23.2683 | E3: 24.4473 | F3: 25.8687 | G3: 26.9985 | H3: 28.1892 | I3: 28.9386 | J3: 28.8734 | K3: 28.3838 | L3: 27.8843 | M3: 27.269 | N3: 26.5575 | O3: 25.6871
A4: SD | B4: 3 | C4: 6.8007 | D4: 6.9642 | E4: 7.219 | F4: 7.5187 | G4: 7.7498 | H4: 7.9856 | I4: 8.1356 | J4: 8.1569 | K4: 8.1272 | L4: 8.1009 | M4: 8.0787 | N4: 8.0687 | O4: 8.0815
A5: skew | B5: 4 | C5: -0.0162 | D5: -0.1952 | E5: -0.4262 | F5: -0.6142 | G5: -0.6874 | H5: -0.684 | I5: -0.6347 | J5: -0.6374 | K5: -0.6501 | L5: -0.6214 | M5: -0.5192 | N5: -0.2939 | O5: 0.1686
E9: mean | F9: SD | G9: skew
D10: Power | E10: 3 | F10: 3 | G10: 4
D11: 1 | E11: 22.5236 | F11: 6.8007 | G11: -0.0162
D12: 2 | E12: 23.2683 | F12: 6.9642 | G12: -0.1952
D13: 3 | E13: 24.4473 | F13: 7.219 | G13: -0.4262
D14: 4 | E14: 25.8687 | F14: 7.5187 | G14: -0.6142
D15: 5 | E15: 26.9985 | F15: 7.7498 | G15: -0.6874
D16: 6 | E16: 28.1892 | F16: 7.9856 | G16: -0.684
D17: 7 | E17: 28.9386 | F17: 8.1356 | G17: -0.6347
D18: 8 | E18: 28.8734 | F18: 8.1569 | G18: -0.6374
D19: 9 | E19: 28.3838 | F19: 8.1272 | G19: -0.6501
D20: 10 | E20: 27.8843 | F20: 8.1009 | G20: -0.6214
D21: 11 | E21: 27.269 | F21: 8.0787 | G21: -0.5192
D22: 12 | E22: 26.5575 | F22: 8.0687 | G22: -0.2939
D23: 13 | E23: 25.6871 | F23: 8.0815 | G23: 0.1686
B25: 1 | C25: 180 | D25: 180 | E25: 21.083333 | F25: 6.7582972 | G25: 9 | H25: 37
B26: 2 | C26: 180 | D26: 180 | E26: 23.227778 | F26: 7.3945704 | G26: 7 | H26: 40
B27: 3 | C27: 180 | D27: 180 | E27: 25.905556 | F27: 6.7812568 | G27: 9 | H27: 41
B28: 4 | C28: 180 | D28: 180 | E28: 26.55 | F28: 7.1349913 | G28: 4 | H28: 44
B29: 5 | C29: 180 | D29: 180 | E29: 27.127778 | F29: 8.2867806 | G29: 0 | H29: 44
B30: 6 | C30: 180 | D30: 180 | E30: 27.266667 | F30: 7.8467159 | G30: 7 | H30: 45
B31: 7 | C31: 180 | D31: 180 | E31: 28.75 | F31: 7.8305197 | G31: 7 | H31: 44
B32: 8 | C32: 180 | D32: 180 | E32: 28.111111 | F32: 8.8272615 | G32: 4 | H32: 45
B33: 9 | C33: 180 | D33: 180 | E33: 28.394444 | F33: 8.2166864 | G33: 7 | H33: 45
B34: 10 | C34: 100 | D34: 100 | E34: 28.21 | F34: 7.4823631 | G34: 11 | H34: 44
B35: 11 | C35: 100 | D35: 100 | E35: 28.85 | F35: 7.933276 | G35: 9 | H35: 44
B36: 12 | C36: 100 | D36: 100 | E36: 26.11 | F36: 8.3688878 | G36: 8 | H36: 42
B37: 13 | C37: 100 | D37: 100 | E37: 25.3 | F37: 8.0760276 | G37: 10 | H37: 45

Sheet handsmoothed
A1: vctot | B1: ss1 | C1: ss2 | D1: ss3 | E1: ss4 | F1: ss5 | G1: ss6 | H1: ss7 | I1: ss8 | J1: ss9 | K1: ss10 | L1: ss11 | M1: ss12 | N1: ss13 | O1: ReverseCross | P1: c1_2 | Q1: c2_3 | R1: c3_4 | S1: c4_5 | T1: c5_6 | U1: c6_7 | V1: c7_8 | W1: c8_9 | X1: c9_10 | Y1: c10_11 | Z1: c11_12 | AA1: c12_13 | AB1: ReverseDown | AC1: d1 | AD1: d2 | AE1: d3 | AF1: d4 | AG1: d5 | AH1: d6 | AI1: d7 | AJ1: d8 | AK1: d9 | AL1: d10 | AM1: d11 | AN1: d12 | AO1: d13 | AP1: QA
A2: 0 | B2: 1 | C2: 1 | D2: 1 | E2: 1 | F2: 1 | G2: 1 | H2: 1 | I2: 1 | J2: 1 | K2: 1 | L2: 1 | M2: 1 | N2: 1 | P2: =B2-C2 -> 0 | Q2: =C2-D2 -> 0 | R2: =D2-E2 -> 0 | S2: =E2-F2 -> 0 | T2: =F2-G2 -> 0 | U2: =G2-H2 -> 0 | V2: =H2-I2 -> 0 | W2: =I2-J2 -> 0 | ... AA2: =M2-N2 -> 0 | AC2: =B3-B2 -> 0 | AD2: =C3-C2 -> 0 | AE2: =D3-D2 -> 0 | AF2: =E3-E2 -> 0 | AG2: =F3-F2 -> 0 | AH2: =G3-G2 -> 0 | AI2: =H3-H2 -> 0 | AJ2: =I3-I2 -> 0 | ... AO2: =N3-N2 -> 0 | AP2: RIGHT
A3: 1 | B3: 1 | C3: 1 | D3: 1 | E3: 1 | F3: 1 | G3: 1 | H3: 1 | I3: 1 | J3: 1 | K3: 1 | L3: 1 | M3: 1 | N3: 1 | P3: =B3-C3 -> 0 | Q3: =C3-D3 -> 0 | R3: =D3-E3 -> 0 | S3: =E3-F3 -> 0 | T3: =F3-G3 -> 0 | U3: =G3-H3 -> 0 | V3: =H3-I3 -> 0 | W3: =I3-J3 -> 0 | ... AA3: =M3-N3 -> 0 | AC3: =B4-B3 -> 1 | AD3: =C4-C3 -> 0 | AE3: =D4-D3 -> 0 | AF3: =E4-E3 -> 0 | AG3: =F4-F3 -> 0 | AH3: =G4-G3 -> 0 | AI3: =H4-H3 -> 0 | AJ3: =I4-I3 -> 0 | ... AO3: =N4-N3 -> 1 | AP3: RIGHT
A4: 2 | B4: 2 | C4: 1 | D4: 1 | E4: 1 | F4: 1 | G4: 1 | H4: 1 | I4: 1 | J4: 1 | K4: 1 | L4: 1 | M4: 1 | N4: 2 | P4: =B4-C4 -> 1 | Q4: =C4-D4 -> 0 | R4: =D4-E4 -> 0 | S4: =E4-F4 -> 0 | T4: =F4-G4 -> 0 | U4: =G4-H4 -> 0 | V4: =H4-I4 -> 0 | W4: =I4-J4 -> 0 | ... AA4: =M4-N4 -> -1 | AC4: =B5-B4 -> 0 | AD4: =C5-C4 -> 1 | AE4: =D5-D4 -> 0 | AF4: =E5-E4 -> 0 | AG4: =F5-F4 -> 0 | AH4: =G5-G4 -> 0 | AI4: =H5-H4 -> 0 | AJ4: =I5-I4 -> 0 | ... AO4: =N5-N4 -> 0 | AP4: RIGHT
A5: 3 | B5: 2 | C5: 2 | D5: 1 | E5: 1 | F5: 1 | G5: 1 | H5: 1 | I5: 1 | J5: 2 | K5: 2 | L5: 2 | M5: 2 | N5: 2 | P5: =B5-C5 -> 0 | Q5: =C5-D5 -> 1 | R5: =D5-E5 -> 0 | S5: =E5-F5 -> 0 | T5: =F5-G5 -> 0 | U5: =G5-H5 -> 0 | V5: =H5-I5 -> 0 | W5: =I5-J5 -> -1 | ... AA5: =M5-N5 -> 0 | AC5: =B6-B5 -> 1 | AD5: =C6-C5 -> 0 | AE5: =D6-D5 -> 1 | AF5: =E6-E5 -> 1 | AG5: =F6-F5 -> 1 | AH5: =G6-G5 -> 1 | AI5: =H6-H5 -> 1 | AJ5: =I6-I5 -> 1 | ... AO5: =N6-N5 -> 1 | AP5: RIGHT
A6: 4 | B6: 3 | C6: 2 | D6: 2 | E6: 2 | F6: 2 | G6: 2 | H6: 2 | I6: 2 | J6: 2 | K6: 2 | L6: 2 | M6: 2 | N6: 3 | P6: =B6-C6 -> 1 | Q6: =C6-D6 -> 0 | R6: =D6-E6 -> 0 | S6: =E6-F6 -> 0 | T6: =F6-G6 -> 0 | U6: =G6-H6 -> 0 | V6: =H6-I6 -> 0 | W6: =I6-J6 -> 0 | ... AA6: =M6-N6 -> -1 | AC6: =B7-B6 -> 0 | AD6: =C7-C6 -> 1 | AE6: =D7-D6 -> 0 | AF6: =E7-E6 -> 0 | AG6: =F7-F6 -> 0 | AH6: =G7-G6 -> 0 | AI6: =H7-H6 -> 0 | AJ6: =I7-I6 -> 0 | ... AO6: =N7-N6 -> 0 | AP6: RIGHT
A7: 5 | B7: 3 | C7: 3 | D7: 2 | E7: 2 | F7: 2 | G7: 2 | H7: 2 | I7: 2 | J7: 3 | K7: 3 | L7: 3 | M7: 3 | N7: 3 | P7: =B7-C7 -> 0 | Q7: =C7-D7 -> 1 | R7: =D7-E7 -> 0 | S7: =E7-F7 -> 0 | T7: =F7-G7 -> 0 | U7: =G7-H7 -> 0 | V7: =H7-I7 -> 0 | W7: =I7-J7 -> -1 | ... AA7: =M7-N7 -> 0 | AC7: =B8-B7 -> 1 | AD7: =C8-C7 -> 0 | AE7: =D8-D7 -> 1 | AF7: =E8-E7 -> 1 | AG7: =F8-F7 -> 1 | AH7: =G8-G7 -> 1 | AI7: =H8-H7 -> 1 | AJ7: =I8-I7 -> 1 | ... AO7: =N8-N7 -> 0 | AP7: RIGHT
A8: 6 | B8: 4 | C8: 3 | D8: 3 | E8: 3 | F8: 3 | G8: 3 | H8: 3 | I8: 3 | J8: 3 | K8: 3 | L8: 3 | M8: 3 | N8: 3 | P8: =B8-C8 -> 1 | Q8: =C8-D8 -> 0 | R8: =D8-E8 -> 0 | S8: =E8-F8 -> 0 | T8: =F8-G8 -> 0 | U8: =G8-H8 -> 0 | V8: =H8-I8 -> 0 | W8: =I8-J8 -> 0 | ... AA8: =M8-N8 -> 0 | AC8: =B9-B8 -> 0 | AD8: =C9-C8 -> 0 | AE8: =D9-D8 -> 0 | AF8: =E9-E8 -> 0 | AG8: =F9-F8 -> 0 | AH8: =G9-G8 -> 0 | AI8: =H9-H8 -> 0 | AJ8: =I9-I8 -> 0 | ... AO8: =N9-N8 -> 1 | AP8: RIGHT
A9: 7 | B9: 4 | C9: 3 | D9: 3 | E9: 3 | F9: 3 | G9: 3 | H9: 3 | I9: 3 | J9: 3 | K9: 3 | L9: 3 | M9: 3 | N9: 4 | P9: =B9-C9 -> 1 | Q9: =C9-D9 -> 0 | R9: =D9-E9 -> 0 | S9: =E9-F9 -> 0 | T9: =F9-G9 -> 0 | U9: =G9-H9 -> 0 | V9: =H9-I9 -> 0 | W9: =I9-J9 -> 0 | ... AA9: =M9-N9 -> -1 | AC9: =B10-B9 -> 0 | AD9: =C10-C9 -> 1 | AE9: =D10-D9 -> 0 | AF9: =E10-E9 -> 0 | AG9: =F10-F9 -> 0 | AH9: =G10-G9 -> 0 | AI9: =H10-H9 -> 0 | AJ9: =I10-I9 -> 0 | ... AO9: =N10-N9 -> 0 | AP9: RIGHT
A10: 8 | B10: 4 | C10: 4 | D10: 3 | E10: 3 | F10: 3 | G10: 3 | H10: 3 | I10: 3 | J10: 4 | K10: 4 | L10: 4 | M10: 4 | N10: 4 | P10: =B10-C10 -> 0 | Q10: =C10-D10 -> 1 | R10: =D10-E10 -> 0 | S10: =E10-F10 -> 0 | T10: =F10-G10 -> 0 | U10: =G10-H10 -> 0 | V10: =H10-I10 -> 0 | W10: =I10-J10 -> -1 | ... AA10: =M10-N10 -> 0 | AC10: =B11-B10 -> 1 | AD10: =C11-C10 -> 0 | AE10: =D11-D10 -> 1 | AF10: =E11-E10 -> 1 | AG10: =F11-F10 -> 1 | AH10: =G11-G10 -> 1 | AI10: =H11-H10 -> 1 | AJ10: =I11-I10 -> 1 | ... AO10: =N11-N10 -> 0 | AP10: RIGHT
A11: 9 | B11: 5 | C11: 4 | D11: 4 | E11: 4 | F11: 4 | G11: 4 | H11: 4 | I11: 4 | J11: 4 | K11: 4 | L11: 4 | M11: 4 | N11: 4 | P11: =B11-C11 -> 1 | Q11: =C11-D11 -> 0 | R11: =D11-E11 -> 0 | S11: =E11-F11 -> 0 | T11: =F11-G11 -> 0 | U11: =G11-H11 -> 0 | V11: =H11-I11 -> 0 | W11: =I11-J11 -> 0 | ... AA11: =M11-N11 -> 0 | AC11: =B12-B11 -> 0 | AD11: =C12-C11 -> 0 | AE11: =D12-D11 -> 0 | AF11: =E12-E11 -> 0 | AG11: =F12-F11 -> 0 | AH11: =G12-G11 -> 0 | AI11: =H12-H11 -> 0 | AJ11: =I12-I11 -> 0 | ... AO11: =N12-N11 -> 1 | AP11: RIGHT
A12: 10 | B12: 5 | C12: 4 | D12: 4 | E12: 4 | F12: 4 | G12: 4 | H12: 4 | I12: 4 | J12: 4 | K12: 4 | L12: 4 | M12: 4 | N12: 5 | P12: =B12-C12 -> 1 | Q12: =C12-D12 -> 0 | R12: =D12-E12 -> 0 | S12: =E12-F12 -> 0 | T12: =F12-G12 -> 0 | U12: =G12-H12 -> 0 | V12: =H12-I12 -> 0 | W12: =I12-J12 -> 0 | ... AA12: =M12-N12 -> -1 | AC12: =B13-B12 -> 0 | AD12: =C13-C12 -> 1 | AE12: =D13-D12 -> 0 | AF12: =E13-E12 -> 0 | AG12: =F13-F12 -> 0 | AH12: =G13-G12 -> 0 | AI12: =H13-H12 -> 0 | AJ12: =I13-I12 -> 0 | ... AO12: =N13-N12 -> 0 | AP12: RIGHT
A13: 11 | B13: 5 | C13: 5 | D13: 4 | E13: 4 | F13: 4 | G13: 4 | H13: 4 | I13: 4 | J13: 4 | K13: 4 | L13: 4 | M13: 5 | N13: 5 | P13: =B13-C13 -> 0 | Q13: =C13-D13 -> 1 | R13: =D13-E13 -> 0 | S13: =E13-F13 -> 0 | T13: =F13-G13 -> 0 | U13: =G13-H13 -> 0 | V13: =H13-I13 -> 0 | W13: =I13-J13 -> 0 | ... AA13: =M13-N13 -> 0 | AC13: =B14-B13 -> 1 | AD13: =C14-C13 -> 0 | AE13: =D14-D13 -> 1 | AF13: =E14-E13 -> 1 | AG13: =F14-F13 -> 1 | AH13: =G14-G13 -> 1 | AI13: =H14-H13 -> 1 | AJ13: =I14-I13 -> 1 | ... AO13: =N14-N13 -> 1 | AP13: RIGHT
... A46: 44 | B46: 19 | C46: 19 | D46: 19 | E46: 19 | F46: 18 | G46: 18 | H46: 18 | I46: 18 | J46: 18 | K46: 18 | L46: 18 | M46: 18 | N46: 18 | P46: =B46-C46 -> 0 | Q46: =C46-D46 -> 0 | R46: =D46-E46 -> 0 | S46: =E46-F46 -> 1 | T46: =F46-G46 -> 0 | U46: =G46-H46 -> 0 | V46: =H46-I46 -> 0 | W46: =I46-J46 -> 0 | ... AA46: =M46-N46 -> 0 | AC46: =B47-B46 -> 0 | AD46: =C47-C46 -> 0 | AE46: =D47-D46 -> 0 | AF46: =E47-E46 -> 0 | AG46: =F47-F46 -> 1 | AH46: =G47-G46 -> 1 | AI46: =H47-H46 -> 1 | AJ46: =I47-I46 -> 1 | ... AO46: =N47-N46 -> 1 | AP46: RIGHT
A47: 45 | B47: 19 | C47: 19 | D47: 19 | E47: 19 | F47: 19 | G47: 19 | H47: 19 | I47: 19 | J47: 19 | K47: 19 | L47: 19 | M47: 19 | N47: 19 | P47: =B47-C47 -> 0 | Q47: =C47-D47 -> 0 | R47: =D47-E47 -> 0 | S47: =E47-F47 -> 0 | T47: =F47-G47 -> 0 | U47: =G47-H47 -> 0 | V47: =H47-I47 -> 0 | W47: =I47-J47 -> 0 | ... AA47: =M47-N47 -> 0 | AP47: RIGHT
A48: N | B48: =SUM(freq!B2:B47) -> 180 | C48: =SUM(freq!C2:C47) -> 180 | D48: =SUM(freq!D2:D47) -> 180 | E48: =SUM(freq!E2:E47) -> 180 | F48: =SUM(freq!F2:F47) -> 180 | G48: =SUM(freq!G2:G47) -> 180 | H48: =SUM(freq!H2:H47) -> 180 | I48: =SUM(freq!I2:I47) -> 180 | ... N48: =SUM(freq!N2:N47) -> 100 | O48: =SUM(B48:N48) -> 2020
A49: MEAN | B49: =freq!B48/B48 -> 9.7222222 | C49: =freq!C48/C48 -> 9.9611111 | D49: =freq!D48/D48 -> 10.255556 | E49: =freq!E48/E48 -> 10.116667 | F49: =freq!F48/F48 -> 10.044444 | G49: =freq!G48/G48 -> 9.7555556 | H49: =freq!H48/H48 -> 10.055556 | I49: =freq!I48/I48 -> 9.9055556 | ... O49: =freq!O48/O48 -> 10.00198
A50: SD | B50: =SQRT((freq!B49-B49^2*B48)/(B48-1)) -> 3.0195926 | C50: =SQRT((freq!C49-C49^2*C48)/(C48-1)) -> 3.152305 | D50: =SQRT((freq!D49-D49^2*D48)/(D48-1)) -> 2.8873104 | E50: =SQRT((freq!E49-E49^2*E48)/(E48-1)) -> 2.8584385 | F50: =SQRT((freq!F49-F49^2*F48)/(F48-1)) -> 3.1654952 | G50: =SQRT((freq!G49-G49^2*G48)/(G48-1)) -> 2.940038 | H50: =SQRT((freq!H49-H49^2*H48)/(H48-1)) -> 2.9096684 | I50: =SQRT((freq!I49-I49^2*I48)/(I48-1)) -> 3.293293 | ... O50: =SQRT((freq!O49-O49^2*O48)/(O48-1)) -> 2.9941326
A51: IDEALm | B51: =0.3-ABS(10-ROUND(B49,2)) -> 0.02 | C51: =0.3-ABS(10-ROUND(C49,2)) -> 0.26 | D51: =0.3-ABS(10-ROUND(D49,2)) -> 0.04 | E51: =0.3-ABS(10-ROUND(E49,2)) -> 0.18 | F51: =0.3-ABS(10-ROUND(F49,2)) -> 0.26 | G51: =0.3-ABS(10-ROUND(G49,2)) -> 0.06 | H51: =0.3-ABS(10-ROUND(H49,2)) -> 0.24 | I51: =0.3-ABS(10-ROUND(I49,2)) -> 0.21 | ... O51: =0.3-ABS(10-ROUND(O49,2)) -> 0.3
A52: IDEALs | B52: =0.3-ABS(3-ROUND(B50,2)) -> 0.28 | C52: =0.3-ABS(3-ROUND(C50,2)) -> 0.15 | D52: =0.3-ABS(3-ROUND(D50,2)) -> 0.19 | E52: =0.3-ABS(3-ROUND(E50,2)) -> 0.16 | F52: =0.3-ABS(3-ROUND(F50,2)) -> 0.13 | G52: =0.3-ABS(3-ROUND(G50,2)) -> 0.24 | H52: =0.3-ABS(3-ROUND(H50,2)) -> 0.21 | I52: =0.3-ABS(3-ROUND(I50,2)) -> 0.01 | ... O52: =0.3-ABS(3-ROUND(O50,2)) -> 0.29
A53: STANDARDm | B53: =0.6-ABS(10-ROUND(B49,2)) -> 0.32 | C53: =0.6-ABS(10-ROUND(C49,2)) -> 0.56 | D53: =0.6-ABS(10-ROUND(D49,2)) -> 0.34 | E53: =0.6-ABS(10-ROUND(E49,2)) -> 0.48 | F53: =0.6-ABS(10-ROUND(F49,2)) -> 0.56 | G53: =0.6-ABS(10-ROUND(G49,2)) -> 0.36 | H53: =0.6-ABS(10-ROUND(H49,2)) -> 0.54 | I53: =0.6-ABS(10-ROUND(I49,2)) -> 0.51 | ... O53: =0.6-ABS(10-ROUND(O49,2)) -> 0.6
A54: STANDARDs | B54: =0.3-ABS(3-ROUND(B50,2)) -> 0.28 | C54: =0.3-ABS(3-ROUND(C50,2)) -> 0.15 | D54: =0.3-ABS(3-ROUND(D50,2)) -> 0.19 | E54: =0.3-ABS(3-ROUND(E50,2)) -> 0.16 | F54: =0.3-ABS(3-ROUND(F50,2)) -> 0.13 | G54: =0.3-ABS(3-ROUND(G50,2)) -> 0.24 | H54: =0.3-ABS(3-ROUND(H50,2)) -> 0.21 | I54: =0.3-ABS(3-ROUND(I50,2)) -> 0.01 | ... O54: =0.3-ABS(3-ROUND(O50,2)) -> 0.29
A55: EXCEPIONm | B55: =0.9-ABS(10-ROUND(B49,2)) -> 0.62 | C55: =0.9-ABS(10-ROUND(C49,2)) -> 0.86 | D55: =0.9-ABS(10-ROUND(D49,2)) -> 0.64 | E55: =0.9-ABS(10-ROUND(E49,2)) -> 0.78 | F55: =0.9-ABS(10-ROUND(F49,2)) -> 0.86 | G55: =0.9-ABS(10-ROUND(G49,2)) -> 0.66 | H55: =0.9-ABS(10-ROUND(H49,2)) -> 0.84 | I55: =0.9-ABS(10-ROUND(I49,2)) -> 0.81 | ... O55: =0.9-ABS(10-ROUND(O49,2)) -> 0.9
A56: EXCEPIONs | B56: =0.45-ABS(3-ROUND(B50,2)) -> 0.43 | C56: =0.45-ABS(3-ROUND(C50,2)) -> 0.3 | D56: =0.45-ABS(3-ROUND(D50,2)) -> 0.34 | E56: =0.45-ABS(3-ROUND(E50,2)) -> 0.31 | F56: =0.45-ABS(3-ROUND(F50,2)) -> 0.28 | G56: =0.45-ABS(3-ROUND(G50,2)) -> 0.39 | H56: =0.45-ABS(3-ROUND(H50,2)) -> 0.36 | I56: =0.45-ABS(3-ROUND(I50,2)) -> 0.16 | ... O56: =0.45-ABS(3-ROUND(O50,2)) -> 0.44
A57: N1 | B57: =SUM(freq!B2:B47) -> 180 | C57: =SUM(freq!C2:C47) -> 180 | D57: =SUM(freq!D2:D47) -> 180 | E57: =SUM(freq!E2:E47) -> 180 | F57: =SUM(freq!F2:F47) -> 180 | G57: =SUM(freq!G2:G47) -> 180 | H57: =SUM(freq!H2:H47) -> 180 | I57: =SUM(freq!I2:I47) -> 180 | ... N57: =SUM(freq!N2:N47) -> 100
A58: MEAN1 | B58: =freq!B48/B57 -> 9.7222222 | C58: =freq!C48/C57 -> 9.9611111 | D58: =freq!D48/D57 -> 10.255556 | E58: =freq!E48/E57 -> 10.116667 | F58: =freq!F48/F57 -> 10.044444 | G58: =freq!G48/G57 -> 9.7555556 | H58: =freq!H48/H57 -> 10.055556 | I58: =freq!I48/I57 -> 9.9055556 | ... N58: =freq!N48/N57 -> 9.9
A59: SD1 | B59: =SQRT((freq!B49-B58^2*B57)/(B57-1)) -> 3.0195926 | C59: =SQRT((freq!C49-C58^2*C57)/(C57-1)) -> 3.152305 | D59: =SQRT((freq!D49-D58^2*D57)/(D57-1)) -> 2.8873104 | E59: =SQRT((freq!E49-E58^2*E57)/(E57-1)) -> 2.8584385 | F59: =SQRT((freq!F49-F58^2*F57)/(F57-1)) -> 3.1654952 | G59: =SQRT((freq!G49-G58^2*G57)/(G57-1)) -> 2.940038 | H59: =SQRT((freq!H49-H58^2*H57)/(H57-1)) -> 2.9096684 | I59: =SQRT((freq!I49-I58^2*I57)/(I57-1)) -> 3.293293 | ... N59: =SQRT((freq!N49-N58^2*N57)/(N57-1)) -> 2.9593202

Sheet checksmooth
B1: g1 | C1: g2 | D1: g3 | E1: g4 | F1: g5 | G1: g6 | H1: g7 | I1: g8 | J1: g9 | K1: g10 | L1: g11 | M1: g12 | N1: g13 | Q1: g1 | R1: g2 | S1: g3 | T1: g4 | U1: g5 | V1: g6 | W1: g7 | X1: g8 | Y1: g9 | Z1: g10 | AA1: g11 | AB1: g12 | AF1: g1 | AG1: g2 | AH1: g3 | AI1: g4 | AJ1: g5 | AK1: g6 | AL1: g7 | AM1: g8 | AN1: g9 | AO1: g10 | AP1: g11 | AQ1: g12 | AR1: g13
A2: 1 | B2: =COUNTIF(handsmoothed!B$2:B$47,$A2) -> 2 | C2: =COUNTIF(handsmoothed!C$2:C$47,$A2) -> 3 | D2: =COUNTIF(handsmoothed!D$2:D$47,$A2) -> 4 | E2: =COUNTIF(handsmoothed!E$2:E$47,$A2) -> 4 | F2: =COUNTIF(handsmoothed!F$2:F$47,$A2) -> 4 | G2: =COUNTIF(handsmoothed!G$2:G$47,$A2) -> 4 | H2: =COUNTIF(handsmoothed!H$2:H$47,$A2) -> 4 | I2: =COUNTIF(handsmoothed!I$2:I$47,$A2) -> 4 | ... N2: =COUNTIF(handsmoothed!N$2:N$47,$A2) -> 2 | P2: 1 | Q2: =B2-C2 -> -1 | R2: =C2-D2 -> -1 | S2: =D2-E2 -> 0 | T2: =E2-F2 -> 0 | U2: =F2-G2 -> 0 | V2: =G2-H2 -> 0 | W2: =H2-I2 -> 0 | X2: =I2-J2 -> 1 | ... AB2: =M2-N2 -> 1 | AE2: 1 | AF2: =B3-B2 -> 0 | AG2: =C3-C2 -> -1 | AH2: =D3-D2 -> -2 | AI2: =E3-E2 -> -2 | AJ2: =F3-F2 -> -2 | AK2: =G3-G2 -> -2 | AL2: =H3-H2 -> -2 | AM2: =I3-I2 -> -2 | ... AR2: =N3-N2 -> 0
A3: 2 | B3: =COUNTIF(handsmoothed!B$2:B$47,$A3) -> 2 | C3: =COUNTIF(handsmoothed!C$2:C$47,$A3) -> 2 | D3: =COUNTIF(handsmoothed!D$2:D$47,$A3) -> 2 | E3: =COUNTIF(handsmoothed!E$2:E$47,$A3) -> 2 | F3: =COUNTIF(handsmoothed!F$2:F$47,$A3) -> 2 | G3: =COUNTIF(handsmoothed!G$2:G$47,$A3) -> 2 | H3: =COUNTIF(handsmoothed!H$2:H$47,$A3) -> 2 | I3: =COUNTIF(handsmoothed!I$2:I$47,$A3) -> 2 | ... N3: =COUNTIF(handsmoothed!N$2:N$47,$A3) -> 2 | P3: 2 | Q3: =B3-C3 -> 0 | R3: =C3-D3 -> 0 | S3: =D3-E3 -> 0 | T3: =E3-F3 -> 0 | U3: =F3-G3 -> 0 | V3: =G3-H3 -> 0 | W3: =H3-I3 -> 0 | X3: =I3-J3 -> 0 | ... AB3: =M3-N3 -> 0 | AE3: 2 | AF3: =B4-B3 -> 0 | AG3: =C4-C3 -> 1 | AH3: =D4-D3 -> 1 | AI3: =E4-E3 -> 1 | AJ3: =F4-F3 -> 1 | AK3: =G4-G3 -> 1 | AL3: =H4-H3 -> 1 | AM3: =I4-I3 -> 1 | ... AR3: =N4-N3 -> 1
A4: 3 | B4: =COUNTIF(handsmoothed!B$2:B$47,$A4) -> 2 | C4: =COUNTIF(handsmoothed!C$2:C$47,$A4) -> 3 | D4: =COUNTIF(handsmoothed!D$2:D$47,$A4) -> 3 | E4: =COUNTIF(handsmoothed!E$2:E$47,$A4) -> 3 | F4: =COUNTIF(handsmoothed!F$2:F$47,$A4) -> 3 | G4: =COUNTIF(handsmoothed!G$2:G$47,$A4) -> 3 | H4: =COUNTIF(handsmoothed!H$2:H$47,$A4) -> 3 | I4: =COUNTIF(handsmoothed!I$2:I$47,$A4) -> 3 | ... N4: =COUNTIF(handsmoothed!N$2:N$47,$A4) -> 3 | P4: 3 | Q4: =B4-C4 -> -1 | R4: =C4-D4 -> 0 | S4: =D4-E4 -> 0 | T4: =E4-F4 -> 0 | U4: =F4-G4 -> 0 | V4: =G4-H4 -> 0 | W4: =H4-I4 -> 0 | X4: =I4-J4 -> 0 | ... AB4: =M4-N4 -> 0 | AE4: 3 | AF4: =B5-B4 -> 1 | AG4: =C5-C4 -> 0 | AH4: =D5-D4 -> 0 | AI4: =E5-E4 -> 0 | AJ4: =F5-F4 -> 0 | AK4: =G5-G4 -> 0 | AL4: =H5-H4 -> 0 | AM4: =I5-I4 -> 0 | ... AR4: =N5-N4 -> 0
A5: 4 | B5: =COUNTIF(handsmoothed!B$2:B$47,$A5) -> 3 | C5: =COUNTIF(handsmoothed!C$2:C$47,$A5) -> 3 | D5: =COUNTIF(handsmoothed!D$2:D$47,$A5) -> 3 | E5: =COUNTIF(handsmoothed!E$2:E$47,$A5) -> 3 | F5: =COUNTIF(handsmoothed!F$2:F$47,$A5) -> 3 | G5: =COUNTIF(handsmoothed!G$2:G$47,$A5) -> 3 | H5: =COUNTIF(handsmoothed!H$2:H$47,$A5) -> 3 | I5: =COUNTIF(handsmoothed!I$2:I$47,$A5) -> 3 | ... N5: =COUNTIF(handsmoothed!N$2:N$47,$A5) -> 3 | P5: 4 | Q5: =B5-C5 -> 0 | R5: =C5-D5 -> 0 | S5: =D5-E5 -> 0 | T5: =E5-F5 -> 0 | U5: =F5-G5 -> 0 | V5: =G5-H5 -> 0 | W5: =H5-I5 -> 0 | X5: =I5-J5 -> -1 | ... AB5: =M5-N5 -> 0 | AE5: 4 | AF5: =B6-B5 -> 0 | AG5: =C6-C5 -> -1 | AH5: =D6-D5 -> -1 | AI5: =E6-E5 -> 0 | AJ5: =F6-F5 -> 0 | AK5: =G6-G5 -> 0 | AL5: =H6-H5 -> 1 | AM5: =I6-I5 -> 1 | ... AR5: =N6-N5 -> -1
A6: 5 | B6: =COUNTIF(handsmoothed!B$2:B$47,$A6) -> 3 | C6: =COUNTIF(handsmoothed!C$2:C$47,$A6) -> 2 | D6: =COUNTIF(handsmoothed!D$2:D$47,$A6) -> 2 | E6: =COUNTIF(handsmoothed!E$2:E$47,$A6) -> 3 | F6: =COUNTIF(handsmoothed!F$2:F$47,$A6) -> 3 | G6: =COUNTIF(handsmoothed!G$2:G$47,$A6) -> 3 | H6: =COUNTIF(handsmoothed!H$2:H$47,$A6) -> 4 | I6: =COUNTIF(handsmoothed!I$2:I$47,$A6) -> 4 | ... N6: =COUNTIF(handsmoothed!N$2:N$47,$A6) -> 2 | P6: 5 | Q6: =B6-C6 -> 1 | R6: =C6-D6 -> 0 | S6: =D6-E6 -> -1 | T6: =E6-F6 -> 0 | U6: =F6-G6 -> 0 | V6: =G6-H6 -> -1 | W6: =H6-I6 -> 0 | X6: =I6-J6 -> 1 | ... AB6: =M6-N6 -> 0 | AE6: 5 | AF6: =B7-B6 -> -1 | AG6: =C7-C6 -> 0 | AH6: =D7-D6 -> 0 | AI6: =E7-E6 -> -1 | AJ6: =F7-F6 -> 0 | AK6: =G7-G6 -> 1 | AL6: =H7-H6 -> -1 | AM6: =I7-I6 -> -1 | ... AR6: =N7-N6 -> 1
A7: 6 | B7: =COUNTIF(handsmoothed!B$2:B$47,$A7) -> 2 | C7: =COUNTIF(handsmoothed!C$2:C$47,$A7) -> 2 | D7: =COUNTIF(handsmoothed!D$2:D$47,$A7) -> 2 | E7: =COUNTIF(handsmoothed!E$2:E$47,$A7) -> 2 | F7: =COUNTIF(handsmoothed!F$2:F$47,$A7) -> 3 | G7: =COUNTIF(handsmoothed!G$2:G$47,$A7) -> 4 | H7: =COUNTIF(handsmoothed!H$2:H$47,$A7) -> 3 | I7: =COUNTIF(handsmoothed!I$2:I$47,$A7) -> 3 | ... N7: =COUNTIF(handsmoothed!N$2:N$47,$A7) -> 3 | P7: 6 | Q7: =B7-C7 -> 0 | R7: =C7-D7 -> 0 | S7: =D7-E7 -> 0 | T7: =E7-F7 -> -1 | U7: =F7-G7 -> -1 | V7: =G7-H7 -> 1 | W7: =H7-I7 -> 0 | X7: =I7-J7 -> 0 | ... AB7: =M7-N7 -> 0 | AE7: 6 | AF7: =B8-B7 -> 0 | AG7: =C8-C7 -> 0 | AH7: =D8-D7 -> 1 | AI7: =E8-E7 -> 1 | AJ7: =F8-F7 -> 0 | AK7: =G8-G7 -> -1 | AL7: =H8-H7 -> 1 | AM7: =I8-I7 -> 1 | ... AR7: =N8-N7 -> 1
A8: 7 | B8: =COUNTIF(handsmoothed!B$2:B$47,$A8) -> 2 | C8: =COUNTIF(handsmoothed!C$2:C$47,$A8) -> 2 | D8: =COUNTIF(handsmoothed!D$2:D$47,$A8) -> 3 | E8: =COUNTIF(handsmoothed!E$2:E$47,$A8) -> 3 | F8: =COUNTIF(handsmoothed!F$2:F$47,$A8) -> 3 | G8: =COUNTIF(handsmoothed!G$2:G$47,$A8) -> 3 | H8: =COUNTIF(handsmoothed!H$2:H$47,$A8) -> 4 | I8: =COUNTIF(handsmoothed!I$2:I$47,$A8) -> 4 | ... N8: =COUNTIF(handsmoothed!N$2:N$47,$A8) -> 4 | P8: 7 | Q8: =B8-C8 -> 0 | R8: =C8-D8 -> -1 | S8: =D8-E8 -> 0 | T8: =E8-F8 -> 0 | U8: =F8-G8 -> 0 | V8: =G8-H8 -> -1 | W8: =H8-I8 -> 0 | X8: =I8-J8 -> 0 | ... AB8: =M8-N8 -> 0 | AE8: 7 | AF8: =B9-B8 -> 0 | AG8: =C9-C8 -> 1 | AH8: =D9-D8 -> 0 | AI8: =E9-E8 -> 0 | AJ8: =F9-F8 -> 0 | AK8: =G9-G8 -> 0 | AL8: =H9-H8 -> -1 | AM8: =I9-I8 -> -1 | ... AR8: =N9-N8 -> 0
A9: 8 | B9: =COUNTIF(handsmoothed!B$2:B$47,$A9) -> 2 | C9: =COUNTIF(handsmoothed!C$2:C$47,$A9) -> 3 | D9: =COUNTIF(handsmoothed!D$2:D$47,$A9) -> 3 | E9: =COUNTIF(handsmoothed!E$2:E$47,$A9) -> 3 | F9: =COUNTIF(handsmoothed!F$2:F$47,$A9) -> 3 | G9: =COUNTIF(handsmoothed!G$2:G$47,$A9) -> 3 | H9: =COUNTIF(handsmoothed!H$2:H$47,$A9) -> 3 | I9: =COUNTIF(handsmoothed!I$2:I$47,$A9) -> 3 | ... N9: =COUNTIF(handsmoothed!N$2:N$47,$A9) -> 4 | P9: 8 | Q9: =B9-C9 -> -1 | R9: =C9-D9 -> 0 | S9: =D9-E9 -> 0 | T9: =E9-F9 -> 0 | U9: =F9-G9 -> 0 | V9: =G9-H9 -> 0 | W9: =H9-I9 -> 0 | X9: =I9-J9 -> 0 | ... AB9: =M9-N9 -> 0 | AE9: 8 | AF9: =B10-B9 -> 1 | AG9: =C10-C9 -> 0 | AH9: =D10-D9 -> 0 | AI9: =E10-E9 -> 0 | AJ9: =F10-F9 -> 0 | AK9: =G10-G9 -> 0 | AL9: =H10-H9 -> -1 | AM9: =I10-I9 -> -1 | ... AR9: =N10-N9 -> -1
A10: 9 | B10: =COUNTIF(handsmoothed!B$2:B$47,$A10) -> 3 | C10: =COUNTIF(handsmoothed!C$2:C$47,$A10) -> 3 | D10: =COUNTIF(handsmoothed!D$2:D$47,$A10) -> 3 | E10: =COUNTIF(handsmoothed!E$2:E$47,$A10) -> 3 | F10: =COUNTIF(handsmoothed!F$2:F$47,$A10) -> 3 | G10: =COUNTIF(handsmoothed!G$2:G$47,$A10) -> 3 | H10: =COUNTIF(handsmoothed!H$2:H$47,$A10) -> 2 | I10: =COUNTIF(handsmoothed!I$2:I$47,$A10) -> 2 | ... N10: =COUNTIF(handsmoothed!N$2:N$47,$A10) -> 3 | P10: 9 | Q10: =B10-C10 -> 0 | R10: =C10-D10 -> 0 | S10: =D10-E10 -> 0 | T10: =E10-F10 -> 0 | U10: =F10-G10 -> 0 | V10: =G10-H10 -> 1 | W10: =H10-I10 -> 0 | X10: =I10-J10 -> -1 | ... AB10: =M10-N10 -> 0 | AE10: 9 | AF10: =B11-B10 -> 0 | AG10: =C11-C10 -> 0 | AH10: =D11-D10 -> 0 | AI10: =E11-E10 -> 0 | AJ10: =F11-F10 -> 0 | AK10: =G11-G10 -> 0 | AL10: =H11-H10 -> 1 | AM10: =I11-I10 -> 1 | ... AR10: =N11-N10 -> 0
A11: 10 | B11: =COUNTIF(handsmoothed!B$2:B$47,$A11) -> 3 | C11: =COUNTIF(handsmoothed!C$2:C$47,$A11) -> 3 | D11: =COUNTIF(handsmoothed!D$2:D$47,$A11) -> 3 | E11: =COUNTIF(handsmoothed!E$2:E$47,$A11) -> 3 | F11: =COUNTIF(handsmoothed!F$2:F$47,$A11) -> 3 | G11: =COUNTIF(handsmoothed!G$2:G$47,$A11) -> 3 | H11: =COUNTIF(handsmoothed!H$2:H$47,$A11) -> 3 | I11: =COUNTIF(handsmoothed!I$2:I$47,$A11) -> 3 | ... N11: =COUNTIF(handsmoothed!N$2:N$47,$A11) -> 3 | P11: 10 | Q11: =B11-C11 -> 0 | R11: =C11-D11 -> 0 | S11: =D11-E11 -> 0 | T11: =E11-F11 -> 0 | U11: =F11-G11 -> 0 | V11: =G11-H11 -> 0 | W11: =H11-I11 -> 0 | X11: =I11-J11 -> 0 | ... AB11: =M11-N11 -> 0 | AE11: 10 | AF11: =B12-B11 -> -1 | AG11: =C12-C11 -> -1 | AH11: =D12-D11 -> -1 | AI11: =E12-E11 -> -1 | AJ11: =F12-F11 -> -1 | AK11: =G12-G11 -> -1 | AL11: =H12-H11 -> 0 | AM11: =I12-I11 -> 0 | ... AR11: =N12-N11 -> -1
A12: 11 | B12: =COUNTIF(handsmoothed!B$2:B$47,$A12) -> 2 | C12: =COUNTIF(handsmoothed!C$2:C$47,$A12) -> 2 | D12: =COUNTIF(handsmoothed!D$2:D$47,$A12) -> 2 | E12: =COUNTIF(handsmoothed!E$2:E$47,$A12) -> 2 | F12: =COUNTIF(handsmoothed!F$2:F$47,$A12) -> 2 | G12: =COUNTIF(handsmoothed!G$2:G$47,$A12) -> 2 | H12: =COUNTIF(handsmoothed!H$2:H$47,$A12) -> 3 | I12: =COUNTIF(handsmoothed!I$2:I$47,$A12) -> 3 | ... N12: =COUNTIF(handsmoothed!N$2:N$47,$A12) -> 2 | P12: 11 | Q12: =B12-C12 -> 0 | R12: =C12-D12 -> 0 | S12: =D12-E12 -> 0 | T12: =E12-F12 -> 0 | U12: =F12-G12 -> 0 | V12: =G12-H12 -> -1 | W12: =H12-I12 -> 0 | X12: =I12-J12 -> 1 | ... AB12: =M12-N12 -> 0 | AE12: 11 | AF12: =B13-B12 -> 0 | AG12: =C13-C12 -> 0 | AH12: =D13-D12 -> 0 | AI12: =E13-E12 -> 0 | AJ12: =F13-F12 -> 0 | AK12: =G13-G12 -> 0 | AL12: =H13-H12 -> -1 | AM12: =I13-I12 -> -1 | ... AR12: =N13-N12 -> 0
A13: 12 | B13: =COUNTIF(handsmoothed!B$2:B$47,$A13) -> 2 | C13: =COUNTIF(handsmoothed!C$2:C$47,$A13) -> 2 | D13: =COUNTIF(handsmoothed!D$2:D$47,$A13) -> 2 | E13: =COUNTIF(handsmoothed!E$2:E$47,$A13) -> 2 | F13: =COUNTIF(handsmoothed!F$2:F$47,$A13) -> 2 | G13: =COUNTIF(handsmoothed!G$2:G$47,$A13) -> 2 | H13: =COUNTIF(handsmoothed!H$2:H$47,$A13) -> 2 | I13: =COUNTIF(handsmoothed!I$2:I$47,$A13) -> 2 | ... N13: =COUNTIF(handsmoothed!N$2:N$47,$A13) -> 2 | P13: 12 | Q13: =B13-C13 -> 0 | R13: =C13-D13 -> 0 | S13: =D13-E13 -> 0 | T13: =E13-F13 -> 0 | U13: =F13-G13 -> 0 | V13: =G13-H13 -> 0 | W13: =H13-I13 -> 0 | X13: =I13-J13 -> -1 | ... AB13: =M13-N13 -> 1 | AE13: 12 | AF13: =B14-B13 -> 0 | AG13: =C14-C13 -> 0 | AH13: =D14-D13 -> 0 | AI13: =E14-E13 -> 0 | AJ13: =F14-F13 -> 0 | AK13: =G14-G13 -> 0 | AL13: =H14-H13 -> 0 | AM13: =I14-I13 -> 0 | ... AR13: =N14-N13 -> 0
... A19: 18 | B19: =COUNTIF(handsmoothed!B$2:B$47,$A19) -> 3 | C19: =COUNTIF(handsmoothed!C$2:C$47,$A19) -> 3 | D19: =COUNTIF(handsmoothed!D$2:D$47,$A19) -> 2 | E19: =COUNTIF(handsmoothed!E$2:E$47,$A19) -> 2 | F19: =COUNTIF(handsmoothed!F$2:F$47,$A19) -> 2 | G19: =COUNTIF(handsmoothed!G$2:G$47,$A19) -> 1 | H19: =COUNTIF(handsmoothed!H$2:H$47,$A19) -> 1 | I19: =COUNTIF(handsmoothed!I$2:I$47,$A19) -> 1 | ... N19: =COUNTIF(handsmoothed!N$2:N$47,$A19) -> 2 | P19: 18 | Q19: =B19-C19 -> 0 | R19: =C19-D19 -> 1 | S19: =D19-E19 -> 0 | T19: =E19-F19 -> 0 | U19: =F19-G19 -> 1 | V19: =G19-H19 -> 0 | W19: =H19-I19 -> 0 | X19: =I19-J19 -> 0 | ... AB19: =M19-N19 -> -1 | AE19: 18 | AF19: =B20-B19 -> 3 | AG19: =C20-C19 -> 1 | AH19: =D20-D19 -> 1 | AI19: =E20-E19 -> 0 | AJ19: =F20-F19 -> -1 | AK19: =G20-G19 -> 0 | AL19: =H20-H19 -> 0 | AM19: =I20-I19 -> 0 | ... AR19: =N20-N19 -> -1
A20: 19 | B20: =COUNTIF(handsmoothed!B$2:B$47,$A20) -> 6 | C20: =COUNTIF(handsmoothed!C$2:C$47,$A20) -> 4 | D20: =COUNTIF(handsmoothed!D$2:D$47,$A20) -> 3 | E20: =COUNTIF(handsmoothed!E$2:E$47,$A20) -> 2 | F20: =COUNTIF(handsmoothed!F$2:F$47,$A20) -> 1 | G20: =COUNTIF(handsmoothed!G$2:G$47,$A20) -> 1 | H20: =COUNTIF(handsmoothed!H$2:H$47,$A20) -> 1 | I20: =COUNTIF(handsmoothed!I$2:I$47,$A20) -> 1 | ... N20: =COUNTIF(handsmoothed!N$2:N$47,$A20) -> 1 | P20: 19 | Q20: =B20-C20 -> 2 | R20: =C20-D20 -> 1 | S20: =D20-E20 -> 1 | T20: =E20-F20 -> 1 | U20: =F20-G20 -> 0 | V20: =G20-H20 -> 0 | W20: =H20-I20 -> 0 | X20: =I20-J20 -> 0 | ... AB20: =M20-N20 -> 0

Sheet freq
A1: vctot | B1: g1 | C1: g2 | D1: g3 | E1: g4 | F1: g5 | G1: g6 | H1: g7 | I1: g8 | J1: g9 | K1: g10 | L1: g11 | M1: g12 | N1: g13 | O1: SS_Sq | P1: ssq1 | Q1: ssq2 | R1: ssq3 | S1: ssq4 | T1: ssq5 | U1: ssq6 | V1: ssq7 | W1: ssq8 | X1: ssq9 | Y1: ssq10 | Z1: ssq11 | AA1: ssq12 | AB1: ssq13
A2: 0 | B2: . | C2: . | D2: . | E2: . | F2: 1 | G2: . | H2: . | I2: . | J2: . | K2: . | L2: . | M2: . | N2: . | P2: =handsmoothed!B2^2 -> 1 | Q2: =handsmoothed!C2^2 -> 1 | R2: =handsmoothed!D2^2 -> 1 | S2: =handsmoothed!E2^2 -> 1 | T2: =handsmoothed!F2^2 -> 1 | U2: =handsmoothed!G2^2 -> 1 | V2: =handsmoothed!H2^2 -> 1 | W2: =handsmoothed!I2^2 -> 1 | ... AB2: =handsmoothed!N2^2 -> 1
A3: 1 | B3: . | C3: . | D3: . | E3: . | F3: . | G3: . | H3: . | I3: . | J3: . | K3: . | L3: . | M3: . | N3: . | P3: =handsmoothed!B3^2 -> 1 | Q3: =handsmoothed!C3^2 -> 1 | R3: =handsmoothed!D3^2 -> 1 | S3: =handsmoothed!E3^2 -> 1 | T3: =handsmoothed!F3^2 -> 1 | U3: =handsmoothed!G3^2 -> 1 | V3: =handsmoothed!H3^2 -> 1 | W3: =handsmoothed!I3^2 -> 1 | ... AB3: =handsmoothed!N3^2 -> 1
A4: 2 | B4: . | C4: . | D4: . | E4: . | F4: . | G4: . | H4: . | I4: . | J4: . | K4: . | L4: . | M4: . | N4: . | P4: =handsmoothed!B4^2 -> 4 | Q4: =handsmoothed!C4^2 -> 1 | R4: =handsmoothed!D4^2 -> 1 | S4: =handsmoothed!E4^2 -> 1 | T4: =handsmoothed!F4^2 -> 1 | U4: =handsmoothed!G4^2 -> 1 | V4: =handsmoothed!H4^2 -> 1 | W4: =handsmoothed!I4^2 -> 1 | ... AB4: =handsmoothed!N4^2 -> 4
A5: 3 | B5: . | C5: . | D5: . | E5: . | F5: . | G5: . | H5: . | I5: . | J5: . | K5: . | L5: . | M5: . | N5: . | P5: =handsmoothed!B5^2 -> 4 | Q5: =handsmoothed!C5^2 -> 4 | R5: =handsmoothed!D5^2 -> 1 | S5: =handsmoothed!E5^2 -> 1 | T5: =handsmoothed!F5^2 -> 1 | U5: =handsmoothed!G5^2 -> 1 | V5: =handsmoothed!H5^2 -> 1 | W5: =handsmoothed!I5^2 -> 1 | ... AB5: =handsmoothed!N5^2 -> 4
A6: 4 | B6: . | C6: . | D6: . | E6: 1 | F6: 1 | G6: . | H6: . | I6: 1 | J6: . | K6: . | L6: . | M6: . | N6: . | P6: =handsmoothed!B6^2 -> 9 | Q6: =handsmoothed!C6^2 -> 4 | R6: =handsmoothed!D6^2 -> 4 | S6: =handsmoothed!E6^2 -> 4 | T6: =handsmoothed!F6^2 -> 4 | U6: =handsmoothed!G6^2 -> 4 | V6: =handsmoothed!H6^2 -> 4 | W6: =handsmoothed!I6^2 -> 4 | ... AB6: =handsmoothed!N6^2 -> 9
A7: 5 | B7: . | C7: . | D7: . | E7: . | F7: . | G7: . | H7: . | I7: 1 | J7: . | K7: . | L7: . | M7: . | N7: . | P7: =handsmoothed!B7^2 -> 9 | Q7: =handsmoothed!C7^2 -> 9 | R7: =handsmoothed!D7^2 -> 4 | S7: =handsmoothed!E7^2 -> 4 | T7: =handsmoothed!F7^2 -> 4 | U7: =handsmoothed!G7^2 -> 4 | V7: =handsmoothed!H7^2 -> 4 | W7: =handsmoothed!I7^2 -> 4 | ... AB7: =handsmoothed!N7^2 -> 9
A8: 6 | B8: . | C8: . | D8: . | E8: . | F8: . | G8: . | H8: . | I8: . | J8: . | K8: . | L8: . | M8: . | N8: . | P8: =handsmoothed!B8^2 -> 16 | Q8: =handsmoothed!C8^2 -> 9 | R8: =handsmoothed!D8^2 -> 9 | S8: =handsmoothed!E8^2 -> 9 | T8: =handsmoothed!F8^2 -> 9 | U8: =handsmoothed!G8^2 -> 9 | V8: =handsmoothed!H8^2 -> 9 | W8: =handsmoothed!I8^2 -> 9 | ... AB8: =handsmoothed!N8^2 -> 9
A9: 7 | B9: . | C9: 1 | D9: . | E9: . | F9: 1 | G9: 2 | H9: 1 | I9: 1 | J9: 2 | K9: . | L9: . | M9: . | N9: . | P9: =handsmoothed!B9^2 -> 16 | Q9: =handsmoothed!C9^2 -> 9 | R9: =handsmoothed!D9^2 -> 9 | S9: =handsmoothed!E9^2 -> 9 | T9: =handsmoothed!F9^2 -> 9 | U9: =handsmoothed!G9^2 -> 9 | V9: =handsmoothed!H9^2 -> 9 | W9: =handsmoothed!I9^2 -> 9 | ... AB9: =handsmoothed!N9^2 -> 16
A10: 8 | B10: . | C10: . | D10: . | E10: 1 | F10: 1 | G10: 1 | H10: . | I10: 1 | J10: 2 | K10: . | L10: . | M10: 1 | N10: . | P10: =handsmoothed!B10^2 -> 16 | Q10: =handsmoothed!C10^2 -> 16 | R10: =handsmoothed!D10^2 -> 9 | S10: =handsmoothed!E10^2 -> 9 | T10: =handsmoothed!F10^2 -> 9 | U10: =handsmoothed!G10^2 -> 9 | V10: =handsmoothed!H10^2 -> 9 | W10: =handsmoothed!I10^2 -> 9 | ... AB10: =handsmoothed!N10^2 -> 16
A11: 9 | B11: 3 | C11: 2 | D11: 3 | E11: . | F11: 2 | G11: 3 | H11: 1 | I11: 2 | J11: 3 | K11: . | L11: 2 | M11: . | N11: . | P11: =handsmoothed!B11^2 -> 25 | Q11: =handsmoothed!C11^2 -> 16 | R11: =handsmoothed!D11^2 -> 16 | S11: =handsmoothed!E11^2 -> 16 | T11: =handsmoothed!F11^2 -> 16 | U11: =handsmoothed!G11^2 -> 16 | V11: =handsmoothed!H11^2 -> 16 | W11: =handsmoothed!I11^2 -> 16 | ... AB11: =handsmoothed!N11^2 -> 16
A12: 10 | B12: 1 | C12: 3 | D12: . | E12: 1 | F12: 1 | G12: . | H12: 1 | I12: . | J12: . | K12: . | L12: . | M12: . | N12: 1 | P12: =handsmoothed!B12^2 -> 25 | Q12: =handsmoothed!C12^2 -> 16 | R12: =handsmoothed!D12^2 -> 16 | S12: =handsmoothed!E12^2 -> 16 | T12: =handsmoothed!F12^2 -> 16 | U12: =handsmoothed!G12^2 -> 16 | V12: =handsmoothed!H12^2 -> 16 | W12: =handsmoothed!I12^2 -> 16 | ... AB12: =handsmoothed!N12^2 -> 25
A13: 11 | B13: 7 | C13: 10 | D13: 3 | E13: 2 | F13: 3 | G13: 3 | H13: 3 | I13: 3 | J13: 3 | K13: 3 | L13: . | M13: 2 | N13: 2 | P13: =handsmoothed!B13^2 -> 25 | Q13: =handsmoothed!C13^2 -> 25 | R13: =handsmoothed!D13^2 -> 16 | S13: =handsmoothed!E13^2 -> 16 | T13: =handsmoothed!F13^2 -> 16 | U13: =handsmoothed!G13^2 -> 16 | V13: =handsmoothed!H13^2 -> 16 | W13: =handsmoothed!I13^2 -> 16 | ... AB13: =handsmoothed!N13^2 -> 25
A14: 12 | B14: 5 | C14: 4 | D14: 1 | E14: 1 | F14: 1 | G14: 4 | H14: 2 | I14: 1 | J14: 3 | K14: 1 | L14: 2 | M14: 2 | N14: 3 | P14: =handsmoothed!B14^2 -> 36 | Q14: =handsmoothed!C14^2 -> 25 | R14: =handsmoothed!D14^2 -> 25 | S14: =handsmoothed!E14^2 -> 25 | T14: =handsmoothed!F14^2 -> 25 | U14: =handsmoothed!G14^2 -> 25 | V14: =handsmoothed!H14^2 -> 25 | W14: =handsmoothed!I14^2 -> 25 | ... AB14: =handsmoothed!N14^2 -> 36
A15: 13 | B15: 19 | C15: 5 | D15: 6 | E15: 8 | F15: 5 | G15: 3 | H15: 3 | I15: 3 | J15: 2 | K15: 3 | L15: 3 | M15: 5 | N15: 4 | P15: =handsmoothed!B15^2 -> 36 | Q15: =handsmoothed!C15^2 -> 36 | R15: =handsmoothed!D15^2 -> 25 | S15: =handsmoothed!E15^2 -> 25 | T15: =handsmoothed!F15^2 -> 25 | U15: =handsmoothed!G15^2 -> 25 | V15: =handsmoothed!H15^2 -> 25 | W15: =handsmoothed!I15^2 -> 25 | ... AB15: =handsmoothed!N15^2 -> 36
A16: 14 | B16: 8 | C16: 8 | D16: 1 | E16: 2 | F16: 3 | G16: 1 | H16: 2 | I16: 2 | J16: 2 | K16: 1 | L16: 2 | M16: 4 | N16: 3 | P16: =handsmoothed!B16^2 -> 49 | Q16: =handsmoothed!C16^2 -> 36 | R16: =handsmoothed!D16^2 -> 36 | S16: =handsmoothed!E16^2 -> 25 | T16: =handsmoothed!F16^2 -> 25 | U16: =handsmoothed!G16^2 -> 25 | V16: =handsmoothed!H16^2 -> 25 | W16: =handsmoothed!I16^2 -> 25 | ... AB16: =handsmoothed!N16^2 -> 36
A17: 15 | B17: 14 | C17: 4 | D17: 2 | E17: 3 | F17: 5 | G17: 2 | H17: 4 | I17: 5 | J17: 2 | K17: 1 | L17: . | M17: . | N17: 4 | P17: =handsmoothed!B17^2 -> 49 | Q17: =handsmoothed!C17^2 -> 49 | R17: =handsmoothed!D17^2 -> 36 | S17: =handsmoothed!E17^2 -> 36 | T17: =handsmoothed!F17^2 -> 36 | U17: =handsmoothed!G17^2 -> 36 | V17: =handsmoothed!H17^2 -> 25 | W17: =handsmoothed!I17^2 -> 25 | ... AB17: =handsmoothed!N17^2 -> 49
A18: 16 | B18: 3 | C18: 1 | D18: 2 | E18: 1 | F18: 1 | G18: . | H18: . | I18: 1 | J18: 2 | K18: 1 | L18: . | M18: 3 | N18: 1 | P18: =handsmoothed!B18^2 -> 64 | Q18: =handsmoothed!C18^2 -> 49 | R18: =handsmoothed!D18^2 -> 49 | S18: =handsmoothed!E18^2 -> 36 | T18: =handsmoothed!F18^2 -> 36 | U18: =handsmoothed!G18^2 -> 36 | V18: =handsmoothed!H18^2 -> 36 | W18: =handsmoothed!I18^2 -> 36 | ... AB18: =handsmoothed!N18^2 -> 49
A19: 17 | B19: 5 | C19: 6 | D19: 3 | E19: 2 | F19: 1 | G19: 3 | H19: 2 | I19: 9 | J19: 3 | K19: 2 | L19: 1 | M19: 3 | N19: 1 | P19: =handsmoothed!B19^2 -> 64 | Q19: =handsmoothed!C19^2 -> 64 | R19: =handsmoothed!D19^2 -> 49 | S19: =handsmoothed!E19^2 -> 49 | T19: =handsmoothed!F19^2 -> 36 | U19: =handsmoothed!G19^2 -> 36 | V19: =handsmoothed!H19^2 -> 36 | W19: =handsmoothed!I19^2 -> 36 | ... AB19: =handsmoothed!N19^2 -> 49
A20: 18 | B20: 3 | C20: 4 | D20: 6 | E20: 3 | F20: 2 | G20: 2 | H20: 1 | I20: 3 | J20: 1 | K20: 1 | L20: 3 | M20: 1 | N20: 4 | P20: =handsmoothed!B20^2 -> 81 | Q20: =handsmoothed!C20^2 -> 64 | R20: =handsmoothed!D20^2 -> 49 | S20: =handsmoothed!E20^2 -> 49 | T20: =handsmoothed!F20^2 -> 49 | U20: =handsmoothed!G20^2 -> 36 | V20: =handsmoothed!H20^2 -> 36 | W20: =handsmoothed!I20^2 -> 36 | ... AB20: =handsmoothed!N20^2 -> 49
A21: 19 | B21: 6 | C21: 8 | D21: 3 | E21: 6 | F21: 3 | G21: 2 | H21: 5 | I21: 3 | J21: 4 | K21: 1 | L21: 1 | M21: 2 | N21: 3 | P21: =handsmoothed!B21^2 -> 81 | Q21: =handsmoothed!C21^2 -> 64 | R21: =handsmoothed!D21^2 -> 64 | S21: =handsmoothed!E21^2 -> 49 | T21: =handsmoothed!F21^2 -> 49 | U21: =handsmoothed!G21^2 -> 49 | V21: =handsmoothed!H21^2 -> 49 | W21: =handsmoothed!I21^2 -> 49 | ... AB21: =handsmoothed!N21^2 -> 64
A22: 20 | B22: 10 | C22: 8 | D22: 7 | E22: 3 | F22: 5 | G22: 9 | H22: 2 | I22: 5 | J22: 1 | K22: 1 | L22: 1 | M22: 3 | N22: 6 | P22: =handsmoothed!B22^2 -> 81 | Q22: =handsmoothed!C22^2 -> 81 | R22: =handsmoothed!D22^2 -> 64 | S22: =handsmoothed!E22^2 -> 64 | T22: =handsmoothed!F22^2 -> 49 | U22: =handsmoothed!G22^2 -> 49 | V22: =handsmoothed!H22^2 -> 49 | W22: =handsmoothed!I22^2 -> 49 | ... AB22: =handsmoothed!N22^2 -> 64
A23: 21 | B23: 8 | C23: 7 | D23: 13 | E23: 5 | F23: 5 | G23: 1 | H23: 5 | I23: 2 | J23: 1 | K23: 1 | L23: . | M23: 4 | N23: 2 | P23: =handsmoothed!B23^2 -> 100 | Q23: =handsmoothed!C23^2 -> 81 | R23: =handsmoothed!D23^2 -> 64 | S23: =handsmoothed!E23^2 -> 64 | T23: =handsmoothed!F23^2 -> 64 | U23: =handsmoothed!G23^2 -> 49 | V23: =handsmoothed!H23^2 -> 49 | W23: =handsmoothed!I23^2 -> 49 | ... AB23: =handsmoothed!N23^2 -> 64
A24: 22 | B24: 3 | C24: 7 | D24: 2 | E24: 5 | F24: 3 | G24: 4 | H24: 6 | I24: 3 | J24: 4 | K24: 1 | L24: 3 | M24: 4 | N24: 2 | P24: =handsmoothed!B24^2 -> 100 | Q24: =handsmoothed!C24^2 -> 81 | R24: =handsmoothed!D24^2 -> 81 | S24: =handsmoothed!E24^2 -> 64 | T24: =handsmoothed!F24^2 -> 64 | U24: =handsmoothed!G24^2 -> 64 | V24: =handsmoothed!H24^2 -> 49 | W24: =handsmoothed!I24^2 -> 49 | ... AB24: =handsmoothed!N24^2 -> 64
A25: 23 | B25: 12 | C25: 9 | D25: 5 | E25: 6 | F25: 5 | G25: 5 | H25: 6 | I25: 5 | J25: 2 | K25: 8 | L25: 1 | M25: 4 | N25: 3 | P25: =handsmoothed!B25^2 -> 100 | Q25: =handsmoothed!C25^2 -> 100 | R25: =handsmoothed!D25^2 -> 81 | S25: =handsmoothed!E25^2 -> 81 | T25: =handsmoothed!F25^2 -> 64 | U25: =handsmoothed!G25^2 -> 64 | V25: =handsmoothed!H25^2 -> 64 | W25: =handsmoothed!I25^2 -> 64 | ... AB25: =handsmoothed!N25^2 -> 81
A26: 24 | B26: 8 | C26: 6 | D26: 9 | E26: 12 | F26: 7 | G26: 9 | H26: 5 | I26: 6 | J26: 6 | K26: 3 | L26: 7 | M26: 3 | N26: 5 | P26: =handsmoothed!B26^2 -> 121 | Q26: =handsmoothed!C26^2 -> 100 | R26: =handsmoothed!D26^2 -> 81 | S26: =handsmoothed!E26^2 -> 81 | T26: =handsmoothed!F26^2 -> 81 | U26: =handsmoothed!G26^2 -> 64 | V26: =handsmoothed!H26^2 -> 64 | W26: =handsmoothed!I26^2 -> 64 | ... AB26: =handsmoothed!N26^2 -> 81
A27: 25 | B27: 9 | C27: 9 | D27: 9 | E27: 5 | F27: 7 | G27: 10 | H27: 3 | I27: 4 | J27: 7 | K27: 2 | L27: 5 | M27: 3 | N27: 1 | P27: =handsmoothed!B27^2 -> 121 | Q27: =handsmoothed!C27^2 -> 100 | R27: =handsmoothed!D27^2 -> 100 | S27: =handsmoothed!E27^2 -> 81 | T27: =handsmoothed!F27^2 -> 81 | U27: =handsmoothed!G27^2 -> 81 | V27: =handsmoothed!H27^2 -> 64 | W27: =handsmoothed!I27^2 -> 64 | ... AB27: =handsmoothed!N27^2 -> 81
A28: 26 | B28: 7 | C28: 7 | D28: 10 | E28: 8 | F28: 6 | G28: 11 | H28: 5 | I28: 5 | J28: 6 | K28: 3 | L28: 3 | M28: 4 | N28: 4 | P28: =handsmoothed!B28^2 -> 144 | Q28: =handsmoothed!C28^2 -> 121 | R28: =handsmoothed!D28^2 -> 100 | S28: =handsmoothed!E28^2 -> 100 | T28: =handsmoothed!F28^2 -> 81 | U28: =handsmoothed!G28^2 -> 81 | V28: =handsmoothed!H28^2 -> 81 | W28: =handsmoothed!I28^2 -> 81 | ... AB28: =handsmoothed!N28^2 -> 100
A29: 27 | B29: 12 | C29: 11 | D29: 15 | E29: 17 | F29: 7 | G29: 6 | H29: 7 | I29: 4 | J29: 10 | K29: 7 | L29: 4 | M29: 5 | N29: 6 | P29: =handsmoothed!B29^2 -> 144 | Q29: =handsmoothed!C29^2 -> 121 | R29: =handsmoothed!D29^2 -> 100 | S29: =handsmoothed!E29^2 -> 100 | T29: =handsmoothed!F29^2 -> 100 | U29: =handsmoothed!G29^2 -> 81 | V29: =handsmoothed!H29^2 -> 81 | W29: =handsmoothed!I29^2 -> 81 | ... AB29: =handsmoothed!N29^2 -> 100
A30: 28 | B30: 8 | C30: 7 | D30: 14 | E30: 7 | F30: 14 | G30: 11 | H30: 9 | I30: 4 | J30: 12 | K30: 6 | L30: 4 | M30: 5 | N30: 8 | P30: =handsmoothed!B30^2 -> 169 | Q30: =handsmoothed!C30^2 -> 144 | R30: =handsmoothed!D30^2 -> 121 | S30: =handsmoothed!E30^2 -> 100 | T30: =handsmoothed!F30^2 -> 100 | U30: =handsmoothed!G30^2 -> 100 | V30: =handsmoothed!H30^2 -> 100 | W30: =handsmoothed!I30^2 -> 100 | ... AB30: =handsmoothed!N30^2 -> 100
A31: 29 | B31: 10 | C31: 9 | D31: 9 | E31: 14 | F31: 13 | G31: 12 | H31: 9 | I31: 9 | J31: 9 | K31: 5 | L31: 5 | M31: 6 | N31: 6 | P31: =handsmoothed!B31^2 -> 169 | Q31: =handsmoothed!C31^2 -> 144 | R31: =handsmoothed!D31^2 -> 121 | S31: =handsmoothed!E31^2 -> 121 | T31: =handsmoothed!F31^2 -> 100 | U31: =handsmoothed!G31^2 -> 100 | V31: =handsmoothed!H31^2 -> 100 | W31: =handsmoothed!I31^2 -> 100 | ... AB31: =handsmoothed!N31^2 -> 121
A32: 30 | B32: 6 | C32: 12 | D32: 8 | E32: 13 | F32: 9 | G32: 11 | H32: 11 | I32: 6 | J32: 9 | K32: 4 | L32: 6 | M32: 4 | N32: 4 | P32: =handsmoothed!B32^2 -> 196 | Q32: =handsmoothed!C32^2 -> 169 | R32: =handsmoothed!D32^2 -> 144 | S32: =handsmoothed!E32^2 -> 121 | T32: =handsmoothed!F32^2 -> 121 | U32: =handsmoothed!G32^2 -> 100 | V32: =handsmoothed!H32^2 -> 100 | W32: =handsmoothed!I32^2 -> 100 | ... AB32: =handsmoothed!N32^2 -> 121
A33: 31 | B33: 5 | C33: 11 | D33: 8 | E33: 5 | F33: 7 | G33: 8 | H33: 9 | I33: 12 | J33: 9 | K33: 6 | L33: 5 | M33: 2 | N33: 2 | P33: =handsmoothed!B33^2 -> 196 | Q33: =handsmoothed!C33^2 -> 169 | R33: =handsmoothed!D33^2 -> 144 | S33: =handsmoothed!E33^2 -> 144 | T33: =handsmoothed!F33^2 -> 121 | U33: =handsmoothed!G33^2 -> 121 | V33: =handsmoothed!H33^2 -> 121 | W33: =handsmoothed!I33^2 -> 121 | ... AB33: =handsmoothed!N33^2 -> 144
A34: 32 | B34: 2 | C34: 5 | D34: 9 | E34: 11 | F34: 7 | G34: 8 | H34: 12 | I34: 11 | J34: 10 | K34: 9 | L34: 6 | M34: 5 | N34: 6 | P34: =handsmoothed!B34^2 -> 225 | Q34: =handsmoothed!C34^2 -> 196 | R34: =handsmoothed!D34^2 -> 169 | S34: =handsmoothed!E34^2 -> 144 | T34: =handsmoothed!F34^2 -> 144 | U34: =handsmoothed!G34^2 -> 121 | V34: =handsmoothed!H34^2 -> 121 | W34: =handsmoothed!I34^2 -> 121 | ... AB34: =handsmoothed!N34^2 -> 144
A35: 33 | B35: 4 | C35: 5 | D35: 10 | E35: 8 | F35: 11 | G35: 13 | H35: 17 | I35: 11 | J35: 15 | K35: 7 | L35: 8 | M35: 2 | N35: 7 | P35: =handsmoothed!B35^2 -> 256 | Q35: =handsmoothed!C35^2 -> 196 | R35: =handsmoothed!D35^2 -> 169 | S35: =handsmoothed!E35^2 -> 169 | T35: =handsmoothed!F35^2 -> 144 | U35: =handsmoothed!G35^2 -> 144 | V35: =handsmoothed!H35^2 -> 121 | W35: =handsmoothed!I35^2 -> 121 | ... AB35: =handsmoothed!N35^2 -> 169
A36: 34 | B36: . | C36: 3 | D36: 9 | E36: 13 | F36: 9 | G36: 6 | H36: 8 | I36: 15 | J36: 7 | K36: 7 | L36: 3 | M36: 2 | N36: 3 | P36: =handsmoothed!B36^2 -> 256 | Q36: =handsmoothed!C36^2 -> 225 | R36: =handsmoothed!D36^2 -> 196 | S36: =handsmoothed!E36^2 -> 169 | T36: =handsmoothed!F36^2 -> 169 | U36: =handsmoothed!G36^2 -> 144 | V36: =handsmoothed!H36^2 -> 144 | W36: =handsmoothed!I36^2 -> 144 | ... AB36: =handsmoothed!N36^2 -> 169
A37: 35 | B37: . | C37: 5 | D37: 5 | E37: 5 | F37: 10 | G37: 5 | H37: 7 | I37: 9 | J37: 13 | K37: 4 | L37: 5 | M37: 6 | N37: 1 | P37: =handsmoothed!B37^2 -> 289 | Q37: =handsmoothed!C37^2 -> 256 | R37: =handsmoothed!D37^2 -> 225 | S37: =handsmoothed!E37^2 -> 196 | T37: =handsmoothed!F37^2 -> 169 | U37: =handsmoothed!G37^2 -> 169 | V37: =handsmoothed!H37^2 -> 144 | W37: =handsmoothed!I37^2 -> 144 | ... AB37: =handsmoothed!N37^2 -> 196
A38: 36 | B38: 1 | C38: 1 | D38: 1 | E38: 2 | F38: 10 | G38: 5 | H38: 9 | I38: 9 | J38: 10 | K38: 1 | L38: 7 | M38: 3 | N38: 1 | P38: =handsmoothed!B38^2 -> 289 | Q38: =handsmoothed!C38^2 -> 256 | R38: =handsmoothed!D38^2 -> 225 | S38: =handsmoothed!E38^2 -> 196 | T38: =handsmoothed!F38^2 -> 196 | U38: =handsmoothed!G38^2 -> 169 | V38: =handsmoothed!H38^2 -> 169 | W38: =handsmoothed!I38^2 -> 169 | ... AB38: =handsmoothed!N38^2 -> 196
A39: 37 | B39: 1 | C39: 1 | D39: 4 | E39: 6 | F39: 3 | G39: 9 | H39: 6 | I39: 3 | J39: 7 | K39: 3 | L39: 3 | M39: 5 | N39: 2 | P39: =handsmoothed!B39^2 -> 324 | Q39: =handsmoothed!C39^2 -> 289 | R39: =handsmoothed!D39^2 -> 256 | S39: =handsmoothed!E39^2 -> 225 | T39: =handsmoothed!F39^2 -> 196 | U39: =handsmoothed!G39^2 -> 196 | V39: =handsmoothed!H39^2 -> 169 | W39: =handsmoothed!I39^2 -> 169 | ... AB39: =handsmoothed!N39^2 -> 225
A40: 38 | B40: . | C40: . | D40: . | E40: . | F40: 3 | G40: 3 | H40: 4 | I40: 5 | J40: 1 | K40: 3 | L40: . | M40: 2 | N40: 1 | P40: =handsmoothed!B40^2 -> 324 | Q40: =handsmoothed!C40^2 -> 289 | R40: =handsmoothed!D40^2 -> 256 | S40: =handsmoothed!E40^2 -> 225 | T40: =handsmoothed!F40^2 -> 225 | U40: =handsmoothed!G40^2 -> 196 | V40: =handsmoothed!H40^2 -> 196 | W40: =handsmoothed!I40^2 -> 196 | ... AB40: =handsmoothed!N40^2 -> 225
...

Sheet QA
A1: wais5 norm (si) | L1: wais5 norm (vc)
A3: The MEANS Procedure | L3: The MEANS Procedure
A5: Analysis Variable : vc_ss | L5: Analysis Variable : vc_ss
A6: N | B6: Mean | C6: Std Dev | D6: Minimum | E6: Maximum | L6: N | M6: Mean | N6: Std Dev | O6: Minimum | P6: Maximum
A7: 2020 | B7: 10.007426 | C7: 2.9724581 | D7: 1 | E7: 19 | L7: 2020 | M7: 10.00198 | N7: 2.9941326 | O7: 1 | P7: 19
A12: wais5 norm (si) | L12: wais5 norm (vc)
A14: The MEANS Procedure | L14: The MEANS Procedure
A16: Analysis Variable : vc_ss | L16: Analysis Variable : vc_ss
A17: agegrp | B17: N Obs | C17: N | D17: Mean | E17: Std Dev | F17: Minimum | G17: Maximum | L17: agegrp | M17: N Obs | N17: N | O17: Mean | P17: Std Dev | Q17: Minimum | R17: Maximum
A18: 1 | B18: 180 | C18: 180 | D18: 9.6666667 | E18: 3.01208 | F18: 4 | G18: 18 | L18: 1 | M18: 180 | N18: 180 | O18: 9.7222222 | P18: 3.0195926 | Q18: 5 | R18: 18
A19: 2 | B19: 180 | C19: 180 | D19: 10.055556 | E19: 3.1137149 | F19: 3 | G19: 19 | L19: 2 | M19: 180 | N19: 180 | O19: 9.9611111 | P19: 3.152305 | Q19: 3 | R19: 18
A20: 3 | B20: 180 | C20: 180 | D20: 10.494444 | E20: 2.8195194 | F20: 4 | G20: 19 | L20: 3 | M20: 180 | N20: 180 | O20: 10.255556 | P20: 2.8873104 | Q20: 4 | R20: 18
A21: 4 | B21: 180 | C21: 180 | D21: 10.066667 | E21: 2.7454381 | F21: 2 | G21: 19 | L21: 4 | M21: 180 | N21: 180 | O21: 10.116667 | P21: 2.8584385 | Q21: 2 | R21: 19
A22: 5 | B22: 180 | C22: 180 | D22: 9.8833333 | E22: 3.0162965 | F22: 1 | G22: 18 | L22: 5 | M22: 180 | N22: 180 | O22: 10.044444 | P22: 3.1654952 | Q22: 1 | R22: 18
A23: 6 | B23: 180 | C23: 180 | D23: 9.6555556 | E23: 2.8012811 | F23: 3 | G23: 18 | L23: 6 | M23: 180 | N23: 180 | O23: 9.7555556 | P23: 2.940038 | Q23: 3 | R23: 19
A24: 7 | B24: 180 | C24: 180 | D24: 10.105556 | E24: 2.7876368 | F24: 3 | G24: 17 | L24: 7 | M24: 180 | N24: 180 | O24: 10.055556 | P24: 2.9096684 | Q24: 3 | R24: 18
A25: 8 | B25: 180 | C25: 180 | D25: 10.033333 | E25: 3.2024781 | F25: 2 | G25: 18 | L25: 8 | M25: 180 | N25: 180 | O25: 9.9055556 | P25: 3.293293 | Q25: 2 | R25: 19
A26: 9 | B26: 180 | C26: 180 | D26: 10.216667 | E26: 3.0731764 | F26: 3 | G26: 18 | L26: 9 | M26: 180 | N26: 180 | O26: 10.105556 | P26: 2.9398005 | Q26: 3 | R26: 19
A27: 10 | B27: 100 | C27: 100 | D27: 10.11 | E27: 2.8423031 | F27: 4 | G27: 18 | L27: 10 | M27: 100 | N27: 100 | O27: 9.99 | P27: 2.7725021 | Q27: 4 | R27: 18
A28: 11 | B28: 100 | C28: 100 | D28: 10.59 | E28: 3.0187796 | F28: 4 | G28: 18 | L28: 11 | M28: 100 | N28: 100 | O28: 10.47 | P28: 2.893584 | Q28: 4 | R28: 18
A29: 12 | B29: 100 | C29: 100 | D29: 9.65 | E29: 3.0989571 | F29: 3 | G29: 17 | L29: 12 | M29: 100 | N29: 100 | O29: 9.82 | P29: 2.9520751 | Q29: 4 | R29: 17
A30: 13 | B30: 100 | C30: 100 | D30: 9.48 | E30: 3.0632392 | F30: 4 | G30: 19 | L30: 13 | M30: 100 | N30: 100 | O30: 9.9 | P30: 2.9593202 | Q30: 5 | R30: 19
A35: wais5 norm (vc) | L35: wais5 norm (vc)
A37: Obs | B37: P_02 | C37: P_16 | D37: P_50 | E37: P_84 | F37: P_98 | L37: Obs | M37: P_02 | N37: P_16 | O37: P_50 | P37: P_84 | Q37: P_98
A38: 1 | B38: 4 | C38: 7 | D38: 10 | E38: 13 | F38: 16 | L38: 1 | M38: 4 | N38: 7 | O38: 10 | P38: 13 | Q38: 16
A43: wais5 norm (vc) | L43: wais5 norm (vc)
A45: Obs | B45: agegrp | C45: P_02 | D45: P_16 | E45: P_50 | F45: P_84 | G45: P_98 | L45: Obs | M45: agegrp | N45: P_02 | O45: P_16 | P45: P_50 | Q45: P_84 | R45: P_98
A46: 1 | B46: 1 | C46: 5 | D46: 6 | E46: 10 | F46: 13 | G46: 15 | L46: 1 | M46: 1 | N46: 5 | O46: 6 | P46: 10 | Q46: 13 | R46: 16
A47: 2 | B47: 2 | C47: 5 | D47: 6 | E47: 10 | F47: 13 | G47: 16 | L47: 2 | M47: 2 | N47: 4 | O47: 6 | P47: 10 | Q47: 13 | R47: 16
A48: 3 | B48: 3 | C48: 5 | D48: 8 | E48: 11 | F48: 13 | G48: 16 | L48: 3 | M48: 3 | N48: 4 | O48: 8 | P48: 10 | Q48: 13 | R48: 16
A49: 4 | B49: 4 | C49: 5 | D49: 7 | E49: 10 | F49: 13 | G49: 16 | L49: 4 | M49: 4 | N49: 4 | O49: 7 | P49: 10 | Q49: 13 | R49: 16
A50: 5 | B50: 5 | C50: 3 | D50: 7 | E50: 10 | F50: 13 | G50: 16 | L50: 5 | M50: 5 | N50: 3 | O50: 7 | P50: 10 | Q50: 13 | R50: 16
A51: 6 | B51: 6 | C51: 4 | D51: 7 | E51: 10 | F51: 12 | G51: 16 | L51: 6 | M51: 6 | N51: 4 | O51: 7 | P51: 10 | Q51: 13 | R51: 16
A52: 7 | B52: 7 | C52: 4 | D52: 7 | E52: 10 | F52: 13 | G52: 15 | L52: 7 | M52: 7 | N52: 4 | O52: 7 | P52: 10 | Q52: 13 | R52: 16
A53: 8 | B53: 8 | C53: 3 | D53: 6 | E53: 11 | F53: 13 | G53: 17 | L53: 8 | M53: 8 | N53: 3 | O53: 6 | P53: 11 | Q53: 13 | R53: 17
A54: 9 | B54: 9 | C54: 3 | D54: 7 | E54: 10 | F54: 13 | G54: 16 | L54: 9 | M54: 9 | N54: 4 | O54: 7 | P54: 10 | Q54: 13 | R54: 16
A55: 10 | B55: 10 | C55: 4 | D55: 8 | E55: 10 | F55: 12.5 | G55: 16 | L55: 10 | M55: 10 | N55: 4 | O55: 7.5 | P55: 10 | Q55: 12 | R55: 16
A56: 11 | B56: 11 | C56: 4.5 | D56: 8 | E56: 11 | F56: 13 | G56: 17 | L56: 11 | M56: 11 | N56: 4.5 | O56: 8 | P56: 11 | Q56: 13 | R56: 16.5
A57: 12 | B57: 12 | C57: 5 | D57: 6 | E57: 10 | F57: 13 | G57: 16 | L57: 12 | M57: 12 | N57: 5 | O57: 7 | P57: 10 | Q57: 13 | R57: 16
A58: 13 | B58: 13 | C58: 5 | D58: 6 | E58: 10 | F58: 12 | G58: 17.5 | L58: 13 | M58: 13 | N58: 5 | O58: 7 | P58: 10 | Q58: 13 | R58: 17.5

Sheet out
A1: wais5_vc_raw | B1: ss1 | C1: ss2 | D1: ss3 | E1: ss4 | F1: ss5 | G1: ss6 | H1: ss7 | I1: ss8 | J1: ss9 | K1: ss10 | L1: ss11 | M1: ss12 | N1: ss13
A2: =handsmoothed!A2 -> 0 | B2: =handsmoothed!B2 -> 1 | C2: =handsmoothed!C2 -> 1 | D2: =handsmoothed!D2 -> 1 | E2: =handsmoothed!E2 -> 1 | F2: =handsmoothed!F2 -> 1 | G2: =handsmoothed!G2 -> 1 | H2: =handsmoothed!H2 -> 1 | ... N2: =handsmoothed!N2 -> 1
A3: =handsmoothed!A3 -> 1 | B3: =handsmoothed!B3 -> 1 | C3: =handsmoothed!C3 -> 1 | D3: =handsmoothed!D3 -> 1 | E3: =handsmoothed!E3 -> 1 | F3: =handsmoothed!F3 -> 1 | G3: =handsmoothed!G3 -> 1 | H3: =handsmoothed!H3 -> 1 | ... N3: =handsmoothed!N3 -> 1
A4: =handsmoothed!A4 -> 2 | B4: =handsmoothed!B4 -> 2 | C4: =handsmoothed!C4 -> 1 | D4: =handsmoothed!D4 -> 1 | E4: =handsmoothed!E4 -> 1 | F4: =handsmoothed!F4 -> 1 | G4: =handsmoothed!G4 -> 1 | H4: =handsmoothed!H4 -> 1 | ... N4: =handsmoothed!N4 -> 2
A5: =handsmoothed!A5 -> 3 | B5: =handsmoothed!B5 -> 2 | C5: =handsmoothed!C5 -> 2 | D5: =handsmoothed!D5 -> 1 | E5: =handsmoothed!E5 -> 1 | F5: =handsmoothed!F5 -> 1 | G5: =handsmoothed!G5 -> 1 | H5: =handsmoothed!H5 -> 1 | ... N5: =handsmoothed!N5 -> 2
A6: =handsmoothed!A6 -> 4 | B6: =handsmoothed!B6 -> 3 | C6: =handsmoothed!C6 -> 2 | D6: =handsmoothed!D6 -> 2 | E6: =handsmoothed!E6 -> 2 | F6: =handsmoothed!F6 -> 2 | G6: =handsmoothed!G6 -> 2 | H6: =handsmoothed!H6 -> 2 | ... N6: =handsmoothed!N6 -> 3
A7: =handsmoothed!A7 -> 5 | B7: =handsmoothed!B7 -> 3 | C7: =handsmoothed!C7 -> 3 | D7: =handsmoothed!D7 -> 2 | E7: =handsmoothed!E7 -> 2 | F7: =handsmoothed!F7 -> 2 | G7: =handsmoothed!G7 -> 2 | H7: =handsmoothed!H7 -> 2 | ... N7: =handsmoothed!N7 -> 3
A8: =handsmoothed!A8 -> 6 | B8: =handsmoothed!B8 -> 4 | C8: =handsmoothed!C8 -> 3 | D8: =handsmoothed!D8 -> 3 | E8: =handsmoothed!E8 -> 3 | F8: =handsmoothed!F8 -> 3 | G8: =handsmoothed!G8 -> 3 | H8: =handsmoothed!H8 -> 3 | ... N8: =handsmoothed!N8 -> 3
A9: =handsmoothed!A9 -> 7 | B9: =handsmoothed!B9 -> 4 | C9: =handsmoothed!C9 -> 3 | D9: =handsmoothed!D9 -> 3 | E9: =handsmoothed!E9 -> 3 | F9: =handsmoothed!F9 -> 3 | G9: =handsmoothed!G9 -> 3 | H9: =handsmoothed!H9 -> 3 | ... N9: =handsmoothed!N9 -> 4
A10: =handsmoothed!A10 -> 8 | B10: =handsmoothed!B10 -> 4 | C10: =handsmoothed!C10 -> 4 | D10: =handsmoothed!D10 -> 3 | E10: =handsmoothed!E10 -> 3 | F10: =handsmoothed!F10 -> 3 | G10: =handsmoothed!G10 -> 3 | H10: =handsmoothed!H10 -> 3 | ... N10: =handsmoothed!N10 -> 4
A11: =handsmoothed!A11 -> 9 | B11: =handsmoothed!B11 -> 5 | C11: =handsmoothed!C11 -> 4 | D11: =handsmoothed!D11 -> 4 | E11: =handsmoothed!E11 -> 4 | F11: =handsmoothed!F11 -> 4 | G11: =handsmoothed!G11 -> 4 | H11: =handsmoothed!H11 -> 4 | ... N11: =handsmoothed!N11 -> 4
A12: =handsmoothed!A12 -> 10 | B12: =handsmoothed!B12 -> 5 | C12: =handsmoothed!C12 -> 4 | D12: =handsmoothed!D12 -> 4 | E12: =handsmoothed!E12 -> 4 | F12: =handsmoothed!F12 -> 4 | G12: =handsmoothed!G12 -> 4 | H12: =handsmoothed!H12 -> 4 | ... N12: =handsmoothed!N12 -> 5
A13: =handsmoothed!A13 -> 11 | B13: =handsmoothed!B13 -> 5 | C13: =handsmoothed!C13 -> 5 | D13: =handsmoothed!D13 -> 4 | E13: =handsmoothed!E13 -> 4 | F13: =handsmoothed!F13 -> 4 | G13: =handsmoothed!G13 -> 4 | H13: =handsmoothed!H13 -> 4 | ... N13: =handsmoothed!N13 -> 5
... A47: =handsmoothed!A47 -> 45 | B47: =handsmoothed!B47 -> 19 | C47: =handsmoothed!C47 -> 19 | D47: =handsmoothed!D47 -> 19 | E47: =handsmoothed!E47 -> 19 | F47: =handsmoothed!F47 -> 19 | G47: =handsmoothed!G47 -> 19 | H47: =handsmoothed!H47 -> 19 | ... N47: =handsmoothed!N47 -> 19
