Workbook

Sheet handsmooth
A1: wais5_vci_sum | B1: g1 | C1: freq | G1: rev | I1: ssq1
A2: 2 | B2: 45 | C2: 0 | D2: 49-51 | G2: =B3-B2 -> 4 | I2: =B2^2 -> 2025
A3: 3 | B3: 49 | C3: 4 | G3: =B4-B3 -> 3 | I3: =B3^2 -> 2401
A4: 4 | B4: 52 | C4: 2 | G4: =B5-B4 -> 4 | I4: =B4^2 -> 2704
A5: 5 | B5: 56 | C5: 3 | G5: =B6-B5 -> 3 | I5: =B5^2 -> 3136
A6: 6 | B6: 59 | C6: 3 | G6: =B7-B6 -> 4 | I6: =B6^2 -> 3481
A7: 7 | B7: 63 | C7: 7 | G7: =B8-B7 -> 3 | I7: =B7^2 -> 3969
A8: 8 | B8: 66 | C8: 13 | D8: 66-68 | G8: =B9-B8 -> 3 | I8: =B8^2 -> 4356
A9: 9 | B9: 69 | C9: 28 | G9: =B10-B9 -> 4 | I9: =B9^2 -> 4761
A10: 10 | B10: 73 | C10: 41 | G10: =B11-B10 -> 3 | I10: =B10^2 -> 5329
A11: 11 | B11: 76 | C11: 39 | G11: =B12-B11 -> 3 | I11: =B11^2 -> 5776
A12: 12 | B12: 79 | C12: 47 | G12: =B13-B12 -> 2 | I12: =B12^2 -> 6241
A13: 13 | B13: 81 | C13: 56 | G13: =B14-B13 -> 3 | I13: =B13^2 -> 6561
A14: 14 | B14: 84 | C14: 72 | D14: 83-84 | G14: =B15-B14 -> 3 | I14: =B14^2 -> 7056
A15: 15 | B15: 87 | C15: 94 | G15: =B16-B15 -> 2 | I15: =B15^2 -> 7569
A16: 16 | B16: 89 | C16: 115 | G16: =B17-B16 -> 3 | I16: =B16^2 -> 7921
A17: 17 | B17: 92 | C17: 124 | G17: =B18-B17 -> 3 | I17: =B17^2 -> 8464
A18: 18 | B18: 95 | C18: 138 | G18: =B19-B18 -> 3 | I18: =B18^2 -> 9025
A19: 19 | B19: 98 | C19: 143 | G19: =B20-B19 -> 2 | I19: =B19^2 -> 9604
A20: 20 | B20: 100 | C20: 143 | D20: 100 | G20: =B21-B20 -> 2 | I20: =B20^2 -> 10000
A21: 21 | B21: 102 | C21: 133 | G21: =B22-B21 -> 3 | I21: =B21^2 -> 10404
A22: 22 | B22: 105 | C22: 155 | G22: =B23-B22 -> 3 | I22: =B22^2 -> 11025
A23: 23 | B23: 108 | C23: 128 | G23: =B24-B23 -> 3 | I23: =B23^2 -> 11664
A24: 24 | B24: 111 | C24: 121 | G24: =B25-B24 -> 3 | I24: =B24^2 -> 12321
A25: 25 | B25: 114 | C25: 83 | G25: =B26-B25 -> 2 | I25: =B25^2 -> 12996
A26: 26 | B26: 116 | C26: 92 | D26: 116-117 | G26: =B27-B26 -> 3 | I26: =B26^2 -> 13456
A27: 27 | B27: 119 | C27: 73 | G27: =B28-B27 -> 2 | I27: =B27^2 -> 14161
A28: 28 | B28: 121 | C28: 54 | G28: =B29-B28 -> 3 | I28: =B28^2 -> 14641
A29: 29 | B29: 124 | C29: 26 | G29: =B30-B29 -> 3 | I29: =B29^2 -> 15376
A30: 30 | B30: 127 | C30: 31 | G30: =B31-B30 -> 3 | I30: =B30^2 -> 16129
A31: 31 | B31: 130 | C31: 18 | G31: =B32-B31 -> 3 | I31: =B31^2 -> 16900
A32: 32 | B32: 133 | C32: 11 | D32: 132-134 | G32: =B33-B32 -> 3 | I32: =B32^2 -> 17689
A33: 33 | B33: 136 | C33: 9 | G33: =B34-B33 -> 4 | I33: =B33^2 -> 18496
A34: 34 | B34: 140 | C34: 2 | G34: =B35-B34 -> 4 | I34: =B34^2 -> 19600
A35: 35 | B35: 144 | C35: 8 | G35: =B36-B35 -> 3 | I35: =B35^2 -> 20736
A36: 36 | B36: 147 | C36: 2 | G36: =B37-B36 -> 4 | I36: =B36^2 -> 21609
A37: 37 | B37: 151 | C37: 1 | G37: =B38-B37 -> 4 | I37: =B37^2 -> 22801
A38: 38 | B38: 155 | C38: 1 | D38: 149-151 | I38: =B38^2 -> 24025
A39: mean | B39: =SUMPRODUCT(B2:B38,C2:C38)/2020 -> 100.02277 | C39: . | D39: Check | F39: N=2020 | G39: Ideal | H39: Actual
A40: sd1 | B40: =ROUND(SQRT(SUMPRODUCT(C2:C38,I2:I38)/2020-B39^2),2) -> 15 | C40: . | D40: 130 | E40: 160 | F40: =CONCATENATE(D40,"-",E40) -> 130-160 | G40: =ROUND((NORMDIST(E40+0.5,100,15,TRUE)-NORMDIST(D40-0.5,100,15,TRUE))*100,2) -> 2.46 | H40: =ROUND(100*(SUMIF(B$2:B$38,"<="&E40,C$2:C$38)-SUMIF(B$2:B$38,"<"&D40,C$2:C$38))/2020,2) -> 2.57 | I40: =G40-H40 -> -0.11 | J40: =CONCATENATE(ABS(ROUND(I40/100*2020,1)),"-",IF(I40/100*2020<0,$S$41,$S$40)) -> 2.2-too many | K40: =RANK(N40,N$40:N$50,-1) -> 8 | N40: =AVERAGE(O40,P40) -> 8 | O40: =RANK(R40,R$40:R$50) -> 9 | P40: =RANK(Q40,Q$40:Q$50) -> 7 | Q40: =ABS(I40/G40) -> 0.044715447 | R40: =ABS(I40) -> 0.11 | S40: too few
...

Sheet out
A1: wais5_vci_sum | B1: wais5_vci_ss | C1: 90% CI | D1: 95% CI | E1: %-tile
A2: =handsmooth!A2 -> 2 | B2: =handsmooth!B2 -> 45 | C2: =CONCATENATE(ROUND((100+$H$3*(B2-100))-(1.645*(15*$H$3*SQRT(1-$H$3))),0),"-",ROUND((100+$H$3*(B2-100))+(1.645*(15*$H$3*SQRT(1-$H$3))),0)) -> 43-55 | D2: =CONCATENATE(ROUND((100+$H$3*(B2-100))-(1.96*(15*$H$3*SQRT(1-$H$3))),0),"-",ROUND((100+$H$3*(B2-100))+(1.96*(15*$H$3*SQRT(1-$H$3))),0)) -> 42-56 | E2: =IF(B2<51,"<0.1",IF(B2<62,ROUND(NORMDIST(B2,100,15,TRUE)*100,1),IF(B2<139,ROUND(NORMDIST(B2,100,15,TRUE)*100,0),IF(B2<150,ROUND(NORMDIST(B2,100,15,TRUE)*100,1),">99.9")))) -> <0.1
A3: =handsmooth!A3 -> 3 | B3: =handsmooth!B3 -> 49 | C3: =CONCATENATE(ROUND((100+$H$3*(B3-100))-(1.645*(15*$H$3*SQRT(1-$H$3))),0),"-",ROUND((100+$H$3*(B3-100))+(1.645*(15*$H$3*SQRT(1-$H$3))),0)) -> 46-59 | D3: =CONCATENATE(ROUND((100+$H$3*(B3-100))-(1.96*(15*$H$3*SQRT(1-$H$3))),0),"-",ROUND((100+$H$3*(B3-100))+(1.96*(15*$H$3*SQRT(1-$H$3))),0)) -> 45-60 | E3: =IF(B3<51,"<0.1",IF(B3<62,ROUND(NORMDIST(B3,100,15,TRUE)*100,1),IF(B3<139,ROUND(NORMDIST(B3,100,15,TRUE)*100,0),IF(B3<150,ROUND(NORMDIST(B3,100,15,TRUE)*100,1),">99.9")))) -> <0.1 | G3: composite reliability: | H3: 0.93
A4: =handsmooth!A4 -> 4 | B4: =handsmooth!B4 -> 52 | C4: =CONCATENATE(ROUND((100+$H$3*(B4-100))-(1.645*(15*$H$3*SQRT(1-$H$3))),0),"-",ROUND((100+$H$3*(B4-100))+(1.645*(15*$H$3*SQRT(1-$H$3))),0)) -> 49-61 | D4: =CONCATENATE(ROUND((100+$H$3*(B4-100))-(1.96*(15*$H$3*SQRT(1-$H$3))),0),"-",ROUND((100+$H$3*(B4-100))+(1.96*(15*$H$3*SQRT(1-$H$3))),0)) -> 48-63 | E4: =IF(B4<51,"<0.1",IF(B4<62,ROUND(NORMDIST(B4,100,15,TRUE)*100,1),IF(B4<139,ROUND(NORMDIST(B4,100,15,TRUE)*100,0),IF(B4<150,ROUND(NORMDIST(B4,100,15,TRUE)*100,1),">99.9")))) -> 0.1
A5: =handsmooth!A5 -> 5 | B5: =handsmooth!B5 -> 56 | C5: =CONCATENATE(ROUND((100+$H$3*(B5-100))-(1.645*(15*$H$3*SQRT(1-$H$3))),0),"-",ROUND((100+$H$3*(B5-100))+(1.645*(15*$H$3*SQRT(1-$H$3))),0)) -> 53-65 | D5: =CONCATENATE(ROUND((100+$H$3*(B5-100))-(1.96*(15*$H$3*SQRT(1-$H$3))),0),"-",ROUND((100+$H$3*(B5-100))+(1.96*(15*$H$3*SQRT(1-$H$3))),0)) -> 52-66 | E5: =IF(B5<51,"<0.1",IF(B5<62,ROUND(NORMDIST(B5,100,15,TRUE)*100,1),IF(B5<139,ROUND(NORMDIST(B5,100,15,TRUE)*100,0),IF(B5<150,ROUND(NORMDIST(B5,100,15,TRUE)*100,1),">99.9")))) -> 0.2 | G5: NOTE: THIS PROGRAM USES ESTIMATED TRUE SCORES AND THE SEE.
A6: =handsmooth!A6 -> 6 | B6: =handsmooth!B6 -> 59 | C6: =CONCATENATE(ROUND((100+$H$3*(B6-100))-(1.645*(15*$H$3*SQRT(1-$H$3))),0),"-",ROUND((100+$H$3*(B6-100))+(1.645*(15*$H$3*SQRT(1-$H$3))),0)) -> 56-68 | D6: =CONCATENATE(ROUND((100+$H$3*(B6-100))-(1.96*(15*$H$3*SQRT(1-$H$3))),0),"-",ROUND((100+$H$3*(B6-100))+(1.96*(15*$H$3*SQRT(1-$H$3))),0)) -> 55-69 | E6: =IF(B6<51,"<0.1",IF(B6<62,ROUND(NORMDIST(B6,100,15,TRUE)*100,1),IF(B6<139,ROUND(NORMDIST(B6,100,15,TRUE)*100,0),IF(B6<150,ROUND(NORMDIST(B6,100,15,TRUE)*100,1),">99.9")))) -> 0.3
A7: =handsmooth!A7 -> 7 | B7: =handsmooth!B7 -> 63 | C7: =CONCATENATE(ROUND((100+$H$3*(B7-100))-(1.645*(15*$H$3*SQRT(1-$H$3))),0),"-",ROUND((100+$H$3*(B7-100))+(1.645*(15*$H$3*SQRT(1-$H$3))),0)) -> 60-72 | D7: =CONCATENATE(ROUND((100+$H$3*(B7-100))-(1.96*(15*$H$3*SQRT(1-$H$3))),0),"-",ROUND((100+$H$3*(B7-100))+(1.96*(15*$H$3*SQRT(1-$H$3))),0)) -> 58-73 | E7: =IF(B7<51,"<0.1",IF(B7<62,ROUND(NORMDIST(B7,100,15,TRUE)*100,1),IF(B7<139,ROUND(NORMDIST(B7,100,15,TRUE)*100,0),IF(B7<150,ROUND(NORMDIST(B7,100,15,TRUE)*100,1),">99.9")))) -> 1
A8: =handsmooth!A8 -> 8 | B8: =handsmooth!B8 -> 66 | C8: =CONCATENATE(ROUND((100+$H$3*(B8-100))-(1.645*(15*$H$3*SQRT(1-$H$3))),0),"-",ROUND((100+$H$3*(B8-100))+(1.645*(15*$H$3*SQRT(1-$H$3))),0)) -> 62-74 | D8: =CONCATENATE(ROUND((100+$H$3*(B8-100))-(1.96*(15*$H$3*SQRT(1-$H$3))),0),"-",ROUND((100+$H$3*(B8-100))+(1.96*(15*$H$3*SQRT(1-$H$3))),0)) -> 61-76 | E8: =IF(B8<51,"<0.1",IF(B8<62,ROUND(NORMDIST(B8,100,15,TRUE)*100,1),IF(B8<139,ROUND(NORMDIST(B8,100,15,TRUE)*100,0),IF(B8<150,ROUND(NORMDIST(B8,100,15,TRUE)*100,1),">99.9")))) -> 1
A9: =handsmooth!A9 -> 9 | B9: =handsmooth!B9 -> 69 | C9: =CONCATENATE(ROUND((100+$H$3*(B9-100))-(1.645*(15*$H$3*SQRT(1-$H$3))),0),"-",ROUND((100+$H$3*(B9-100))+(1.645*(15*$H$3*SQRT(1-$H$3))),0)) -> 65-77 | D9: =CONCATENATE(ROUND((100+$H$3*(B9-100))-(1.96*(15*$H$3*SQRT(1-$H$3))),0),"-",ROUND((100+$H$3*(B9-100))+(1.96*(15*$H$3*SQRT(1-$H$3))),0)) -> 64-78 | E9: =IF(B9<51,"<0.1",IF(B9<62,ROUND(NORMDIST(B9,100,15,TRUE)*100,1),IF(B9<139,ROUND(NORMDIST(B9,100,15,TRUE)*100,0),IF(B9<150,ROUND(NORMDIST(B9,100,15,TRUE)*100,1),">99.9")))) -> 2
A10: =handsmooth!A10 -> 10 | B10: =handsmooth!B10 -> 73 | C10: =CONCATENATE(ROUND((100+$H$3*(B10-100))-(1.645*(15*$H$3*SQRT(1-$H$3))),0),"-",ROUND((100+$H$3*(B10-100))+(1.645*(15*$H$3*SQRT(1-$H$3))),0)) -> 69-81 | D10: =CONCATENATE(ROUND((100+$H$3*(B10-100))-(1.96*(15*$H$3*SQRT(1-$H$3))),0),"-",ROUND((100+$H$3*(B10-100))+(1.96*(15*$H$3*SQRT(1-$H$3))),0)) -> 68-82 | E10: =IF(B10<51,"<0.1",IF(B10<62,ROUND(NORMDIST(B10,100,15,TRUE)*100,1),IF(B10<139,ROUND(NORMDIST(B10,100,15,TRUE)*100,0),IF(B10<150,ROUND(NORMDIST(B10,100,15,TRUE)*100,1),">99.9")))) -> 4
A11: =handsmooth!A11 -> 11 | B11: =handsmooth!B11 -> 76 | C11: =CONCATENATE(ROUND((100+$H$3*(B11-100))-(1.645*(15*$H$3*SQRT(1-$H$3))),0),"-",ROUND((100+$H$3*(B11-100))+(1.645*(15*$H$3*SQRT(1-$H$3))),0)) -> 72-84 | D11: =CONCATENATE(ROUND((100+$H$3*(B11-100))-(1.96*(15*$H$3*SQRT(1-$H$3))),0),"-",ROUND((100+$H$3*(B11-100))+(1.96*(15*$H$3*SQRT(1-$H$3))),0)) -> 70-85 | E11: =IF(B11<51,"<0.1",IF(B11<62,ROUND(NORMDIST(B11,100,15,TRUE)*100,1),IF(B11<139,ROUND(NORMDIST(B11,100,15,TRUE)*100,0),IF(B11<150,ROUND(NORMDIST(B11,100,15,TRUE)*100,1),">99.9")))) -> 5
A12: =handsmooth!A12 -> 12 | B12: =handsmooth!B12 -> 79 | C12: =CONCATENATE(ROUND((100+$H$3*(B12-100))-(1.645*(15*$H$3*SQRT(1-$H$3))),0),"-",ROUND((100+$H$3*(B12-100))+(1.645*(15*$H$3*SQRT(1-$H$3))),0)) -> 74-87 | D12: =CONCATENATE(ROUND((100+$H$3*(B12-100))-(1.96*(15*$H$3*SQRT(1-$H$3))),0),"-",ROUND((100+$H$3*(B12-100))+(1.96*(15*$H$3*SQRT(1-$H$3))),0)) -> 73-88 | E12: =IF(B12<51,"<0.1",IF(B12<62,ROUND(NORMDIST(B12,100,15,TRUE)*100,1),IF(B12<139,ROUND(NORMDIST(B12,100,15,TRUE)*100,0),IF(B12<150,ROUND(NORMDIST(B12,100,15,TRUE)*100,1),">99.9")))) -> 8
A13: =handsmooth!A13 -> 13 | B13: =handsmooth!B13 -> 81 | C13: =CONCATENATE(ROUND((100+$H$3*(B13-100))-(1.645*(15*$H$3*SQRT(1-$H$3))),0),"-",ROUND((100+$H$3*(B13-100))+(1.645*(15*$H$3*SQRT(1-$H$3))),0)) -> 76-88 | D13: =CONCATENATE(ROUND((100+$H$3*(B13-100))-(1.96*(15*$H$3*SQRT(1-$H$3))),0),"-",ROUND((100+$H$3*(B13-100))+(1.96*(15*$H$3*SQRT(1-$H$3))),0)) -> 75-90 | E13: =IF(B13<51,"<0.1",IF(B13<62,ROUND(NORMDIST(B13,100,15,TRUE)*100,1),IF(B13<139,ROUND(NORMDIST(B13,100,15,TRUE)*100,0),IF(B13<150,ROUND(NORMDIST(B13,100,15,TRUE)*100,1),">99.9")))) -> 10
A14: =handsmooth!A14 -> 14 | B14: =handsmooth!B14 -> 84 | C14: =CONCATENATE(ROUND((100+$H$3*(B14-100))-(1.645*(15*$H$3*SQRT(1-$H$3))),0),"-",ROUND((100+$H$3*(B14-100))+(1.645*(15*$H$3*SQRT(1-$H$3))),0)) -> 79-91 | D14: =CONCATENATE(ROUND((100+$H$3*(B14-100))-(1.96*(15*$H$3*SQRT(1-$H$3))),0),"-",ROUND((100+$H$3*(B14-100))+(1.96*(15*$H$3*SQRT(1-$H$3))),0)) -> 78-92 | E14: =IF(B14<51,"<0.1",IF(B14<62,ROUND(NORMDIST(B14,100,15,TRUE)*100,1),IF(B14<139,ROUND(NORMDIST(B14,100,15,TRUE)*100,0),IF(B14<150,ROUND(NORMDIST(B14,100,15,TRUE)*100,1),">99.9")))) -> 14
A15: =handsmooth!A15 -> 15 | B15: =handsmooth!B15 -> 87 | C15: =CONCATENATE(ROUND((100+$H$3*(B15-100))-(1.645*(15*$H$3*SQRT(1-$H$3))),0),"-",ROUND((100+$H$3*(B15-100))+(1.645*(15*$H$3*SQRT(1-$H$3))),0)) -> 82-94 | D15: =CONCATENATE(ROUND((100+$H$3*(B15-100))-(1.96*(15*$H$3*SQRT(1-$H$3))),0),"-",ROUND((100+$H$3*(B15-100))+(1.96*(15*$H$3*SQRT(1-$H$3))),0)) -> 81-95 | E15: =IF(B15<51,"<0.1",IF(B15<62,ROUND(NORMDIST(B15,100,15,TRUE)*100,1),IF(B15<139,ROUND(NORMDIST(B15,100,15,TRUE)*100,0),IF(B15<150,ROUND(NORMDIST(B15,100,15,TRUE)*100,1),">99.9")))) -> 19
A16: =handsmooth!A16 -> 16 | B16: =handsmooth!B16 -> 89 | C16: =CONCATENATE(ROUND((100+$H$3*(B16-100))-(1.645*(15*$H$3*SQRT(1-$H$3))),0),"-",ROUND((100+$H$3*(B16-100))+(1.645*(15*$H$3*SQRT(1-$H$3))),0)) -> 84-96 | D16: =CONCATENATE(ROUND((100+$H$3*(B16-100))-(1.96*(15*$H$3*SQRT(1-$H$3))),0),"-",ROUND((100+$H$3*(B16-100))+(1.96*(15*$H$3*SQRT(1-$H$3))),0)) -> 83-97 | E16: =IF(B16<51,"<0.1",IF(B16<62,ROUND(NORMDIST(B16,100,15,TRUE)*100,1),IF(B16<139,ROUND(NORMDIST(B16,100,15,TRUE)*100,0),IF(B16<150,ROUND(NORMDIST(B16,100,15,TRUE)*100,1),">99.9")))) -> 23
A17: =handsmooth!A17 -> 17 | B17: =handsmooth!B17 -> 92 | C17: =CONCATENATE(ROUND((100+$H$3*(B17-100))-(1.645*(15*$H$3*SQRT(1-$H$3))),0),"-",ROUND((100+$H$3*(B17-100))+(1.645*(15*$H$3*SQRT(1-$H$3))),0)) -> 86-99 | D17: =CONCATENATE(ROUND((100+$H$3*(B17-100))-(1.96*(15*$H$3*SQRT(1-$H$3))),0),"-",ROUND((100+$H$3*(B17-100))+(1.96*(15*$H$3*SQRT(1-$H$3))),0)) -> 85-100 | E17: =IF(B17<51,"<0.1",IF(B17<62,ROUND(NORMDIST(B17,100,15,TRUE)*100,1),IF(B17<139,ROUND(NORMDIST(B17,100,15,TRUE)*100,0),IF(B17<150,ROUND(NORMDIST(B17,100,15,TRUE)*100,1),">99.9")))) -> 30
... A38: =handsmooth!A38 -> 38 | B38: =handsmooth!B38 -> 155 | C38: =CONCATENATE(ROUND((100+$H$3*(B38-100))-(1.645*(15*$H$3*SQRT(1-$H$3))),0),"-",ROUND((100+$H$3*(B38-100))+(1.645*(15*$H$3*SQRT(1-$H$3))),0)) -> 145-157 | D38: =CONCATENATE(ROUND((100+$H$3*(B38-100))-(1.96*(15*$H$3*SQRT(1-$H$3))),0),"-",ROUND((100+$H$3*(B38-100))+(1.96*(15*$H$3*SQRT(1-$H$3))),0)) -> 144-158 | E38: =IF(B38<51,"<0.1",IF(B38<62,ROUND(NORMDIST(B38,100,15,TRUE)*100,1),IF(B38<139,ROUND(NORMDIST(B38,100,15,TRUE)*100,0),IF(B38<150,ROUND(NORMDIST(B38,100,15,TRUE)*100,1),">99.9")))) -> >99.9
