Workbook

Sheet control
A1: type | B1: Power | C1: _1 | D1: _2 | E1: _3 | F1: _4 | G1: _5 | H1: _6 | I1: _7 | J1: _8 | K1: _9 | L1: _10 | M1: _11 | N1: _12 | O1: _13
A2: Obs | B2: . | C2: 37.077778 | D2: 37.783333 | E2: 39.944444 | F2: 38.711111 | G2: 37.794444 | H2: 35.322222 | I2: 35.583333 | J2: 29.95 | K2: 28.222222 | L2: 26.7 | M2: 25.2 | N2: 22.28 | O2: 21.32
A3: mean | B3: 2 | C3: 38.5213 | D3: 38.456 | E3: 38.2782 | F3: 37.8838 | G3: 37.3242 | H3: 36.1751 | I3: 34.0649 | J3: 31.2941 | K3: 28.7823 | L3: 26.9014 | M3: 24.8552 | N3: 22.6439 | O3: 20.0207
A4: SD | B4: 2 | C4: 12.646 | D4: 12.6244 | E4: 12.5698 | F4: 12.4551 | G4: 12.2971 | H4: 11.9788 | I4: 11.4028 | J4: 10.6536 | K4: 9.978 | L4: 9.4734 | M4: 8.9255 | N4: 8.3343 | O4: 7.6339
A5: skew | B5: 2 | C5: -0.2333 | D5: -0.208 | E5: -0.1646 | F5: -0.105 | G5: -0.048 | H5: 0.0325 | I5: 0.1307 | J5: 0.2182 | K5: 0.2769 | L5: 0.3128 | M5: 0.346 | N5: 0.3765 | O5: 0.4071
E9: mean | F9: SD | G9: skew
D10: 1 | E10: 38.5213 | F10: 12.646 | G10: -0.2333
D11: 2 | E11: 38.456 | F11: 12.6244 | G11: -0.208
D12: 3 | E12: 38.2782 | F12: 12.5698 | G12: -0.1646
D13: 4 | E13: 37.8838 | F13: 12.4551 | G13: -0.105
D14: 5 | E14: 37.3242 | F14: 12.2971 | G14: -0.048
D15: 6 | E15: 36.1751 | F15: 11.9788 | G15: 0.0325
D16: 7 | E16: 34.0649 | F16: 11.4028 | G16: 0.1307
D17: 8 | E17: 31.2941 | F17: 10.6536 | G17: 0.2182
D18: 9 | E18: 28.7823 | F18: 9.978 | G18: 0.2769
D19: 10 | E19: 26.9014 | F19: 9.4734 | G19: 0.3128
D20: 11 | E20: 24.8552 | F20: 8.9255 | G20: 0.346
D21: 12 | E21: 22.6439 | F21: 8.3343 | G21: 0.3765
D22: 13 | E22: 20.0207 | F22: 7.6339 | G22: 0.4071

Sheet handsmoothed
A1: bdtot | B1: g1 | C1: g2 | D1: g3 | E1: g4 | F1: g5 | G1: g6 | H1: g7 | I1: g8 | J1: g9 | K1: g10 | L1: g11 | M1: g12 | N1: g13 | O1: ReverseCross | P1: r12 | Q1: r23 | R1: r34 | S1: r45 | T1: r56 | U1: r67 | V1: r78 | W1: r89 | X1: r910 | Y1: r1011 | Z1: r1112 | AA1: r1213 | AB1: ReverseDown | AC1: d1 | AD1: d2 | AE1: d3 | AF1: d4 | AG1: d5 | AH1: d6 | AI1: d7 | AJ1: d8 | AK1: d9 | AL1: d10 | AM1: d11 | AN1: d12 | AO1: d13 | AP1: blank | AQ1: ssq1 | AR1: ssq2 | AS1: ssq3 | AT1: ssq4 | AU1: ssq5 | AV1: ssq6 | AW1: ssq7 | AX1: ssq8 | AY1: ssq9 | AZ1: ssq10 | BA1: ssq11 | BB1: ssq12 | BC1: ssq13 | BD1: blank | BE1: f1 | BF1: f2 | BG1: f3 | BH1: f4 | BI1: f5 | BJ1: f6 | BK1: f7 | BL1: f8 | BM1: f9 | BN1: f10 | BO1: f11 | BP1: f12 | BQ1: f13
A2: 0 | B2: 1 | C2: 1 | D2: 1 | E2: 1 | F2: 1 | G2: 1 | H2: 1 | I2: 1 | J2: 1 | K2: 1 | L2: 1 | M2: 1 | N2: 1 | P2: =(B2-C2) -> 0 | Q2: =(C2-D2) -> 0 | R2: =(D2-E2) -> 0 | S2: =(E2-F2) -> 0 | T2: =(F2-G2) -> 0 | U2: =(G2-H2) -> 0 | V2: =(H2-I2) -> 0 | W2: =(I2-J2) -> 0 | ... AA2: =(M2-N2) -> 0 | AC2: =(B3-B2) -> 0 | AD2: =(C3-C2) -> 0 | AE2: =(D3-D2) -> 0 | AF2: =(E3-E2) -> 0 | AG2: =(F3-F2) -> 0 | AH2: =(G3-G2) -> 0 | AI2: =(H3-H2) -> 0 | AJ2: =(I3-I2) -> 0 | ... AO2: =(N3-N2) -> 0 | AQ2: =B2^2 -> 1 | AR2: =C2^2 -> 1 | AS2: =D2^2 -> 1 | AT2: =E2^2 -> 1 | AU2: =F2^2 -> 1 | AV2: =G2^2 -> 1 | AW2: =H2^2 -> 1 | AX2: =I2^2 -> 1 | ... BC2: =N2^2 -> 1 | BE2: 0.000617 | BF2: 0.000596 | BG2: 0.000561 | BH2: 0.000513 | BI2: 0.000469 | BJ2: 0.000407 | BK2: 0.000333 | BL2: 0.000269 | BM2: 0 | BN2: 0 | BO2: 0 | BP2: 0 | BQ2: 0
A3: 1 | B3: 1 | C3: 1 | D3: 1 | E3: 1 | F3: 1 | G3: 1 | H3: 1 | I3: 1 | J3: 1 | K3: 1 | L3: 1 | M3: 1 | N3: 1 | P3: =(B3-C3) -> 0 | Q3: =(C3-D3) -> 0 | R3: =(D3-E3) -> 0 | S3: =(E3-F3) -> 0 | T3: =(F3-G3) -> 0 | U3: =(G3-H3) -> 0 | V3: =(H3-I3) -> 0 | W3: =(I3-J3) -> 0 | ... AA3: =(M3-N3) -> 0 | AC3: =(B4-B3) -> 0 | AD3: =(C4-C3) -> 0 | AE3: =(D4-D3) -> 0 | AF3: =(E4-E3) -> 0 | AG3: =(F4-F3) -> 0 | AH3: =(G4-G3) -> 0 | AI3: =(H4-H3) -> 0 | AJ3: =(I4-I3) -> 0 | ... AO3: =(N4-N3) -> 1 | AQ3: =B3^2 -> 1 | AR3: =C3^2 -> 1 | AS3: =D3^2 -> 1 | AT3: =E3^2 -> 1 | AU3: =F3^2 -> 1 | AV3: =G3^2 -> 1 | AW3: =H3^2 -> 1 | AX3: =I3^2 -> 1 | ... BC3: =N3^2 -> 1 | BE3: 0.000743 | BF3: 0.00072 | BG3: 0.000683 | BH3: 0.000633 | BI3: 0.000587 | BJ3: 0.000524 | BK3: 0.000455 | BL3: 0.000302 | BM3: 0.000181 | BN3: 0 | BO3: 0 | BP3: 0 | BQ3: 0
A4: 2 | B4: 1 | C4: 1 | D4: 1 | E4: 1 | F4: 1 | G4: 1 | H4: 1 | I4: 1 | J4: 1 | K4: 1 | L4: 1 | M4: 1 | N4: 2 | P4: =(B4-C4) -> 0 | Q4: =(C4-D4) -> 0 | R4: =(D4-E4) -> 0 | S4: =(E4-F4) -> 0 | T4: =(F4-G4) -> 0 | U4: =(G4-H4) -> 0 | V4: =(H4-I4) -> 0 | W4: =(I4-J4) -> 0 | ... AA4: =(M4-N4) -> -1 | AC4: =(B5-B4) -> 0 | AD4: =(C5-C4) -> 0 | AE4: =(D5-D4) -> 0 | AF4: =(E5-E4) -> 0 | AG4: =(F5-F4) -> 1 | AH4: =(G5-G4) -> 1 | AI4: =(H5-H4) -> 1 | AJ4: =(I5-I4) -> 1 | ... AO4: =(N5-N4) -> 0 | AQ4: =B4^2 -> 1 | AR4: =C4^2 -> 1 | AS4: =D4^2 -> 1 | AT4: =E4^2 -> 1 | AU4: =F4^2 -> 1 | AV4: =G4^2 -> 1 | AW4: =H4^2 -> 1 | AX4: =I4^2 -> 1 | ... BC4: =N4^2 -> 4 | BE4: 0.00089 | BF4: 0.000867 | BG4: 0.000828 | BH4: 0.000776 | BI4: 0.000729 | BJ4: 0.00067 | BK4: 0.000614 | BL4: 0.000411 | BM4: 0.000415 | BN4: 0.000382 | BO4: 0.000256 | BP4: 0.000343 | BQ4: 0.001066
A5: 3 | B5: 1 | C5: 1 | D5: 1 | E5: 1 | F5: 2 | G5: 2 | H5: 2 | I5: 2 | J5: 2 | K5: 2 | L5: 2 | M5: 2 | N5: 2 | P5: =(B5-C5) -> 0 | Q5: =(C5-D5) -> 0 | R5: =(D5-E5) -> 0 | S5: =(E5-F5) -> -1 | T5: =(F5-G5) -> 0 | U5: =(G5-H5) -> 0 | V5: =(H5-I5) -> 0 | W5: =(I5-J5) -> 0 | ... AA5: =(M5-N5) -> 0 | AC5: =(B6-B5) -> 1 | AD5: =(C6-C5) -> 1 | AE5: =(D6-D5) -> 1 | AF5: =(E6-E5) -> 1 | AG5: =(F6-F5) -> 0 | AH5: =(G6-G5) -> 0 | AI5: =(H6-H5) -> 0 | AJ5: =(I6-I5) -> 0 | ... AO5: =(N6-N5) -> 1 | AQ5: =B5^2 -> 1 | AR5: =C5^2 -> 1 | AS5: =D5^2 -> 1 | AT5: =E5^2 -> 1 | AU5: =F5^2 -> 4 | AV5: =G5^2 -> 4 | AW5: =H5^2 -> 4 | AX5: =I5^2 -> 4 | ... BC5: =N5^2 -> 4 | BE5: 0.001064 | BF5: 0.001039 | BG5: 0.000999 | BH5: 0.000947 | BI5: 0.000902 | BJ5: 0.000849 | BK5: 0.000761 | BL5: 0.000605 | BM5: 0.000672 | BN5: 0.000793 | BO5: 0.001039 | BP5: 0.001533 | BQ5: 0.002682
A6: 4 | B6: 2 | C6: 2 | D6: 2 | E6: 2 | F6: 2 | G6: 2 | H6: 2 | I6: 2 | J6: 2 | K6: 2 | L6: 2 | M6: 2 | N6: 3 | P6: =(B6-C6) -> 0 | Q6: =(C6-D6) -> 0 | R6: =(D6-E6) -> 0 | S6: =(E6-F6) -> 0 | T6: =(F6-G6) -> 0 | U6: =(G6-H6) -> 0 | V6: =(H6-I6) -> 0 | W6: =(I6-J6) -> 0 | ... AA6: =(M6-N6) -> -1 | AC6: =(B7-B6) -> 0 | AD6: =(C7-C6) -> 0 | AE6: =(D7-D6) -> 0 | AF6: =(E7-E6) -> 0 | AG6: =(F7-F6) -> 0 | AH6: =(G7-G6) -> 0 | AI6: =(H7-H6) -> 0 | AJ6: =(I7-I6) -> 0 | ... AO6: =(N7-N6) -> 0 | AQ6: =B6^2 -> 4 | AR6: =C6^2 -> 4 | AS6: =D6^2 -> 4 | AT6: =E6^2 -> 4 | AU6: =F6^2 -> 4 | AV6: =G6^2 -> 4 | AW6: =H6^2 -> 4 | AX6: =I6^2 -> 4 | ... BC6: =N6^2 -> 9 | BE6: 0.001266 | BF6: 0.001241 | BG6: 0.0012 | BH6: 0.001149 | BI6: 0.001108 | BJ6: 0.001068 | BK6: 0.000816 | BL6: 0.000866 | BM6: 0.001027 | BN6: 0.001262 | BO6: 0.001699 | BP6: 0.002523 | BQ6: 0.004348
A7: 5 | B7: 2 | C7: 2 | D7: 2 | E7: 2 | F7: 2 | G7: 2 | H7: 2 | I7: 2 | J7: 2 | K7: 2 | L7: 2 | M7: 3 | N7: 3 | P7: =(B7-C7) -> 0 | Q7: =(C7-D7) -> 0 | R7: =(D7-E7) -> 0 | S7: =(E7-F7) -> 0 | T7: =(F7-G7) -> 0 | U7: =(G7-H7) -> 0 | V7: =(H7-I7) -> 0 | W7: =(I7-J7) -> 0 | ... AA7: =(M7-N7) -> 0 | AC7: =(B8-B7) -> 0 | AD7: =(C8-C7) -> 0 | AE7: =(D8-D7) -> 0 | AF7: =(E8-E7) -> 0 | AG7: =(F8-F7) -> 0 | AH7: =(G8-G7) -> 0 | AI7: =(H8-H7) -> 0 | AJ7: =(I8-I7) -> 1 | ... AO7: =(N8-N7) -> 1 | AQ7: =B7^2 -> 4 | AR7: =C7^2 -> 4 | AS7: =D7^2 -> 4 | AT7: =E7^2 -> 4 | AU7: =F7^2 -> 4 | AV7: =G7^2 -> 4 | AW7: =H7^2 -> 4 | AX7: =I7^2 -> 4 | ... BC7: =N7^2 -> 9 | BE7: 0.001501 | BF7: 0.001476 | BG7: 0.001436 | BH7: 0.001388 | BI7: 0.001354 | BJ7: 0.00125 | BK7: 0.001072 | BL7: 0.001208 | BM7: 0.001503 | BN7: 0.001897 | BO7: 0.002594 | BP7: 0.003859 | BQ7: 0.006557
A8: 6 | B8: 2 | C8: 2 | D8: 2 | E8: 2 | F8: 2 | G8: 2 | H8: 2 | I8: 3 | J8: 3 | K8: 3 | L8: 3 | M8: 3 | N8: 4 | P8: =(B8-C8) -> 0 | Q8: =(C8-D8) -> 0 | R8: =(D8-E8) -> 0 | S8: =(E8-F8) -> 0 | T8: =(F8-G8) -> 0 | U8: =(G8-H8) -> 0 | V8: =(H8-I8) -> -1 | W8: =(I8-J8) -> 0 | ... AA8: =(M8-N8) -> -1 | AC8: =(B9-B8) -> 0 | AD8: =(C9-C8) -> 0 | AE8: =(D9-D8) -> 0 | AF8: =(E9-E8) -> 0 | AG8: =(F9-F8) -> 1 | AH8: =(G9-G8) -> 1 | AI8: =(H9-H8) -> 1 | AJ8: =(I9-I8) -> 0 | ... AO8: =(N9-N8) -> 0 | AQ8: =B8^2 -> 4 | AR8: =C8^2 -> 4 | AS8: =D8^2 -> 4 | AT8: =E8^2 -> 4 | AU8: =F8^2 -> 4 | AV8: =G8^2 -> 4 | AW8: =H8^2 -> 4 | AX8: =I8^2 -> 9 | ... BC8: =N8^2 -> 16 | BE8: 0.001774 | BF8: 0.001749 | BG8: 0.00171 | BH8: 0.001668 | BI8: 0.001644 | BJ8: 0.001333 | BK8: 0.001391 | BL8: 0.001645 | BM8: 0.002124 | BN8: 0.002728 | BO8: 0.003766 | BP8: 0.005591 | BQ8: 0.009351
A9: 7 | B9: 2 | C9: 2 | D9: 2 | E9: 2 | F9: 3 | G9: 3 | H9: 3 | I9: 3 | J9: 3 | K9: 3 | L9: 3 | M9: 4 | N9: 4 | P9: =(B9-C9) -> 0 | Q9: =(C9-D9) -> 0 | R9: =(D9-E9) -> 0 | S9: =(E9-F9) -> -1 | T9: =(F9-G9) -> 0 | U9: =(G9-H9) -> 0 | V9: =(H9-I9) -> 0 | W9: =(I9-J9) -> 0 | ... AA9: =(M9-N9) -> 0 | AC9: =(B10-B9) -> 1 | AD9: =(C10-C9) -> 1 | AE9: =(D10-D9) -> 1 | AF9: =(E10-E9) -> 1 | AG9: =(F10-F9) -> 0 | AH9: =(G10-G9) -> 0 | AI9: =(H10-H9) -> 0 | AJ9: =(I10-I9) -> 0 | ... AO9: =(N10-N9) -> 1 | AQ9: =B9^2 -> 4 | AR9: =C9^2 -> 4 | AS9: =D9^2 -> 4 | AT9: =E9^2 -> 4 | AU9: =F9^2 -> 9 | AV9: =G9^2 -> 9 | AW9: =H9^2 -> 9 | AX9: =I9^2 -> 9 | ... BC9: =N9^2 -> 16 | BE9: 0.002087 | BF9: 0.002063 | BG9: 0.002028 | BH9: 0.001974 | BI9: 0.001664 | BJ9: 0.001651 | BK9: 0.001783 | BL9: 0.002196 | BM9: 0.002913 | BN9: 0.003787 | BO9: 0.005248 | BP9: 0.007751 | BQ9: 0.012735
A10: 8 | B10: 3 | C10: 3 | D10: 3 | E10: 3 | F10: 3 | G10: 3 | H10: 3 | I10: 3 | J10: 3 | K10: 3 | L10: 4 | M10: 4 | N10: 5 | P10: =(B10-C10) -> 0 | Q10: =(C10-D10) -> 0 | R10: =(D10-E10) -> 0 | S10: =(E10-F10) -> 0 | T10: =(F10-G10) -> 0 | U10: =(G10-H10) -> 0 | V10: =(H10-I10) -> 0 | W10: =(I10-J10) -> 0 | ... AA10: =(M10-N10) -> -1 | AC10: =(B11-B10) -> 0 | AD10: =(C11-C10) -> 0 | AE10: =(D11-D10) -> 0 | AF10: =(E11-E10) -> 0 | AG10: =(F11-F10) -> 0 | AH10: =(G11-G10) -> 0 | AI10: =(H11-H10) -> 0 | AJ10: =(I11-I10) -> 0 | ... AO10: =(N11-N10) -> 0 | AQ10: =B10^2 -> 9 | AR10: =C10^2 -> 9 | AS10: =D10^2 -> 9 | AT10: =E10^2 -> 9 | AU10: =F10^2 -> 9 | AV10: =G10^2 -> 9 | AW10: =H10^2 -> 9 | AX10: =I10^2 -> 9 | ... BC10: =N10^2 -> 25 | BE10: 0.002447 | BF10: 0.002424 | BG10: 0.002317 | BH10: 0.001994 | BI10: 0.001985 | BJ10: 0.002029 | BK10: 0.00226 | BL10: 0.002876 | BM10: 0.003892 | BN10: 0.005097 | BO10: 0.007067 | BP10: 0.010353 | BQ10: 0.01667
A11: 9 | B11: 3 | C11: 3 | D11: 3 | E11: 3 | F11: 3 | G11: 3 | H11: 3 | I11: 3 | J11: 4 | K11: 4 | L11: 4 | M11: 5 | N11: 5 | P11: =(B11-C11) -> 0 | Q11: =(C11-D11) -> 0 | R11: =(D11-E11) -> 0 | S11: =(E11-F11) -> 0 | T11: =(F11-G11) -> 0 | U11: =(G11-H11) -> 0 | V11: =(H11-I11) -> 0 | W11: =(I11-J11) -> -1 | ... AA11: =(M11-N11) -> 0 | AC11: =(B12-B11) -> 0 | AD11: =(C12-C11) -> 0 | AE11: =(D12-D11) -> 0 | AF11: =(E12-E11) -> 0 | AG11: =(F12-F11) -> 0 | AH11: =(G12-G11) -> 0 | AI11: =(H12-H11) -> 0 | AJ11: =(I12-I11) -> 1 | ... AO11: =(N12-N11) -> 1 | AQ11: =B11^2 -> 9 | AR11: =C11^2 -> 9 | AS11: =D11^2 -> 9 | AT11: =E11^2 -> 9 | AU11: =F11^2 -> 9 | AV11: =G11^2 -> 9 | AW11: =H11^2 -> 9 | AX11: =I11^2 -> 9 | ... BC11: =N11^2 -> 25 | BE11: 0.002742 | BF11: 0.002582 | BG11: 0.002393 | BH11: 0.002372 | BI11: 0.002382 | BJ11: 0.002476 | BK11: 0.002831 | BL11: 0.003702 | BM11: 0.005081 | BN11: 0.006678 | BO11: 0.009233 | BP11: 0.013384 | BQ11: 0.021063
A12: 10 | B12: 3 | C12: 3 | D12: 3 | E12: 3 | F12: 3 | G12: 3 | H12: 3 | I12: 4 | J12: 4 | K12: 4 | L12: 5 | M12: 5 | N12: 6 | P12: =(B12-C12) -> 0 | Q12: =(C12-D12) -> 0 | R12: =(D12-E12) -> 0 | S12: =(E12-F12) -> 0 | T12: =(F12-G12) -> 0 | U12: =(G12-H12) -> 0 | V12: =(H12-I12) -> -1 | W12: =(I12-J12) -> 0 | ... AA12: =(M12-N12) -> -1 | AC12: =(B13-B12) -> 0 | AD12: =(C13-C12) -> 0 | AE12: =(D13-D12) -> 0 | AF12: =(E13-E12) -> 1 | AG12: =(F13-F12) -> 1 | AH12: =(G13-G12) -> 1 | AI12: =(H13-H12) -> 1 | AJ12: =(I13-I12) -> 0 | ... AO12: =(N13-N12) -> 0 | AQ12: =B12^2 -> 9 | AR12: =C12^2 -> 9 | AS12: =D12^2 -> 9 | AT12: =E12^2 -> 9 | AU12: =F12^2 -> 9 | AV12: =G12^2 -> 9 | AW12: =H12^2 -> 9 | AX12: =I12^2 -> 16 | ... BC12: =N12^2 -> 36 | BE12: 0.002856 | BF12: 0.002835 | BG12: 0.002811 | BH12: 0.002806 | BI12: 0.002842 | BJ12: 0.002999 | BK12: 0.003508 | BL12: 0.004687 | BM12: 0.006494 | BN12: 0.008541 | BO12: 0.011743 | BP12: 0.0168 | BQ12: 0.025772
A13: 11 | B13: 3 | C13: 3 | D13: 3 | E13: 4 | F13: 4 | G13: 4 | H13: 4 | I13: 4 | J13: 4 | K13: 5 | L13: 5 | M13: 6 | N13: 6 | P13: =(B13-C13) -> 0 | Q13: =(C13-D13) -> 0 | R13: =(D13-E13) -> -1 | S13: =(E13-F13) -> 0 | T13: =(F13-G13) -> 0 | U13: =(G13-H13) -> 0 | V13: =(H13-I13) -> 0 | W13: =(I13-J13) -> 0 | ... AA13: =(M13-N13) -> 0 | AC13: =(B14-B13) -> 1 | AD13: =(C14-C13) -> 1 | AE13: =(D14-D13) -> 1 | AF13: =(E14-E13) -> 0 | AG13: =(F14-F13) -> 0 | AH13: =(G14-G13) -> 0 | AI13: =(H14-H13) -> 0 | AJ13: =(I14-I13) -> 0 | ... AO13: =(N14-N13) -> 1 | AQ13: =B13^2 -> 9 | AR13: =C13^2 -> 9 | AS13: =D13^2 -> 9 | AT13: =E13^2 -> 16 | AU13: =F13^2 -> 16 | AV13: =G13^2 -> 16 | AW13: =H13^2 -> 16 | AX13: =I13^2 -> 16 | ... BC13: =N13^2 -> 36 | BE13: 0.003319 | BF13: 0.003302 | BG13: 0.003286 | BH13: 0.003302 | BI13: 0.00337 | BJ13: 0.003604 | BK13: 0.004301 | BL13: 0.005842 | BM13: 0.008138 | BN13: 0.010682 | BO13: 0.01457 | BP13: 0.020525 | BQ13: 0.030614
... A67: 65 | B67: 18 | C67: 18 | D67: 18 | E67: 18 | F67: 18 | G67: 19 | H67: 19 | I67: 19 | J67: 19 | K67: 19 | L67: 19 | M67: 19 | N67: 19 | P67: =(B67-C67) -> 0 | Q67: =(C67-D67) -> 0 | R67: =(D67-E67) -> 0 | S67: =(E67-F67) -> 0 | T67: =(F67-G67) -> -1 | U67: =(G67-H67) -> 0 | V67: =(H67-I67) -> 0 | W67: =(I67-J67) -> 0 | ... AA67: =(M67-N67) -> 0 | AC67: =(B68-B67) -> 1 | AD67: =(C68-C67) -> 1 | AE67: =(D68-D67) -> 1 | AF67: =(E68-E67) -> 1 | AG67: =(F68-F67) -> 1 | AH67: =(G68-G67) -> 0 | AI67: =(H68-H67) -> 0 | AJ67: =(I68-I67) -> 0 | ... AO67: =(N68-N67) -> 0 | AQ67: =B67^2 -> 324 | AR67: =C67^2 -> 324 | AS67: =D67^2 -> 324 | AT67: =E67^2 -> 324 | AU67: =F67^2 -> 324 | AV67: =G67^2 -> 361 | AW67: =H67^2 -> 361 | AX67: =I67^2 -> 361 | ... BC67: =N67^2 -> 361 | BE67: 0.003766 | BF67: 0.003738 | BG67: 0.003631 | BH67: 0.003364 | BI67: 0.002994 | BJ67: 0.002313 | BK67: 0.001343 | BL67: 0.00056 | BM67: 0.000205 | BN67: 6.7e-05 | BO67: 1.9e-05 | BP67: 3e-06 | BQ67: 0
A68: 66 | B68: 19 | C68: 19 | D68: 19 | E68: 19 | F68: 19 | G68: 19 | H68: 19 | I68: 19 | J68: 19 | K68: 19 | L68: 19 | M68: 19 | N68: 19 | P68: =(B68-C68) -> 0 | Q68: =(C68-D68) -> 0 | R68: =(D68-E68) -> 0 | S68: =(E68-F68) -> 0 | T68: =(F68-G68) -> 0 | U68: =(G68-H68) -> 0 | V68: =(H68-I68) -> 0 | W68: =(I68-J68) -> 0 | ... AA68: =(M68-N68) -> 0 | AQ68: =B68^2 -> 361 | AR68: =C68^2 -> 361 | AS68: =D68^2 -> 361 | AT68: =E68^2 -> 361 | AU68: =F68^2 -> 361 | AV68: =G68^2 -> 361 | AW68: =H68^2 -> 361 | AX68: =I68^2 -> 361 | ... BC68: =N68^2 -> 361 | BE68: 0.003072 | BF68: 0.003063 | BG68: 0.002991 | BH68: 0.002785 | BI68: 0.002481 | BJ68: 0.00191 | BK68: 0.001092 | BL68: 0.000444 | BM68: 0.000165 | BN68: 6.4e-05 | BO68: 1.5e-05 | BP68: 2e-06 | BQ68: 0
A69: N | B69: =SUM(freq!B2:B68) -> 180 | C69: =SUM(freq!C2:C68) -> 180 | D69: =SUM(freq!D2:D68) -> 180 | E69: =SUM(freq!E2:E68) -> 180 | F69: =SUM(freq!F2:F68) -> 180 | G69: =SUM(freq!G2:G68) -> 180 | H69: =SUM(freq!H2:H68) -> 180 | I69: =SUM(freq!I2:I68) -> 180 | ... N69: =SUM(freq!N2:N68) -> 100 | O69: =SUM(B69:N69) -> 2020 | BE69: . | BF69: . | BG69: . | BH69: . | BI69: . | BJ69: . | BK69: . | BL69: . | BM69: . | BN69: . | BO69: . | BP69: . | BQ69: .
A70: mean | B70: =freq!B69/handsmoothed!B69 -> 9.6888889 | C70: =freq!C69/handsmoothed!C69 -> 9.8777778 | D70: =freq!D69/handsmoothed!D69 -> 10.433333 | E70: =freq!E69/handsmoothed!E69 -> 10.255556 | F70: =freq!F69/handsmoothed!F69 -> 10.166667 | G70: =freq!G69/handsmoothed!G69 -> 9.9388889 | H70: =freq!H69/handsmoothed!H69 -> 10.244444 | I70: =freq!I69/handsmoothed!I69 -> 9.5777778 | ... O70: =freq!O69/handsmoothed!O69 -> 10.000495 | BE70: . | BF70: . | BG70: . | BH70: . | BI70: . | BJ70: . | BK70: . | BL70: . | BM70: . | BN70: . | BO70: . | BP70: . | BQ70: .
A71: sd | B71: =SQRT((freq!B70-B70^2*B69)/(B69-1)) -> 2.9126748 | C71: =SQRT((freq!C70-C70^2*C69)/(C69-1)) -> 3.0077285 | D71: =SQRT((freq!D70-D70^2*D69)/(D69-1)) -> 2.9749419 | E71: =SQRT((freq!E70-E70^2*E69)/(E69-1)) -> 3.0710801 | F71: =SQRT((freq!F70-F70^2*F69)/(F69-1)) -> 2.8705789 | G71: =SQRT((freq!G70-G70^2*G69)/(G69-1)) -> 3.1377391 | H71: =SQRT((freq!H70-H70^2*H69)/(H69-1)) -> 3.0901216 | I71: =SQRT((freq!I70-I70^2*I69)/(I69-1)) -> 3.0543596 | ... O71: =SQRT((freq!O70-O70^2*O69)/(O69-1)) -> 3.0156435 | BE71: . | BF71: . | BG71: . | BH71: . | BI71: . | BJ71: . | BK71: . | BL71: . | BM71: . | BN71: . | BO71: . | BP71: . | BQ71: .
A72: ideal | B72: =0.3-ABS(10-ROUND(B70,2)) -> -0.01 | C72: =0.3-ABS(10-ROUND(C70,2)) -> 0.18 | D72: =0.3-ABS(10-ROUND(D70,2)) -> -0.13 | E72: =0.3-ABS(10-ROUND(E70,2)) -> 0.04 | F72: =0.3-ABS(10-ROUND(F70,2)) -> 0.13 | G72: =0.3-ABS(10-ROUND(G70,2)) -> 0.24 | H72: =0.3-ABS(10-ROUND(H70,2)) -> 0.06 | I72: =0.3-ABS(10-ROUND(I70,2)) -> -0.12 | ... N72: =0.3-ABS(10-ROUND(N70,2)) -> -0.08 | BE72: . | BF72: . | BG72: . | BH72: . | BI72: . | BJ72: . | BK72: . | BL72: . | BM72: . | BN72: . | BO72: . | BP72: . | BQ72: .
B73: =0.3-ABS(3-B71) -> 0.21267484 | C73: =0.3-ABS(3-C71) -> 0.29227149 | D73: =0.3-ABS(3-D71) -> 0.2749419 | E73: =0.3-ABS(3-E71) -> 0.22891986 | F73: =0.3-ABS(3-F71) -> 0.17057894 | G73: =0.3-ABS(3-G71) -> 0.16226091 | H73: =0.3-ABS(3-H71) -> 0.20987838 | I73: =0.3-ABS(3-I71) -> 0.24564043 | ... N73: =0.3-ABS(3-N71) -> -0.023561434 | BE73: . | BF73: . | BG73: . | BH73: . | BI73: . | BJ73: . | BK73: . | BL73: . | BM73: . | BN73: . | BO73: . | BP73: . | BQ73: .
A74: standard | B74: =0.6-ABS(10-ROUND(B70,2)) -> 0.29 | C74: =0.6-ABS(10-ROUND(C70,2)) -> 0.48 | D74: =0.6-ABS(10-ROUND(D70,2)) -> 0.17 | E74: =0.6-ABS(10-ROUND(E70,2)) -> 0.34 | F74: =0.6-ABS(10-ROUND(F70,2)) -> 0.43 | G74: =0.6-ABS(10-ROUND(G70,2)) -> 0.54 | H74: =0.6-ABS(10-ROUND(H70,2)) -> 0.36 | I74: =0.6-ABS(10-ROUND(I70,2)) -> 0.18 | ... N74: =0.6-ABS(10-ROUND(N70,2)) -> 0.22 | BE74: . | BF74: . | BG74: . | BH74: . | BI74: . | BJ74: . | BK74: . | BL74: . | BM74: . | BN74: . | BO74: . | BP74: . | BQ74: .
B75: =0.3-ABS(3-B71) -> 0.21267484 | C75: =0.3-ABS(3-C71) -> 0.29227149 | D75: =0.3-ABS(3-D71) -> 0.2749419 | E75: =0.3-ABS(3-E71) -> 0.22891986 | F75: =0.3-ABS(3-F71) -> 0.17057894 | G75: =0.3-ABS(3-G71) -> 0.16226091 | H75: =0.3-ABS(3-H71) -> 0.20987838 | I75: =0.3-ABS(3-I71) -> 0.24564043 | ... N75: =0.3-ABS(3-N71) -> -0.023561434 | BE75: . | BF75: . | BG75: . | BH75: . | BI75: . | BJ75: . | BK75: . | BL75: . | BM75: . | BN75: . | BO75: . | BP75: . | BQ75: .
A76: exception | B76: =0.9-ABS(10-ROUND(B70,2)) -> 0.59 | C76: =0.9-ABS(10-ROUND(C70,2)) -> 0.78 | D76: =0.9-ABS(10-ROUND(D70,2)) -> 0.47 | E76: =0.9-ABS(10-ROUND(E70,2)) -> 0.64 | F76: =0.9-ABS(10-ROUND(F70,2)) -> 0.73 | G76: =0.9-ABS(10-ROUND(G70,2)) -> 0.84 | H76: =0.9-ABS(10-ROUND(H70,2)) -> 0.66 | I76: =0.9-ABS(10-ROUND(I70,2)) -> 0.48 | ... N76: =0.9-ABS(10-ROUND(N70,2)) -> 0.52 | BE76: . | BF76: . | BG76: . | BH76: . | BI76: . | BJ76: . | BK76: . | BL76: . | BM76: . | BN76: . | BO76: . | BP76: . | BQ76: .
B77: =0.45-ABS(3-B71) -> 0.36267484 | C77: =0.45-ABS(3-C71) -> 0.44227149 | D77: =0.45-ABS(3-D71) -> 0.4249419 | E77: =0.45-ABS(3-E71) -> 0.37891986 | F77: =0.45-ABS(3-F71) -> 0.32057894 | G77: =0.45-ABS(3-G71) -> 0.31226091 | H77: =0.45-ABS(3-H71) -> 0.35987838 | I77: =0.45-ABS(3-I71) -> 0.39564043 | ... N77: =0.45-ABS(3-N71) -> 0.12643857 | BE77: . | BF77: . | BG77: . | BH77: . | BI77: . | BJ77: . | BK77: . | BL77: . | BM77: . | BN77: . | BO77: . | BP77: . | BQ77: .

Sheet freq
B1: g1 | C1: g2 | D1: g3 | E1: g4 | F1: g5 | G1: g6 | H1: g7 | I1: g8 | J1: g9 | K1: g10 | L1: g11 | M1: g12 | N1: g13 | P1: sssq1 | Q1: sssq2 | R1: sssq3 | S1: sssq4 | T1: sssq5 | U1: sssq6 | V1: sssq7 | W1: sssq8 | X1: sssq9 | Y1: sssq10 | Z1: sssq11 | AA1: sssq12 | AB1: sssq13
A2: 0 | B2: . | C2: . | D2: . | E2: . | F2: . | G2: . | H2: . | I2: . | J2: . | K2: . | L2: 1 | M2: . | N2: . | P2: =handsmoothed!B2^2 -> 1 | Q2: =handsmoothed!C2^2 -> 1 | R2: =handsmoothed!D2^2 -> 1 | S2: =handsmoothed!E2^2 -> 1 | T2: =handsmoothed!F2^2 -> 1 | U2: =handsmoothed!G2^2 -> 1 | V2: =handsmoothed!H2^2 -> 1 | W2: =handsmoothed!I2^2 -> 1 | ... AB2: =handsmoothed!N2^2 -> 1
A3: 1 | B3: . | C3: . | D3: . | E3: . | F3: . | G3: . | H3: . | I3: . | J3: . | K3: . | L3: . | M3: . | N3: . | P3: =handsmoothed!B3^2 -> 1 | Q3: =handsmoothed!C3^2 -> 1 | R3: =handsmoothed!D3^2 -> 1 | S3: =handsmoothed!E3^2 -> 1 | T3: =handsmoothed!F3^2 -> 1 | U3: =handsmoothed!G3^2 -> 1 | V3: =handsmoothed!H3^2 -> 1 | W3: =handsmoothed!I3^2 -> 1 | ... AB3: =handsmoothed!N3^2 -> 1
A4: 2 | B4: . | C4: . | D4: . | E4: 1 | F4: . | G4: . | H4: . | I4: 1 | J4: . | K4: . | L4: . | M4: . | N4: 1 | P4: =handsmoothed!B4^2 -> 1 | Q4: =handsmoothed!C4^2 -> 1 | R4: =handsmoothed!D4^2 -> 1 | S4: =handsmoothed!E4^2 -> 1 | T4: =handsmoothed!F4^2 -> 1 | U4: =handsmoothed!G4^2 -> 1 | V4: =handsmoothed!H4^2 -> 1 | W4: =handsmoothed!I4^2 -> 1 | ... AB4: =handsmoothed!N4^2 -> 4
A5: 3 | B5: 1 | C5: . | D5: . | E5: . | F5: . | G5: . | H5: . | I5: . | J5: . | K5: . | L5: . | M5: . | N5: . | P5: =handsmoothed!B5^2 -> 1 | Q5: =handsmoothed!C5^2 -> 1 | R5: =handsmoothed!D5^2 -> 1 | S5: =handsmoothed!E5^2 -> 1 | T5: =handsmoothed!F5^2 -> 4 | U5: =handsmoothed!G5^2 -> 4 | V5: =handsmoothed!H5^2 -> 4 | W5: =handsmoothed!I5^2 -> 4 | ... AB5: =handsmoothed!N5^2 -> 4
A6: 4 | B6: . | C6: . | D6: . | E6: . | F6: . | G6: 1 | H6: . | I6: 2 | J6: . | K6: . | L6: . | M6: . | N6: 2 | P6: =handsmoothed!B6^2 -> 4 | Q6: =handsmoothed!C6^2 -> 4 | R6: =handsmoothed!D6^2 -> 4 | S6: =handsmoothed!E6^2 -> 4 | T6: =handsmoothed!F6^2 -> 4 | U6: =handsmoothed!G6^2 -> 4 | V6: =handsmoothed!H6^2 -> 4 | W6: =handsmoothed!I6^2 -> 4 | ... AB6: =handsmoothed!N6^2 -> 9
A7: 5 | B7: . | C7: 1 | D7: . | E7: . | F7: . | G7: . | H7: . | I7: 2 | J7: 1 | K7: . | L7: . | M7: . | N7: 3 | P7: =handsmoothed!B7^2 -> 4 | Q7: =handsmoothed!C7^2 -> 4 | R7: =handsmoothed!D7^2 -> 4 | S7: =handsmoothed!E7^2 -> 4 | T7: =handsmoothed!F7^2 -> 4 | U7: =handsmoothed!G7^2 -> 4 | V7: =handsmoothed!H7^2 -> 4 | W7: =handsmoothed!I7^2 -> 4 | ... AB7: =handsmoothed!N7^2 -> 9
A8: 6 | B8: . | C8: . | D8: 1 | E8: 2 | F8: 1 | G8: 1 | H8: . | I8: . | J8: . | K8: 1 | L8: . | M8: 1 | N8: 2 | P8: =handsmoothed!B8^2 -> 4 | Q8: =handsmoothed!C8^2 -> 4 | R8: =handsmoothed!D8^2 -> 4 | S8: =handsmoothed!E8^2 -> 4 | T8: =handsmoothed!F8^2 -> 4 | U8: =handsmoothed!G8^2 -> 4 | V8: =handsmoothed!H8^2 -> 4 | W8: =handsmoothed!I8^2 -> 9 | ... AB8: =handsmoothed!N8^2 -> 16
A9: 7 | B9: . | C9: . | D9: . | E9: . | F9: . | G9: . | H9: . | I9: . | J9: 2 | K9: . | L9: . | M9: . | N9: . | P9: =handsmoothed!B9^2 -> 4 | Q9: =handsmoothed!C9^2 -> 4 | R9: =handsmoothed!D9^2 -> 4 | S9: =handsmoothed!E9^2 -> 4 | T9: =handsmoothed!F9^2 -> 9 | U9: =handsmoothed!G9^2 -> 9 | V9: =handsmoothed!H9^2 -> 9 | W9: =handsmoothed!I9^2 -> 9 | ... AB9: =handsmoothed!N9^2 -> 16
A10: 8 | B10: 2 | C10: 1 | D10: 1 | E10: . | F10: . | G10: 1 | H10: 1 | I10: . | J10: . | K10: 1 | L10: 1 | M10: 3 | N10: 1 | P10: =handsmoothed!B10^2 -> 9 | Q10: =handsmoothed!C10^2 -> 9 | R10: =handsmoothed!D10^2 -> 9 | S10: =handsmoothed!E10^2 -> 9 | T10: =handsmoothed!F10^2 -> 9 | U10: =handsmoothed!G10^2 -> 9 | V10: =handsmoothed!H10^2 -> 9 | W10: =handsmoothed!I10^2 -> 9 | ... AB10: =handsmoothed!N10^2 -> 25
A11: 9 | B11: . | C11: . | D11: . | E11: . | F11: . | G11: . | H11: . | I11: . | J11: . | K11: . | L11: . | M11: . | N11: . | P11: =handsmoothed!B11^2 -> 9 | Q11: =handsmoothed!C11^2 -> 9 | R11: =handsmoothed!D11^2 -> 9 | S11: =handsmoothed!E11^2 -> 9 | T11: =handsmoothed!F11^2 -> 9 | U11: =handsmoothed!G11^2 -> 9 | V11: =handsmoothed!H11^2 -> 9 | W11: =handsmoothed!I11^2 -> 9 | ... AB11: =handsmoothed!N11^2 -> 25
A12: 10 | B12: . | C12: . | D12: . | E12: . | F12: . | G12: . | H12: . | I12: . | J12: . | K12: . | L12: 1 | M12: 1 | N12: . | P12: =handsmoothed!B12^2 -> 9 | Q12: =handsmoothed!C12^2 -> 9 | R12: =handsmoothed!D12^2 -> 9 | S12: =handsmoothed!E12^2 -> 9 | T12: =handsmoothed!F12^2 -> 9 | U12: =handsmoothed!G12^2 -> 9 | V12: =handsmoothed!H12^2 -> 9 | W12: =handsmoothed!I12^2 -> 16 | ... AB12: =handsmoothed!N12^2 -> 36
A13: 11 | B13: . | C13: . | D13: . | E13: . | F13: . | G13: 1 | H13: 2 | I13: . | J13: 1 | K13: . | L13: . | M13: 1 | N13: . | P13: =handsmoothed!B13^2 -> 9 | Q13: =handsmoothed!C13^2 -> 9 | R13: =handsmoothed!D13^2 -> 9 | S13: =handsmoothed!E13^2 -> 16 | T13: =handsmoothed!F13^2 -> 16 | U13: =handsmoothed!G13^2 -> 16 | V13: =handsmoothed!H13^2 -> 16 | W13: =handsmoothed!I13^2 -> 16 | ... AB13: =handsmoothed!N13^2 -> 36
A14: 12 | B14: 1 | C14: 5 | D14: 1 | E14: 1 | F14: 4 | G14: . | H14: 3 | I14: 3 | J14: 8 | K14: 4 | L14: 2 | M14: 4 | N14: 10 | P14: =handsmoothed!B14^2 -> 16 | Q14: =handsmoothed!C14^2 -> 16 | R14: =handsmoothed!D14^2 -> 16 | S14: =handsmoothed!E14^2 -> 16 | T14: =handsmoothed!F14^2 -> 16 | U14: =handsmoothed!G14^2 -> 16 | V14: =handsmoothed!H14^2 -> 16 | W14: =handsmoothed!I14^2 -> 16 | ... AB14: =handsmoothed!N14^2 -> 49
A15: 13 | B15: . | C15: . | D15: . | E15: . | F15: . | G15: . | H15: . | I15: . | J15: . | K15: . | L15: . | M15: . | N15: . | P15: =handsmoothed!B15^2 -> 16 | Q15: =handsmoothed!C15^2 -> 16 | R15: =handsmoothed!D15^2 -> 16 | S15: =handsmoothed!E15^2 -> 16 | T15: =handsmoothed!F15^2 -> 16 | U15: =handsmoothed!G15^2 -> 16 | V15: =handsmoothed!H15^2 -> 16 | W15: =handsmoothed!I15^2 -> 25 | ... AB15: =handsmoothed!N15^2 -> 49
A16: 14 | B16: . | C16: . | D16: . | E16: . | F16: . | G16: . | H16: . | I16: . | J16: . | K16: . | L16: 1 | M16: 2 | N16: . | P16: =handsmoothed!B16^2 -> 16 | Q16: =handsmoothed!C16^2 -> 16 | R16: =handsmoothed!D16^2 -> 16 | S16: =handsmoothed!E16^2 -> 16 | T16: =handsmoothed!F16^2 -> 16 | U16: =handsmoothed!G16^2 -> 25 | V16: =handsmoothed!H16^2 -> 25 | W16: =handsmoothed!I16^2 -> 25 | ... AB16: =handsmoothed!N16^2 -> 64
A17: 15 | B17: . | C17: . | D17: . | E17: . | F17: . | G17: . | H17: 1 | I17: 1 | J17: 2 | K17: . | L17: . | M17: 1 | N17: . | P17: =handsmoothed!B17^2 -> 25 | Q17: =handsmoothed!C17^2 -> 25 | R17: =handsmoothed!D17^2 -> 25 | S17: =handsmoothed!E17^2 -> 25 | T17: =handsmoothed!F17^2 -> 25 | U17: =handsmoothed!G17^2 -> 25 | V17: =handsmoothed!H17^2 -> 25 | W17: =handsmoothed!I17^2 -> 25 | ... AB17: =handsmoothed!N17^2 -> 64
A18: 16 | B18: 2 | C18: 1 | D18: 1 | E18: 3 | F18: 3 | G18: 2 | H18: 5 | I18: 11 | J18: 10 | K18: 4 | L18: 10 | M18: 15 | N18: 8 | P18: =handsmoothed!B18^2 -> 25 | Q18: =handsmoothed!C18^2 -> 25 | R18: =handsmoothed!D18^2 -> 25 | S18: =handsmoothed!E18^2 -> 25 | T18: =handsmoothed!F18^2 -> 25 | U18: =handsmoothed!G18^2 -> 25 | V18: =handsmoothed!H18^2 -> 25 | W18: =handsmoothed!I18^2 -> 36 | ... AB18: =handsmoothed!N18^2 -> 64
A19: 17 | B19: . | C19: . | D19: . | E19: . | F19: . | G19: . | H19: . | I19: . | J19: . | K19: . | L19: . | M19: 1 | N19: . | P19: =handsmoothed!B19^2 -> 25 | Q19: =handsmoothed!C19^2 -> 25 | R19: =handsmoothed!D19^2 -> 25 | S19: =handsmoothed!E19^2 -> 25 | T19: =handsmoothed!F19^2 -> 25 | U19: =handsmoothed!G19^2 -> 25 | V19: =handsmoothed!H19^2 -> 25 | W19: =handsmoothed!I19^2 -> 36 | ... AB19: =handsmoothed!N19^2 -> 81
A20: 18 | B20: . | C20: . | D20: . | E20: . | F20: 1 | G20: 1 | H20: . | I20: 1 | J20: 1 | K20: . | L20: . | M20: . | N20: 3 | P20: =handsmoothed!B20^2 -> 25 | Q20: =handsmoothed!C20^2 -> 25 | R20: =handsmoothed!D20^2 -> 25 | S20: =handsmoothed!E20^2 -> 25 | T20: =handsmoothed!F20^2 -> 25 | U20: =handsmoothed!G20^2 -> 36 | V20: =handsmoothed!H20^2 -> 36 | W20: =handsmoothed!I20^2 -> 36 | ... AB20: =handsmoothed!N20^2 -> 81
A21: 19 | B21: 2 | C21: 1 | D21: 1 | E21: 1 | F21: . | G21: . | H21: 1 | I21: 1 | J21: . | K21: . | L21: 1 | M21: . | N21: 2 | P21: =handsmoothed!B21^2 -> 36 | Q21: =handsmoothed!C21^2 -> 36 | R21: =handsmoothed!D21^2 -> 36 | S21: =handsmoothed!E21^2 -> 36 | T21: =handsmoothed!F21^2 -> 36 | U21: =handsmoothed!G21^2 -> 36 | V21: =handsmoothed!H21^2 -> 36 | W21: =handsmoothed!I21^2 -> 49 | ... AB21: =handsmoothed!N21^2 -> 100
A22: 20 | B22: 11 | C22: 12 | D22: 8 | E22: 13 | F22: 4 | G22: 17 | H22: 11 | I22: 18 | J22: 26 | K22: 19 | L22: 20 | M22: 27 | N22: 23 | P22: =handsmoothed!B22^2 -> 36 | Q22: =handsmoothed!C22^2 -> 36 | R22: =handsmoothed!D22^2 -> 36 | S22: =handsmoothed!E22^2 -> 36 | T22: =handsmoothed!F22^2 -> 36 | U22: =handsmoothed!G22^2 -> 36 | V22: =handsmoothed!H22^2 -> 36 | W22: =handsmoothed!I22^2 -> 49 | ... AB22: =handsmoothed!N22^2 -> 100
A23: 21 | B23: . | C23: . | D23: . | E23: . | F23: . | G23: . | H23: . | I23: . | J23: 1 | K23: . | L23: . | M23: 1 | N23: 1 | P23: =handsmoothed!B23^2 -> 36 | Q23: =handsmoothed!C23^2 -> 36 | R23: =handsmoothed!D23^2 -> 36 | S23: =handsmoothed!E23^2 -> 36 | T23: =handsmoothed!F23^2 -> 36 | U23: =handsmoothed!G23^2 -> 36 | V23: =handsmoothed!H23^2 -> 49 | W23: =handsmoothed!I23^2 -> 49 | ... AB23: =handsmoothed!N23^2 -> 121
A24: 22 | B24: . | C24: . | D24: . | E24: . | F24: . | G24: . | H24: . | I24: . | J24: 2 | K24: . | L24: . | M24: . | N24: . | P24: =handsmoothed!B24^2 -> 36 | Q24: =handsmoothed!C24^2 -> 36 | R24: =handsmoothed!D24^2 -> 36 | S24: =handsmoothed!E24^2 -> 36 | T24: =handsmoothed!F24^2 -> 36 | U24: =handsmoothed!G24^2 -> 49 | V24: =handsmoothed!H24^2 -> 49 | W24: =handsmoothed!I24^2 -> 49 | ... AB24: =handsmoothed!N24^2 -> 121
A25: 23 | B25: 1 | C25: . | D25: . | E25: . | F25: . | G25: . | H25: . | I25: 3 | J25: 1 | K25: . | L25: 1 | M25: 3 | N25: 1 | P25: =handsmoothed!B25^2 -> 36 | Q25: =handsmoothed!C25^2 -> 36 | R25: =handsmoothed!D25^2 -> 36 | S25: =handsmoothed!E25^2 -> 36 | T25: =handsmoothed!F25^2 -> 49 | U25: =handsmoothed!G25^2 -> 49 | V25: =handsmoothed!H25^2 -> 49 | W25: =handsmoothed!I25^2 -> 64 | ... AB25: =handsmoothed!N25^2 -> 121
A26: 24 | B26: 21 | C26: 17 | D26: 13 | E26: 10 | F26: 12 | G26: 17 | H26: 18 | I26: 25 | J26: 26 | K26: 26 | L26: 22 | M26: 17 | N26: 12 | P26: =handsmoothed!B26^2 -> 49 | Q26: =handsmoothed!C26^2 -> 49 | R26: =handsmoothed!D26^2 -> 49 | S26: =handsmoothed!E26^2 -> 49 | T26: =handsmoothed!F26^2 -> 49 | U26: =handsmoothed!G26^2 -> 49 | V26: =handsmoothed!H26^2 -> 49 | W26: =handsmoothed!I26^2 -> 64 | ... AB26: =handsmoothed!N26^2 -> 144
A27: 25 | B27: 2 | C27: . | D27: 1 | E27: 3 | F27: 1 | G27: 1 | H27: 2 | I27: 3 | J27: 1 | K27: . | L27: 2 | M27: 1 | N27: 3 | P27: =handsmoothed!B27^2 -> 49 | Q27: =handsmoothed!C27^2 -> 49 | R27: =handsmoothed!D27^2 -> 49 | S27: =handsmoothed!E27^2 -> 49 | T27: =handsmoothed!F27^2 -> 49 | U27: =handsmoothed!G27^2 -> 49 | V27: =handsmoothed!H27^2 -> 64 | W27: =handsmoothed!I27^2 -> 64 | ... AB27: =handsmoothed!N27^2 -> 144
A28: 26 | B28: 1 | C28: 1 | D28: . | E28: 1 | F28: . | G28: 1 | H28: 2 | I28: 1 | J28: 1 | K28: . | L28: 1 | M28: . | N28: . | P28: =handsmoothed!B28^2 -> 49 | Q28: =handsmoothed!C28^2 -> 49 | R28: =handsmoothed!D28^2 -> 49 | S28: =handsmoothed!E28^2 -> 49 | T28: =handsmoothed!F28^2 -> 49 | U28: =handsmoothed!G28^2 -> 64 | V28: =handsmoothed!H28^2 -> 64 | W28: =handsmoothed!I28^2 -> 81 | ... AB28: =handsmoothed!N28^2 -> 144
A29: 27 | B29: 1 | C29: . | D29: . | E29: . | F29: 1 | G29: . | H29: 2 | I29: 1 | J29: . | K29: . | L29: . | M29: . | N29: . | P29: =handsmoothed!B29^2 -> 49 | Q29: =handsmoothed!C29^2 -> 49 | R29: =handsmoothed!D29^2 -> 49 | S29: =handsmoothed!E29^2 -> 49 | T29: =handsmoothed!F29^2 -> 49 | U29: =handsmoothed!G29^2 -> 64 | V29: =handsmoothed!H29^2 -> 64 | W29: =handsmoothed!I29^2 -> 81 | ... AB29: =handsmoothed!N29^2 -> 169
A30: 28 | B30: 9 | C30: 8 | D30: 9 | E30: 13 | F30: 11 | G30: 24 | H30: 13 | I30: 19 | J30: 16 | K30: 9 | L30: 8 | M30: 3 | N30: 6 | P30: =handsmoothed!B30^2 -> 49 | Q30: =handsmoothed!C30^2 -> 49 | R30: =handsmoothed!D30^2 -> 49 | S30: =handsmoothed!E30^2 -> 64 | T30: =handsmoothed!F30^2 -> 64 | U30: =handsmoothed!G30^2 -> 64 | V30: =handsmoothed!H30^2 -> 64 | W30: =handsmoothed!I30^2 -> 81 | ... AB30: =handsmoothed!N30^2 -> 169
A31: 29 | B31: 8 | C31: 6 | D31: 6 | E31: 4 | F31: 10 | G31: 4 | H31: 7 | I31: 9 | J31: 9 | K31: 8 | L31: 1 | M31: . | N31: 7 | P31: =handsmoothed!B31^2 -> 64 | Q31: =handsmoothed!C31^2 -> 64 | R31: =handsmoothed!D31^2 -> 64 | S31: =handsmoothed!E31^2 -> 64 | T31: =handsmoothed!F31^2 -> 64 | U31: =handsmoothed!G31^2 -> 64 | V31: =handsmoothed!H31^2 -> 81 | W31: =handsmoothed!I31^2 -> 81 | ... AB31: =handsmoothed!N31^2 -> 169
A32: 30 | B32: 5 | C32: 6 | D32: 7 | E32: 7 | F32: 6 | G32: 8 | H32: 2 | I32: 5 | J32: 5 | K32: 3 | L32: 1 | M32: 3 | N32: 2 | P32: =handsmoothed!B32^2 -> 64 | Q32: =handsmoothed!C32^2 -> 64 | R32: =handsmoothed!D32^2 -> 64 | S32: =handsmoothed!E32^2 -> 64 | T32: =handsmoothed!F32^2 -> 64 | U32: =handsmoothed!G32^2 -> 81 | V32: =handsmoothed!H32^2 -> 81 | W32: =handsmoothed!I32^2 -> 100 | ... AB32: =handsmoothed!N32^2 -> 196
A33: 31 | B33: . | C33: 1 | D33: . | E33: 2 | F33: 3 | G33: . | H33: 1 | I33: 1 | J33: 1 | K33: . | L33: . | M33: . | N33: . | P33: =handsmoothed!B33^2 -> 64 | Q33: =handsmoothed!C33^2 -> 64 | R33: =handsmoothed!D33^2 -> 64 | S33: =handsmoothed!E33^2 -> 64 | T33: =handsmoothed!F33^2 -> 64 | U33: =handsmoothed!G33^2 -> 81 | V33: =handsmoothed!H33^2 -> 81 | W33: =handsmoothed!I33^2 -> 100 | ... AB33: =handsmoothed!N33^2 -> 196
A34: 32 | B34: 5 | C34: 5 | D34: 6 | E34: 1 | F34: 5 | G34: 9 | H34: 2 | I34: 6 | J34: 8 | K34: 3 | L34: 7 | M34: 4 | N34: 3 | P34: =handsmoothed!B34^2 -> 64 | Q34: =handsmoothed!C34^2 -> 64 | R34: =handsmoothed!D34^2 -> 64 | S34: =handsmoothed!E34^2 -> 81 | T34: =handsmoothed!F34^2 -> 81 | U34: =handsmoothed!G34^2 -> 81 | V34: =handsmoothed!H34^2 -> 100 | W34: =handsmoothed!I34^2 -> 100 | ... AB34: =handsmoothed!N34^2 -> 196
A35: 33 | B35: 4 | C35: 6 | D35: 7 | E35: 4 | F35: 7 | G35: 4 | H35: 1 | I35: 4 | J35: 5 | K35: 5 | L35: 4 | M35: 4 | N35: 2 | P35: =handsmoothed!B35^2 -> 81 | Q35: =handsmoothed!C35^2 -> 81 | R35: =handsmoothed!D35^2 -> 81 | S35: =handsmoothed!E35^2 -> 81 | T35: =handsmoothed!F35^2 -> 81 | U35: =handsmoothed!G35^2 -> 81 | V35: =handsmoothed!H35^2 -> 100 | W35: =handsmoothed!I35^2 -> 100 | ... AB35: =handsmoothed!N35^2 -> 225
A36: 34 | B36: 4 | C36: 2 | D36: 4 | E36: 1 | F36: 7 | G36: 5 | H36: 6 | I36: 5 | J36: 9 | K36: 1 | L36: 2 | M36: . | N36: 3 | P36: =handsmoothed!B36^2 -> 81 | Q36: =handsmoothed!C36^2 -> 81 | R36: =handsmoothed!D36^2 -> 81 | S36: =handsmoothed!E36^2 -> 81 | T36: =handsmoothed!F36^2 -> 81 | U36: =handsmoothed!G36^2 -> 100 | V36: =handsmoothed!H36^2 -> 100 | W36: =handsmoothed!I36^2 -> 121 | ... AB36: =handsmoothed!N36^2 -> 225
A37: 35 | B37: 3 | C37: 4 | D37: 2 | E37: . | F37: 3 | G37: 2 | H37: 3 | I37: 2 | J37: 2 | K37: . | L37: 1 | M37: 1 | N37: . | P37: =handsmoothed!B37^2 -> 81 | Q37: =handsmoothed!C37^2 -> 81 | R37: =handsmoothed!D37^2 -> 81 | S37: =handsmoothed!E37^2 -> 81 | T37: =handsmoothed!F37^2 -> 81 | U37: =handsmoothed!G37^2 -> 100 | V37: =handsmoothed!H37^2 -> 100 | W37: =handsmoothed!I37^2 -> 121 | ... AB37: =handsmoothed!N37^2 -> 225
A38: 36 | B38: 4 | C38: 3 | D38: 2 | E38: 7 | F38: 6 | G38: 3 | H38: 5 | I38: 8 | J38: 4 | K38: . | L38: 4 | M38: . | N38: 3 | P38: =handsmoothed!B38^2 -> 81 | Q38: =handsmoothed!C38^2 -> 81 | R38: =handsmoothed!D38^2 -> 81 | S38: =handsmoothed!E38^2 -> 81 | T38: =handsmoothed!F38^2 -> 100 | U38: =handsmoothed!G38^2 -> 100 | V38: =handsmoothed!H38^2 -> 121 | W38: =handsmoothed!I38^2 -> 121 | ... AB38: =handsmoothed!N38^2 -> 256
A39: 37 | B39: 5 | C39: 5 | D39: 5 | E39: 5 | F39: 5 | G39: 2 | H39: 6 | I39: 1 | J39: 4 | K39: 2 | L39: . | M39: 2 | N39: 1 | P39: =handsmoothed!B39^2 -> 100 | Q39: =handsmoothed!C39^2 -> 100 | R39: =handsmoothed!D39^2 -> 100 | S39: =handsmoothed!E39^2 -> 100 | T39: =handsmoothed!F39^2 -> 100 | U39: =handsmoothed!G39^2 -> 100 | V39: =handsmoothed!H39^2 -> 121 | W39: =handsmoothed!I39^2 -> 144 | ... AB39: =handsmoothed!N39^2 -> 256
A40: 38 | B40: 6 | C40: 2 | D40: 4 | E40: 6 | F40: 10 | G40: 6 | H40: 8 | I40: 6 | J40: 1 | K40: 2 | L40: 2 | M40: 1 | N40: . | P40: =handsmoothed!B40^2 -> 100 | Q40: =handsmoothed!C40^2 -> 100 | R40: =handsmoothed!D40^2 -> 100 | S40: =handsmoothed!E40^2 -> 100 | T40: =handsmoothed!F40^2 -> 100 | U40: =handsmoothed!G40^2 -> 121 | V40: =handsmoothed!H40^2 -> 121 | W40: =handsmoothed!I40^2 -> 144 | ... AB40: =handsmoothed!N40^2 -> 256
...

Sheet checksmooth
B1: g1 | C1: g2 | D1: g3 | E1: g4 | F1: g5 | G1: g6 | H1: g7 | I1: g8 | J1: g9 | K1: g10 | L1: g11 | M1: g12 | N1: g13 | Q1: g1 | R1: g2 | S1: g3 | T1: g4 | U1: g5 | V1: g6 | W1: g7 | X1: g8 | Y1: g9 | Z1: g10 | AA1: g11 | AB1: g12 | AF1: g1 | AG1: g2 | AH1: g3 | AI1: g4 | AJ1: g5 | AK1: g6 | AL1: g7 | AM1: g8 | AN1: g9 | AO1: g10 | AP1: g11 | AQ1: g12 | AR1: g13
A2: 1 | B2: =COUNTIF(handsmoothed!B$2:B$68,$A2) -> 4 | C2: =COUNTIF(handsmoothed!C$2:C$68,$A2) -> 4 | D2: =COUNTIF(handsmoothed!D$2:D$68,$A2) -> 4 | E2: =COUNTIF(handsmoothed!E$2:E$68,$A2) -> 4 | F2: =COUNTIF(handsmoothed!F$2:F$68,$A2) -> 3 | G2: =COUNTIF(handsmoothed!G$2:G$68,$A2) -> 3 | H2: =COUNTIF(handsmoothed!H$2:H$68,$A2) -> 3 | I2: =COUNTIF(handsmoothed!I$2:I$68,$A2) -> 3 | ... N2: =COUNTIF(handsmoothed!N$2:N$68,$A2) -> 2 | P2: 1 | Q2: =B2-C2 -> 0 | R2: =C2-D2 -> 0 | S2: =D2-E2 -> 0 | T2: =E2-F2 -> 1 | U2: =F2-G2 -> 0 | V2: =G2-H2 -> 0 | W2: =H2-I2 -> 0 | X2: =I2-J2 -> 0 | ... AB2: =M2-N2 -> 1 | AE2: 1 | AF2: =B3-B2 -> 0 | AG2: =C3-C2 -> 0 | AH2: =D3-D2 -> 0 | AI2: =E3-E2 -> 0 | AJ2: =F3-F2 -> 1 | AK2: =G3-G2 -> 1 | AL2: =H3-H2 -> 1 | AM2: =I3-I2 -> 0 | ... AR2: =N3-N2 -> 0
A3: 2 | B3: =COUNTIF(handsmoothed!B$2:B$68,$A3) -> 4 | C3: =COUNTIF(handsmoothed!C$2:C$68,$A3) -> 4 | D3: =COUNTIF(handsmoothed!D$2:D$68,$A3) -> 4 | E3: =COUNTIF(handsmoothed!E$2:E$68,$A3) -> 4 | F3: =COUNTIF(handsmoothed!F$2:F$68,$A3) -> 4 | G3: =COUNTIF(handsmoothed!G$2:G$68,$A3) -> 4 | H3: =COUNTIF(handsmoothed!H$2:H$68,$A3) -> 4 | I3: =COUNTIF(handsmoothed!I$2:I$68,$A3) -> 3 | ... N3: =COUNTIF(handsmoothed!N$2:N$68,$A3) -> 2 | P3: 2 | Q3: =B3-C3 -> 0 | R3: =C3-D3 -> 0 | S3: =D3-E3 -> 0 | T3: =E3-F3 -> 0 | U3: =F3-G3 -> 0 | V3: =G3-H3 -> 0 | W3: =H3-I3 -> 1 | X3: =I3-J3 -> 0 | ... AB3: =M3-N3 -> 0 | AE3: 2 | AF3: =B4-B3 -> 0 | AG3: =C4-C3 -> 0 | AH3: =D4-D3 -> 0 | AI3: =E4-E3 -> -1 | AJ3: =F4-F3 -> 0 | AK3: =G4-G3 -> 0 | AL3: =H4-H3 -> 0 | AM3: =I4-I3 -> 1 | ... AR3: =N4-N3 -> 0
A4: 3 | B4: =COUNTIF(handsmoothed!B$2:B$68,$A4) -> 4 | C4: =COUNTIF(handsmoothed!C$2:C$68,$A4) -> 4 | D4: =COUNTIF(handsmoothed!D$2:D$68,$A4) -> 4 | E4: =COUNTIF(handsmoothed!E$2:E$68,$A4) -> 3 | F4: =COUNTIF(handsmoothed!F$2:F$68,$A4) -> 4 | G4: =COUNTIF(handsmoothed!G$2:G$68,$A4) -> 4 | H4: =COUNTIF(handsmoothed!H$2:H$68,$A4) -> 4 | I4: =COUNTIF(handsmoothed!I$2:I$68,$A4) -> 4 | ... N4: =COUNTIF(handsmoothed!N$2:N$68,$A4) -> 2 | P4: 3 | Q4: =B4-C4 -> 0 | R4: =C4-D4 -> 0 | S4: =D4-E4 -> 1 | T4: =E4-F4 -> -1 | U4: =F4-G4 -> 0 | V4: =G4-H4 -> 0 | W4: =H4-I4 -> 0 | X4: =I4-J4 -> 1 | ... AB4: =M4-N4 -> 0 | AE4: 3 | AF4: =B5-B4 -> -1 | AG4: =C5-C4 -> -1 | AH4: =D5-D4 -> -1 | AI4: =E5-E4 -> 1 | AJ4: =F5-F4 -> 0 | AK4: =G5-G4 -> -1 | AL4: =H5-H4 -> -1 | AM4: =I5-I4 -> -1 | ... AR4: =N5-N4 -> 0
A5: 4 | B5: =COUNTIF(handsmoothed!B$2:B$68,$A5) -> 3 | C5: =COUNTIF(handsmoothed!C$2:C$68,$A5) -> 3 | D5: =COUNTIF(handsmoothed!D$2:D$68,$A5) -> 3 | E5: =COUNTIF(handsmoothed!E$2:E$68,$A5) -> 4 | F5: =COUNTIF(handsmoothed!F$2:F$68,$A5) -> 4 | G5: =COUNTIF(handsmoothed!G$2:G$68,$A5) -> 3 | H5: =COUNTIF(handsmoothed!H$2:H$68,$A5) -> 3 | I5: =COUNTIF(handsmoothed!I$2:I$68,$A5) -> 3 | ... N5: =COUNTIF(handsmoothed!N$2:N$68,$A5) -> 2 | P5: 4 | Q5: =B5-C5 -> 0 | R5: =C5-D5 -> 0 | S5: =D5-E5 -> -1 | T5: =E5-F5 -> 0 | U5: =F5-G5 -> 1 | V5: =G5-H5 -> 0 | W5: =H5-I5 -> 0 | X5: =I5-J5 -> 0 | ... AB5: =M5-N5 -> 0 | AE5: 4 | AF5: =B6-B5 -> 1 | AG5: =C6-C5 -> 1 | AH5: =D6-D5 -> 1 | AI5: =E6-E5 -> 0 | AJ5: =F6-F5 -> 0 | AK5: =G6-G5 -> 1 | AL5: =H6-H5 -> 1 | AM5: =I6-I5 -> 0 | ... AR5: =N6-N5 -> 0
A6: 5 | B6: =COUNTIF(handsmoothed!B$2:B$68,$A6) -> 4 | C6: =COUNTIF(handsmoothed!C$2:C$68,$A6) -> 4 | D6: =COUNTIF(handsmoothed!D$2:D$68,$A6) -> 4 | E6: =COUNTIF(handsmoothed!E$2:E$68,$A6) -> 4 | F6: =COUNTIF(handsmoothed!F$2:F$68,$A6) -> 4 | G6: =COUNTIF(handsmoothed!G$2:G$68,$A6) -> 4 | H6: =COUNTIF(handsmoothed!H$2:H$68,$A6) -> 4 | I6: =COUNTIF(handsmoothed!I$2:I$68,$A6) -> 3 | ... N6: =COUNTIF(handsmoothed!N$2:N$68,$A6) -> 2 | P6: 5 | Q6: =B6-C6 -> 0 | R6: =C6-D6 -> 0 | S6: =D6-E6 -> 0 | T6: =E6-F6 -> 0 | U6: =F6-G6 -> 0 | V6: =G6-H6 -> 0 | W6: =H6-I6 -> 1 | X6: =I6-J6 -> 0 | ... AB6: =M6-N6 -> 0 | AE6: 5 | AF6: =B7-B6 -> 1 | AG6: =C7-C6 -> 1 | AH6: =D7-D6 -> 1 | AI6: =E7-E6 -> 1 | AJ6: =F7-F6 -> 0 | AK6: =G7-G6 -> 0 | AL6: =H7-H6 -> -1 | AM6: =I7-I6 -> 0 | ... AR6: =N7-N6 -> 0
A7: 6 | B7: =COUNTIF(handsmoothed!B$2:B$68,$A7) -> 5 | C7: =COUNTIF(handsmoothed!C$2:C$68,$A7) -> 5 | D7: =COUNTIF(handsmoothed!D$2:D$68,$A7) -> 5 | E7: =COUNTIF(handsmoothed!E$2:E$68,$A7) -> 5 | F7: =COUNTIF(handsmoothed!F$2:F$68,$A7) -> 4 | G7: =COUNTIF(handsmoothed!G$2:G$68,$A7) -> 4 | H7: =COUNTIF(handsmoothed!H$2:H$68,$A7) -> 3 | I7: =COUNTIF(handsmoothed!I$2:I$68,$A7) -> 3 | ... N7: =COUNTIF(handsmoothed!N$2:N$68,$A7) -> 2 | P7: 6 | Q7: =B7-C7 -> 0 | R7: =C7-D7 -> 0 | S7: =D7-E7 -> 0 | T7: =E7-F7 -> 1 | U7: =F7-G7 -> 0 | V7: =G7-H7 -> 1 | W7: =H7-I7 -> 0 | X7: =I7-J7 -> 0 | ... AB7: =M7-N7 -> 1 | AE7: 6 | AF7: =B8-B7 -> 0 | AG7: =C8-C7 -> 0 | AH7: =D8-D7 -> 0 | AI7: =E8-E7 -> -1 | AJ7: =F8-F7 -> 1 | AK7: =G8-G7 -> 0 | AL7: =H8-H7 -> 1 | AM7: =I8-I7 -> 1 | ... AR7: =N8-N7 -> 0
A8: 7 | B8: =COUNTIF(handsmoothed!B$2:B$68,$A8) -> 5 | C8: =COUNTIF(handsmoothed!C$2:C$68,$A8) -> 5 | D8: =COUNTIF(handsmoothed!D$2:D$68,$A8) -> 5 | E8: =COUNTIF(handsmoothed!E$2:E$68,$A8) -> 4 | F8: =COUNTIF(handsmoothed!F$2:F$68,$A8) -> 5 | G8: =COUNTIF(handsmoothed!G$2:G$68,$A8) -> 4 | H8: =COUNTIF(handsmoothed!H$2:H$68,$A8) -> 4 | I8: =COUNTIF(handsmoothed!I$2:I$68,$A8) -> 4 | ... N8: =COUNTIF(handsmoothed!N$2:N$68,$A8) -> 2 | P8: 7 | Q8: =B8-C8 -> 0 | R8: =C8-D8 -> 0 | S8: =D8-E8 -> 1 | T8: =E8-F8 -> -1 | U8: =F8-G8 -> 1 | V8: =G8-H8 -> 0 | W8: =H8-I8 -> 0 | X8: =I8-J8 -> 1 | ... AB8: =M8-N8 -> 1 | AE8: 7 | AF8: =B9-B8 -> -1 | AG8: =C9-C8 -> -1 | AH8: =D9-D8 -> -1 | AI8: =E9-E8 -> 0 | AJ8: =F9-F8 -> -1 | AK8: =G9-G8 -> 0 | AL8: =H9-H8 -> 0 | AM8: =I9-I8 -> -1 | ... AR8: =N9-N8 -> 1
A9: 8 | B9: =COUNTIF(handsmoothed!B$2:B$68,$A9) -> 4 | C9: =COUNTIF(handsmoothed!C$2:C$68,$A9) -> 4 | D9: =COUNTIF(handsmoothed!D$2:D$68,$A9) -> 4 | E9: =COUNTIF(handsmoothed!E$2:E$68,$A9) -> 4 | F9: =COUNTIF(handsmoothed!F$2:F$68,$A9) -> 4 | G9: =COUNTIF(handsmoothed!G$2:G$68,$A9) -> 4 | H9: =COUNTIF(handsmoothed!H$2:H$68,$A9) -> 4 | I9: =COUNTIF(handsmoothed!I$2:I$68,$A9) -> 3 | ... N9: =COUNTIF(handsmoothed!N$2:N$68,$A9) -> 3 | P9: 8 | Q9: =B9-C9 -> 0 | R9: =C9-D9 -> 0 | S9: =D9-E9 -> 0 | T9: =E9-F9 -> 0 | U9: =F9-G9 -> 0 | V9: =G9-H9 -> 0 | W9: =H9-I9 -> 1 | X9: =I9-J9 -> 0 | ... AB9: =M9-N9 -> -1 | AE9: 8 | AF9: =B10-B9 -> 0 | AG9: =C10-C9 -> 0 | AH9: =D10-D9 -> 0 | AI9: =E10-E9 -> 1 | AJ9: =F10-F9 -> 0 | AK9: =G10-G9 -> 0 | AL9: =H10-H9 -> -1 | AM9: =I10-I9 -> 1 | ... AR9: =N10-N9 -> -1
A10: 9 | B10: =COUNTIF(handsmoothed!B$2:B$68,$A10) -> 4 | C10: =COUNTIF(handsmoothed!C$2:C$68,$A10) -> 4 | D10: =COUNTIF(handsmoothed!D$2:D$68,$A10) -> 4 | E10: =COUNTIF(handsmoothed!E$2:E$68,$A10) -> 5 | F10: =COUNTIF(handsmoothed!F$2:F$68,$A10) -> 4 | G10: =COUNTIF(handsmoothed!G$2:G$68,$A10) -> 4 | H10: =COUNTIF(handsmoothed!H$2:H$68,$A10) -> 3 | I10: =COUNTIF(handsmoothed!I$2:I$68,$A10) -> 4 | ... N10: =COUNTIF(handsmoothed!N$2:N$68,$A10) -> 2 | P10: 9 | Q10: =B10-C10 -> 0 | R10: =C10-D10 -> 0 | S10: =D10-E10 -> -1 | T10: =E10-F10 -> 1 | U10: =F10-G10 -> 0 | V10: =G10-H10 -> 1 | W10: =H10-I10 -> -1 | X10: =I10-J10 -> 1 | ... AB10: =M10-N10 -> 0 | AE10: 9 | AF10: =B11-B10 -> 1 | AG10: =C11-C10 -> 1 | AH10: =D11-D10 -> 0 | AI10: =E11-E10 -> -1 | AJ10: =F11-F10 -> 0 | AK10: =G11-G10 -> 0 | AL10: =H11-H10 -> 1 | AM10: =I11-I10 -> 0 | ... AR10: =N11-N10 -> 0
A11: 10 | B11: =COUNTIF(handsmoothed!B$2:B$68,$A11) -> 5 | C11: =COUNTIF(handsmoothed!C$2:C$68,$A11) -> 5 | D11: =COUNTIF(handsmoothed!D$2:D$68,$A11) -> 4 | E11: =COUNTIF(handsmoothed!E$2:E$68,$A11) -> 4 | F11: =COUNTIF(handsmoothed!F$2:F$68,$A11) -> 4 | G11: =COUNTIF(handsmoothed!G$2:G$68,$A11) -> 4 | H11: =COUNTIF(handsmoothed!H$2:H$68,$A11) -> 4 | I11: =COUNTIF(handsmoothed!I$2:I$68,$A11) -> 4 | ... N11: =COUNTIF(handsmoothed!N$2:N$68,$A11) -> 2 | P11: 10 | Q11: =B11-C11 -> 0 | R11: =C11-D11 -> 1 | S11: =D11-E11 -> 0 | T11: =E11-F11 -> 0 | U11: =F11-G11 -> 0 | V11: =G11-H11 -> 0 | W11: =H11-I11 -> 0 | X11: =I11-J11 -> 0 | ... AB11: =M11-N11 -> 1 | AE11: 10 | AF11: =B12-B11 -> -1 | AG11: =C12-C11 -> -1 | AH11: =D12-D11 -> 0 | AI11: =E12-E11 -> 0 | AJ11: =F12-F11 -> 0 | AK11: =G12-G11 -> 0 | AL11: =H12-H11 -> 0 | AM11: =I12-I11 -> -1 | ... AR11: =N12-N11 -> 1
A12: 11 | B12: =COUNTIF(handsmoothed!B$2:B$68,$A12) -> 4 | C12: =COUNTIF(handsmoothed!C$2:C$68,$A12) -> 4 | D12: =COUNTIF(handsmoothed!D$2:D$68,$A12) -> 4 | E12: =COUNTIF(handsmoothed!E$2:E$68,$A12) -> 4 | F12: =COUNTIF(handsmoothed!F$2:F$68,$A12) -> 4 | G12: =COUNTIF(handsmoothed!G$2:G$68,$A12) -> 4 | H12: =COUNTIF(handsmoothed!H$2:H$68,$A12) -> 4 | I12: =COUNTIF(handsmoothed!I$2:I$68,$A12) -> 3 | ... N12: =COUNTIF(handsmoothed!N$2:N$68,$A12) -> 3 | P12: 11 | Q12: =B12-C12 -> 0 | R12: =C12-D12 -> 0 | S12: =D12-E12 -> 0 | T12: =E12-F12 -> 0 | U12: =F12-G12 -> 0 | V12: =G12-H12 -> 0 | W12: =H12-I12 -> 1 | X12: =I12-J12 -> 0 | ... AB12: =M12-N12 -> 0 | AE12: 11 | AF12: =B13-B12 -> 0 | AG12: =C13-C12 -> 0 | AH12: =D13-D12 -> 1 | AI12: =E13-E12 -> 0 | AJ12: =F13-F12 -> 0 | AK12: =G13-G12 -> 0 | AL12: =H13-H12 -> 1 | AM12: =I13-I12 -> 1 | ... AR12: =N13-N12 -> 0
A13: 12 | B13: =COUNTIF(handsmoothed!B$2:B$68,$A13) -> 4 | C13: =COUNTIF(handsmoothed!C$2:C$68,$A13) -> 4 | D13: =COUNTIF(handsmoothed!D$2:D$68,$A13) -> 5 | E13: =COUNTIF(handsmoothed!E$2:E$68,$A13) -> 4 | F13: =COUNTIF(handsmoothed!F$2:F$68,$A13) -> 4 | G13: =COUNTIF(handsmoothed!G$2:G$68,$A13) -> 4 | H13: =COUNTIF(handsmoothed!H$2:H$68,$A13) -> 5 | I13: =COUNTIF(handsmoothed!I$2:I$68,$A13) -> 4 | ... N13: =COUNTIF(handsmoothed!N$2:N$68,$A13) -> 3 | P13: 12 | Q13: =B13-C13 -> 0 | R13: =C13-D13 -> -1 | S13: =D13-E13 -> 1 | T13: =E13-F13 -> 0 | U13: =F13-G13 -> 0 | V13: =G13-H13 -> -1 | W13: =H13-I13 -> 1 | X13: =I13-J13 -> 0 | ... AB13: =M13-N13 -> 0 | AE13: 12 | AF13: =B14-B13 -> 0 | AG13: =C14-C13 -> 0 | AH13: =D14-D13 -> -1 | AI13: =E14-E13 -> 0 | AJ13: =F14-F13 -> 0 | AK13: =G14-G13 -> 0 | AL13: =H14-H13 -> -1 | AM13: =I14-I13 -> 0 | ... AR13: =N14-N13 -> 0
... A19: 18 | B19: =COUNTIF(handsmoothed!B$2:B$68,$A19) -> 1 | C19: =COUNTIF(handsmoothed!C$2:C$68,$A19) -> 1 | D19: =COUNTIF(handsmoothed!D$2:D$68,$A19) -> 1 | E19: =COUNTIF(handsmoothed!E$2:E$68,$A19) -> 1 | F19: =COUNTIF(handsmoothed!F$2:F$68,$A19) -> 1 | G19: =COUNTIF(handsmoothed!G$2:G$68,$A19) -> 2 | H19: =COUNTIF(handsmoothed!H$2:H$68,$A19) -> 2 | I19: =COUNTIF(handsmoothed!I$2:I$68,$A19) -> 3 | ... N19: =COUNTIF(handsmoothed!N$2:N$68,$A19) -> 3 | P19: 18 | Q19: =B19-C19 -> 0 | R19: =C19-D19 -> 0 | S19: =D19-E19 -> 0 | T19: =E19-F19 -> 0 | U19: =F19-G19 -> -1 | V19: =G19-H19 -> 0 | W19: =H19-I19 -> -1 | X19: =I19-J19 -> -1 | ... AB19: =M19-N19 -> 1 | AE19: 18 | AF19: =B20-B19 -> 0 | AG19: =C20-C19 -> 0 | AH19: =D20-D19 -> 0 | AI19: =E20-E19 -> 0 | AJ19: =F20-F19 -> 0 | AK19: =G20-G19 -> 0 | AL19: =H20-H19 -> 0 | AM19: =I20-I19 -> 1 | ... AR19: =N20-N19 -> 18
A20: 19 | B20: =COUNTIF(handsmoothed!B$2:B$68,$A20) -> 1 | C20: =COUNTIF(handsmoothed!C$2:C$68,$A20) -> 1 | D20: =COUNTIF(handsmoothed!D$2:D$68,$A20) -> 1 | E20: =COUNTIF(handsmoothed!E$2:E$68,$A20) -> 1 | F20: =COUNTIF(handsmoothed!F$2:F$68,$A20) -> 1 | G20: =COUNTIF(handsmoothed!G$2:G$68,$A20) -> 2 | H20: =COUNTIF(handsmoothed!H$2:H$68,$A20) -> 2 | I20: =COUNTIF(handsmoothed!I$2:I$68,$A20) -> 4 | ... N20: =COUNTIF(handsmoothed!N$2:N$68,$A20) -> 21 | P20: 19 | Q20: =B20-C20 -> 0 | R20: =C20-D20 -> 0 | S20: =D20-E20 -> 0 | T20: =E20-F20 -> 0 | U20: =F20-G20 -> -1 | V20: =G20-H20 -> 0 | W20: =H20-I20 -> -2 | X20: =I20-J20 -> -3 | ... AB20: =M20-N20 -> -4

Sheet QA
A1: Analysis Variable : wais5_bd_ss
A2: N | B2: Mean | C2: Std Dev | D2: Minimum | E2: Maximum | I2: 10 | J2: 3
A3: 2020 | B3: 10.000495 | C3: 3.0156435 | D3: 1 | E3: 19 | I3: =B3-I$2 -> 0.000495 | J3: =C3-J$2 -> 0.0156435
B4: =ROUND(B3,1) -> 10 | C4: =ROUND(C3,1) -> 3
A8: Analysis Variable : wais5_bd_ss
A9: agegrp | B9: N Obs | C9: N | D9: Mean | E9: Std Dev | F9: Minimum | G9: Maximum
A10: 1 | B10: 180 | C10: 180 | D10: 9.6888889 | E10: 2.9126748 | F10: 1 | G10: 16 | I10: =D10-I$2 -> -0.3111111 | J10: =E10-J$2 -> -0.0873252
A11: 2 | B11: 180 | C11: 180 | D11: 9.8777778 | E11: 3.0077285 | F11: 2 | G11: 18 | I11: =D11-I$2 -> -0.1222222 | J11: =E11-J$2 -> 0.0077285
A12: 3 | B12: 180 | C12: 180 | D12: 10.433333 | E12: 2.9749419 | F12: 2 | G12: 17 | I12: =D12-I$2 -> 0.4333333 | J12: =E12-J$2 -> -0.0250581
A13: 4 | B13: 180 | C13: 180 | D13: 10.255556 | E13: 3.0710801 | F13: 1 | G13: 17 | I13: =D13-I$2 -> 0.2555556 | J13: =E13-J$2 -> 0.0710801
A14: 5 | B14: 180 | C14: 180 | D14: 10.166667 | E14: 2.8705789 | F14: 2 | G14: 17 | I14: =D14-I$2 -> 0.1666667 | J14: =E14-J$2 -> -0.1294211
A15: 6 | B15: 180 | C15: 180 | D15: 9.9388889 | E15: 3.1377391 | F15: 2 | G15: 17 | I15: =D15-I$2 -> -0.0611111 | J15: =E15-J$2 -> 0.1377391
A16: 7 | B16: 180 | C16: 180 | D16: 10.244444 | E16: 3.0901216 | F16: 3 | G16: 17 | I16: =D16-I$2 -> 0.2444444 | J16: =E16-J$2 -> 0.0901216
A17: 8 | B17: 180 | C17: 180 | D17: 9.5777778 | E17: 3.0543596 | F17: 1 | G17: 19 | I17: =D17-I$2 -> -0.4222222 | J17: =E17-J$2 -> 0.0543596
A18: 9 | B18: 180 | C18: 180 | D18: 9.7888889 | E18: 2.9915876 | F18: 2 | G18: 17 | I18: =D18-I$2 -> -0.2111111 | J18: =E18-J$2 -> -0.0084124
A19: 10 | B19: 100 | C19: 100 | D19: 9.87 | E19: 2.7657903 | F19: 3 | G19: 17 | I19: =D19-I$2 -> -0.13 | J19: =E19-J$2 -> -0.2342097
A20: 11 | B20: 100 | C20: 100 | D20: 10.04 | E20: 2.8530331 | F20: 1 | G20: 17 | I20: =D20-I$2 -> 0.04 | J20: =E20-J$2 -> -0.1469669
A21: 12 | B21: 100 | C21: 100 | D21: 9.77 | E21: 3.0677699 | F21: 3 | G21: 19 | I21: =D21-I$2 -> -0.23 | J21: =E21-J$2 -> 0.0677699
A22: 13 | B22: 100 | C22: 100 | D22: 10.38 | E22: 3.3235614 | F22: 2 | G22: 17 | I22: =D22-I$2 -> 0.38 | J22: =E22-J$2 -> 0.3235614
A27: WAIS5 US norm (bd)
I28: 4 | J28: 7 | K28: 10 | L28: 13 | M28: 16
A29: Obs | B29: P_02 | C29: P_16 | D29: P_50 | E29: P_84 | F29: P_98
A30: 1 | B30: 4 | C30: 7 | D30: 10 | E30: 13 | F30: 16 | I30: =B30-I$28 -> 0 | J30: =C30-J$28 -> 0 | K30: =D30-K$28 -> 0 | L30: =E30-L$28 -> 0 | M30: =F30-M$28 -> 0
A35: WAIS5 US norm (bd)
A37: Obs | B37: agegrp | C37: P_02 | D37: P_16 | E37: P_50 | F37: P_84 | G37: P_98
A38: 1 | B38: 1 | C38: 4 | D38: 7 | E38: 10 | F38: 13 | G38: 15 | I38: =C38-I$28 -> 0 | J38: =D38-J$28 -> 0 | K38: =E38-K$28 -> 0 | L38: =F38-L$28 -> 0 | M38: =G38-M$28 -> -1
A39: 2 | B39: 2 | C39: 4 | D39: 7 | E39: 10 | F39: 13 | G39: 16 | I39: =C39-I$28 -> 0 | J39: =D39-J$28 -> 0 | K39: =E39-K$28 -> 0 | L39: =F39-L$28 -> 0 | M39: =G39-M$28 -> 0
A40: 3 | B40: 3 | C40: 5 | D40: 7 | E40: 10 | F40: 14 | G40: 16 | I40: =C40-I$28 -> 1 | J40: =D40-J$28 -> 0 | K40: =E40-K$28 -> 0 | L40: =F40-L$28 -> 1 | M40: =G40-M$28 -> 0
A41: 4 | B41: 4 | C41: 4 | D41: 7 | E41: 10.5 | F41: 13 | G41: 16 | I41: =C41-I$28 -> 0 | J41: =D41-J$28 -> 0 | K41: =E41-K$28 -> 0.5 | L41: =F41-L$28 -> 0 | M41: =G41-M$28 -> 0
A42: 5 | B42: 5 | C42: 4 | D42: 8 | E42: 10 | F42: 13 | G42: 16 | I42: =C42-I$28 -> 0 | J42: =D42-J$28 -> 1 | K42: =E42-K$28 -> 0 | L42: =F42-L$28 -> 0 | M42: =G42-M$28 -> 0
A43: 6 | B43: 6 | C43: 4 | D43: 7 | E43: 9 | F43: 14 | G43: 16 | I43: =C43-I$28 -> 0 | J43: =D43-J$28 -> 0 | K43: =E43-K$28 -> -1 | L43: =F43-L$28 -> 1 | M43: =G43-M$28 -> 0
A44: 7 | B44: 7 | C44: 4 | D44: 7 | E44: 11 | F44: 14 | G44: 15 | I44: =C44-I$28 -> 0 | J44: =D44-J$28 -> 0 | K44: =E44-K$28 -> 1 | L44: =F44-L$28 -> 1 | M44: =G44-M$28 -> -1
A45: 8 | B45: 8 | C45: 2 | D45: 7 | E45: 9 | F45: 13 | G45: 16 | I45: =C45-I$28 -> -2 | J45: =D45-J$28 -> 0 | K45: =E45-K$28 -> -1 | L45: =F45-L$28 -> 0 | M45: =G45-M$28 -> 0
A46: 9 | B46: 9 | C46: 4 | D46: 7 | E46: 10 | F46: 13 | G46: 16 | I46: =C46-I$28 -> 0 | J46: =D46-J$28 -> 0 | K46: =E46-K$28 -> 0 | L46: =F46-L$28 -> 0 | M46: =G46-M$28 -> 0
A47: 10 | B47: 10 | C47: 4 | D47: 8 | E47: 9 | F47: 12.5 | G47: 16 | I47: =C47-I$28 -> 0 | J47: =D47-J$28 -> 1 | K47: =E47-K$28 -> -1 | L47: =F47-L$28 -> -0.5 | M47: =G47-M$28 -> 0
A48: 11 | B48: 11 | C48: 4.5 | D48: 7.5 | E48: 10 | F48: 13 | G48: 16 | I48: =C48-I$28 -> 0.5 | J48: =D48-J$28 -> 0.5 | K48: =E48-K$28 -> 0 | L48: =F48-L$28 -> 0 | M48: =G48-M$28 -> 0
A49: 12 | B49: 12 | C49: 4 | D49: 7 | E49: 9 | F49: 13 | G49: 17.5 | I49: =C49-I$28 -> 0 | J49: =D49-J$28 -> 0 | K49: =E49-K$28 -> -1 | L49: =F49-L$28 -> 0 | M49: =G49-M$28 -> 1.5
A50: 13 | B50: 13 | C50: 3 | D50: 7 | E50: 10 | F50: 13 | G50: 16 | I50: =C50-I$28 -> -1 | J50: =D50-J$28 -> 0 | K50: =E50-K$28 -> 0 | L50: =F50-L$28 -> 0 | M50: =G50-M$28 -> 0

Sheet out
A1: wais5_bd_raw | B1: ss1 | C1: ss2 | D1: ss3 | E1: ss4 | F1: ss5 | G1: ss6 | H1: ss7 | I1: ss8 | J1: ss9 | K1: ss10 | L1: ss11 | M1: ss12 | N1: ss13
A2: =handsmoothed!A2 -> 0 | B2: =handsmoothed!B2 -> 1 | C2: =handsmoothed!C2 -> 1 | D2: =handsmoothed!D2 -> 1 | E2: =handsmoothed!E2 -> 1 | F2: =handsmoothed!F2 -> 1 | G2: =handsmoothed!G2 -> 1 | H2: =handsmoothed!H2 -> 1 | ... N2: =handsmoothed!N2 -> 1
A3: =handsmoothed!A3 -> 1 | B3: =handsmoothed!B3 -> 1 | C3: =handsmoothed!C3 -> 1 | D3: =handsmoothed!D3 -> 1 | E3: =handsmoothed!E3 -> 1 | F3: =handsmoothed!F3 -> 1 | G3: =handsmoothed!G3 -> 1 | H3: =handsmoothed!H3 -> 1 | ... N3: =handsmoothed!N3 -> 1
A4: =handsmoothed!A4 -> 2 | B4: =handsmoothed!B4 -> 1 | C4: =handsmoothed!C4 -> 1 | D4: =handsmoothed!D4 -> 1 | E4: =handsmoothed!E4 -> 1 | F4: =handsmoothed!F4 -> 1 | G4: =handsmoothed!G4 -> 1 | H4: =handsmoothed!H4 -> 1 | ... N4: =handsmoothed!N4 -> 2
A5: =handsmoothed!A5 -> 3 | B5: =handsmoothed!B5 -> 1 | C5: =handsmoothed!C5 -> 1 | D5: =handsmoothed!D5 -> 1 | E5: =handsmoothed!E5 -> 1 | F5: =handsmoothed!F5 -> 2 | G5: =handsmoothed!G5 -> 2 | H5: =handsmoothed!H5 -> 2 | ... N5: =handsmoothed!N5 -> 2
A6: =handsmoothed!A6 -> 4 | B6: =handsmoothed!B6 -> 2 | C6: =handsmoothed!C6 -> 2 | D6: =handsmoothed!D6 -> 2 | E6: =handsmoothed!E6 -> 2 | F6: =handsmoothed!F6 -> 2 | G6: =handsmoothed!G6 -> 2 | H6: =handsmoothed!H6 -> 2 | ... N6: =handsmoothed!N6 -> 3
A7: =handsmoothed!A7 -> 5 | B7: =handsmoothed!B7 -> 2 | C7: =handsmoothed!C7 -> 2 | D7: =handsmoothed!D7 -> 2 | E7: =handsmoothed!E7 -> 2 | F7: =handsmoothed!F7 -> 2 | G7: =handsmoothed!G7 -> 2 | H7: =handsmoothed!H7 -> 2 | ... N7: =handsmoothed!N7 -> 3
A8: =handsmoothed!A8 -> 6 | B8: =handsmoothed!B8 -> 2 | C8: =handsmoothed!C8 -> 2 | D8: =handsmoothed!D8 -> 2 | E8: =handsmoothed!E8 -> 2 | F8: =handsmoothed!F8 -> 2 | G8: =handsmoothed!G8 -> 2 | H8: =handsmoothed!H8 -> 2 | ... N8: =handsmoothed!N8 -> 4
A9: =handsmoothed!A9 -> 7 | B9: =handsmoothed!B9 -> 2 | C9: =handsmoothed!C9 -> 2 | D9: =handsmoothed!D9 -> 2 | E9: =handsmoothed!E9 -> 2 | F9: =handsmoothed!F9 -> 3 | G9: =handsmoothed!G9 -> 3 | H9: =handsmoothed!H9 -> 3 | ... N9: =handsmoothed!N9 -> 4
A10: =handsmoothed!A10 -> 8 | B10: =handsmoothed!B10 -> 3 | C10: =handsmoothed!C10 -> 3 | D10: =handsmoothed!D10 -> 3 | E10: =handsmoothed!E10 -> 3 | F10: =handsmoothed!F10 -> 3 | G10: =handsmoothed!G10 -> 3 | H10: =handsmoothed!H10 -> 3 | ... N10: =handsmoothed!N10 -> 5
A11: =handsmoothed!A11 -> 9 | B11: =handsmoothed!B11 -> 3 | C11: =handsmoothed!C11 -> 3 | D11: =handsmoothed!D11 -> 3 | E11: =handsmoothed!E11 -> 3 | F11: =handsmoothed!F11 -> 3 | G11: =handsmoothed!G11 -> 3 | H11: =handsmoothed!H11 -> 3 | ... N11: =handsmoothed!N11 -> 5
A12: =handsmoothed!A12 -> 10 | B12: =handsmoothed!B12 -> 3 | C12: =handsmoothed!C12 -> 3 | D12: =handsmoothed!D12 -> 3 | E12: =handsmoothed!E12 -> 3 | F12: =handsmoothed!F12 -> 3 | G12: =handsmoothed!G12 -> 3 | H12: =handsmoothed!H12 -> 3 | ... N12: =handsmoothed!N12 -> 6
A13: =handsmoothed!A13 -> 11 | B13: =handsmoothed!B13 -> 3 | C13: =handsmoothed!C13 -> 3 | D13: =handsmoothed!D13 -> 3 | E13: =handsmoothed!E13 -> 4 | F13: =handsmoothed!F13 -> 4 | G13: =handsmoothed!G13 -> 4 | H13: =handsmoothed!H13 -> 4 | ... N13: =handsmoothed!N13 -> 6
... A68: =handsmoothed!A68 -> 66 | B68: =handsmoothed!B68 -> 19 | C68: =handsmoothed!C68 -> 19 | D68: =handsmoothed!D68 -> 19 | E68: =handsmoothed!E68 -> 19 | F68: =handsmoothed!F68 -> 19 | G68: =handsmoothed!G68 -> 19 | H68: =handsmoothed!H68 -> 19 | ... N68: =handsmoothed!N68 -> 19
