Workbook
Name Balance: OFFSET(#REF!,0,0,NumMonths,1)
Name Balance1: OFFSET(#REF!,0,0,NumMonths,1)
Name balance1skew: OFFSET(#REF!,0,0,NumMonths,1)
Name balance1skewx: OFFSET(#REF!,0,0,nummonthskew,1)
Name BalanceCan: OFFSET(#REF!,0,0,NumMonths,1)
Name balancesd: OFFSET(#REF!,0,0,nummonthssd,1)
Name balancesd1: OFFSET(#REF!,0,0,nummonthssd,1)
Name balanceskew: OFFSET(#REF!,0,0,NumMonths,1)
Name balanceskewx: OFFSET(#REF!,0,0,nummonthskew,1)
Name can: OFFSET(#REF!,#REF!,0)
Name IDX: QA!$A$2
Name Months: OFFSET(#REF!,0,0,NumMonths,1)
Name MonthsCan: OFFSET(#REF!,0,0,NumMonths,1)
Name monthssd: OFFSET(#REF!,0,0,nummonthssd,1)
Name monthsskew: OFFSET(#REF!,0,0,NumMonths,1)
Name monthsskewx: OFFSET(#REF!,0,0,nummonthskew,1)
Name NumMonths: #REF!
Name nummonthskew: #REF!
Name nummonthssd: #REF!
Name test: OFFSET(#REF!,#REF!,0)
Name test1: OFFSET(#REF!,0,0)
Name test1sd: OFFSET(#REF!,0,0)
Name test1skew: OFFSET(#REF!,0,0)
Name testsd: OFFSET(#REF!,#REF!,0)
Name testskewx: OFFSET(#REF!,#REF!,0)

Sheet control
A1: Observed and Predicted mean for mrtot
A3: type | B3: order | C3: _1 | D3: _2 | E3: _3 | F3: _4 | G3: _5 | H3: _6 | I3: _7 | J3: _8 | K3: _9 | L3: _10 | M3: _11 | N3: _12 | O3: _13
A4: Obs | B4: . | C4: 16.788889 | D4: 17.311111 | E4: 17.066667 | F4: 17.327778 | G4: 17.272222 | H4: 16.383333 | I4: 15.972222 | J4: 14.188889 | K4: 14.288889 | L4: 13.48 | M4: 12.93 | N4: 11.44 | O4: 10.72
A5: Pred | B5: 2 | C5: 17.1181 | D5: 17.1349 | E5: 17.1364 | F5: 17.0771 | G5: 16.9453 | H5: 16.612 | I5: 15.9141 | J5: 14.9267 | K5: 13.996 | L5: 13.2851 | M5: 12.5018 | N5: 11.6461 | O5: 10.6212
A7: Observed and Predicted stddev for mrtot
A9: type | B9: order | C9: _1 | D9: _2 | E9: _3 | F9: _4 | G9: _5 | H9: _6 | I9: _7 | J9: _8 | K9: _9 | L9: _10 | M9: _11 | N9: _12 | O9: _13
A10: Obs | B10: . | C10: 3.578316 | D10: 3.7718287 | E10: 3.6702031 | F10: 3.5545715 | G10: 4.1505611 | H10: 4.2613962 | I10: 4.0574513 | J10: 4.5314406 | K10: 4.2904192 | L10: 4.2911231 | M10: 4.6237311 | N10: 4.257661 | O10: 4.0528828
A11: Pred | B11: 2 | C11: 3.5527 | D11: 3.6197 | E11: 3.7301 | F11: 3.8726 | G11: 3.9975 | H11: 4.1514 | I11: 4.2944 | J11: 4.3663 | K11: 4.3736 | L11: 4.3562 | M11: 4.321 | N11: 4.2681 | O11: 4.1894
A13: Observed and Predicted skew for mrtot
A15: type | B15: order | C15: _1 | D15: _2 | E15: _3 | F15: _4 | G15: _5 | H15: _6 | I15: _7 | J15: _8 | K15: _9 | L15: _10 | M15: _11 | N15: _12 | O15: _13
A16: Obs | B16: . | C16: -0.69254218 | D16: -0.60622288 | E16: -0.91624392 | F16: -1.0429432 | G16: -1.1259601 | H16: -0.86255631 | I16: -0.48456329 | J16: -0.51352354 | K16: -0.27554029 | L16: -0.11767681 | M16: 0.0074554795 | N16: 0.41032259 | O16: 0.40257638
A17: Pred | B17: 3 | C17: -0.6948 | D17: -0.7621 | E17: -0.8555 | F17: -0.9389 | G17: -0.9691 | H17: -0.9284 | I17: -0.7463 | J17: -0.4642 | K17: -0.217 | L17: -0.0471 | M17: 0.1196 | N17: 0.2769 | O17: 0.4316
A19: Power | B19: 2 | C19: 2 | D19: 3
A20: MR | B20: Mean | C20: SD | D20: Skew
A21: 1 | B21: 17.1181 | C21: 3.5527 | D21: -0.6948
A22: 2 | B22: 17.1349 | C22: 3.6197 | D22: -0.7621
A23: 3 | B23: 17.1364 | C23: 3.7301 | D23: -0.8555
A24: 4 | B24: 17.0771 | C24: 3.8726 | D24: -0.9389
A25: 5 | B25: 16.9453 | C25: 3.9975 | D25: -0.9691
A26: 6 | B26: 16.612 | C26: 4.1514 | D26: -0.9284
A27: 7 | B27: 15.9141 | C27: 4.2944 | D27: -0.7463
A28: 8 | B28: 14.9267 | C28: 4.3663 | D28: -0.4642
A29: 9 | B29: 13.996 | C29: 4.3736 | D29: -0.217
A30: 10 | B30: 13.2851 | C30: 4.3562 | D30: -0.0471
A31: 11 | B31: 12.5018 | C31: 4.321 | D31: 0.1196
A32: 12 | B32: 11.6461 | C32: 4.2681 | D32: 0.2769
A33: 13 | B33: 10.6212 | C33: 4.1894 | D33: 0.4316
A35: WAIS5, 2/16/2024

Sheet handsmth
A1: wais5_mr_raw | B1: ss1 | C1: ss2 | D1: ss3 | E1: ss4 | F1: ss5 | G1: ss6 | H1: ss7 | I1: ss8 | J1: ss9 | K1: ss10 | L1: ss11 | M1: ss12 | N1: ss13 | O1: ReverseCross | P1: r12 | Q1: r23 | R1: r34 | S1: r45 | T1: r56 | U1: r67 | V1: r78 | W1: r89 | X1: r910 | Y1: r1011 | Z1: r1112 | AA1: r1213 | AB1: ReverseDown | AC1: d1 | AD1: d2 | AE1: d3 | AF1: d4 | AG1: d5 | AH1: d6 | AI1: d7 | AJ1: d8 | AK1: d9 | AL1: d10 | AM1: d11 | AN1: d12 | AO1: d13 | AP1: blank | AQ1: ssq1 | AR1: ssq2 | AS1: ssq3 | AT1: ssq4 | AU1: ssq5 | AV1: ssq6 | AW1: ssq7 | AX1: ssq8 | AY1: ssq9 | AZ1: ssq10 | BA1: ssq11 | BB1: ssq12 | BC1: ssq13 | BD1: blank | BE1: f1 | BF1: f2 | BG1: f3 | BH1: f4 | BI1: f5 | BJ1: f6 | BK1: f7 | BL1: f8 | BM1: f9 | BN1: f10 | BO1: f11 | BP1: f12 | BQ1: f13
A2: 0 | B2: 1 | C2: 1 | D2: 1 | E2: 1 | F2: 1 | G2: 1 | H2: 1 | I2: 1 | J2: 1 | K2: 1 | L2: 1 | M2: 1 | N2: 1 | P2: =(B2-C2) -> 0 | Q2: =(C2-D2) -> 0 | R2: =(D2-E2) -> 0 | S2: =(E2-F2) -> 0 | T2: =(F2-G2) -> 0 | U2: =(G2-H2) -> 0 | V2: =(H2-I2) -> 0 | W2: =(I2-J2) -> 0 | ... AA2: =(M2-N2) -> 0 | AC2: =(B3-B2) -> 0 | AD2: =(C3-C2) -> 0 | AE2: =(D3-D2) -> 0 | AF2: =(E3-E2) -> 0 | AG2: =(F3-F2) -> 0 | AH2: =(G3-G2) -> 0 | AI2: =(H3-H2) -> 0 | AJ2: =(I3-I2) -> 1 | ... AO2: =(N3-N2) -> 1 | AQ2: =B2^2 -> 1 | AR2: =C2^2 -> 1 | AS2: =D2^2 -> 1 | AT2: =E2^2 -> 1 | AU2: =F2^2 -> 1 | AV2: =G2^2 -> 1 | AW2: =H2^2 -> 1 | AX2: =I2^2 -> 1 | ... BC2: =N2^2 -> 1 | BE2: 8e-05 | BF2: 0.00012 | BG2: 0.00024 | BH2: 0.00049 | BI2: 0.00076 | BJ2: 0.001054 | BK2: 0.001276 | BL2: 0.00148 | BM2: 0.001743 | BN2: 0.001926 | BO2: 0.001599 | BP2: 0.000722 | BQ2: 0
A3: 1 | B3: 1 | C3: 1 | D3: 1 | E3: 1 | F3: 1 | G3: 1 | H3: 1 | I3: 2 | J3: 2 | K3: 2 | L3: 2 | M3: 2 | N3: 2 | P3: =(B3-C3) -> 0 | Q3: =(C3-D3) -> 0 | R3: =(D3-E3) -> 0 | S3: =(E3-F3) -> 0 | T3: =(F3-G3) -> 0 | U3: =(G3-H3) -> 0 | V3: =(H3-I3) -> -1 | W3: =(I3-J3) -> 0 | ... AA3: =(M3-N3) -> 0 | AC3: =(B4-B3) -> 0 | AD3: =(C4-C3) -> 0 | AE3: =(D4-D3) -> 0 | AF3: =(E4-E3) -> 0 | AG3: =(F4-F3) -> 0 | AH3: =(G4-G3) -> 0 | AI3: =(H4-H3) -> 1 | AJ3: =(I4-I3) -> 0 | ... AO3: =(N4-N3) -> 1 | AQ3: =B3^2 -> 1 | AR3: =C3^2 -> 1 | AS3: =D3^2 -> 1 | AT3: =E3^2 -> 1 | AU3: =F3^2 -> 1 | AV3: =G3^2 -> 1 | AW3: =H3^2 -> 1 | AX3: =I3^2 -> 4 | ... BC3: =N3^2 -> 4 | BE3: 0.00013 | BF3: 0.00018 | BG3: 0.0003 | BH3: 0.00052 | BI3: 0.00083 | BJ3: 0.001424 | BK3: 0.001824 | BL3: 0.002201 | BM3: 0.002139 | BN3: 0.001991 | BO3: 0.002082 | BP3: 0.002353 | BQ3: 0.002615
A4: 2 | B4: 1 | C4: 1 | D4: 1 | E4: 1 | F4: 1 | G4: 1 | H4: 2 | I4: 2 | J4: 2 | K4: 2 | L4: 2 | M4: 2 | N4: 3 | P4: =(B4-C4) -> 0 | Q4: =(C4-D4) -> 0 | R4: =(D4-E4) -> 0 | S4: =(E4-F4) -> 0 | T4: =(F4-G4) -> 0 | U4: =(G4-H4) -> -1 | V4: =(H4-I4) -> 0 | W4: =(I4-J4) -> 0 | ... AA4: =(M4-N4) -> -1 | AC4: =(B5-B4) -> 1 | AD4: =(C5-C4) -> 1 | AE4: =(D5-D4) -> 1 | AF4: =(E5-E4) -> 1 | AG4: =(F5-F4) -> 1 | AH4: =(G5-G4) -> 1 | AI4: =(H5-H4) -> 0 | AJ4: =(I5-I4) -> 1 | ... AO4: =(N5-N4) -> 1 | AQ4: =B4^2 -> 1 | AR4: =C4^2 -> 1 | AS4: =D4^2 -> 1 | AT4: =E4^2 -> 1 | AU4: =F4^2 -> 1 | AV4: =G4^2 -> 1 | AW4: =H4^2 -> 4 | AX4: =I4^2 -> 4 | ... BC4: =N4^2 -> 9 | BE4: 0.00028 | BF4: 0.00038 | BG4: 0.00058 | BH4: 0.0009 | BI4: 0.0012 | BJ4: 0.001534 | BK4: 0.002026 | BL4: 0.002328 | BM4: 0.002963 | BN4: 0.003467 | BO4: 0.004134 | BP4: 0.005433 | BQ4: 0.008997
A5: 3 | B5: 2 | C5: 2 | D5: 2 | E5: 2 | F5: 2 | G5: 2 | H5: 2 | I5: 3 | J5: 3 | K5: 3 | L5: 3 | M5: 3 | N5: 4 | P5: =(B5-C5) -> 0 | Q5: =(C5-D5) -> 0 | R5: =(D5-E5) -> 0 | S5: =(E5-F5) -> 0 | T5: =(F5-G5) -> 0 | U5: =(G5-H5) -> 0 | V5: =(H5-I5) -> -1 | W5: =(I5-J5) -> 0 | ... AA5: =(M5-N5) -> -1 | AC5: =(B6-B5) -> 0 | AD5: =(C6-C5) -> 0 | AE5: =(D6-D5) -> 0 | AF5: =(E6-E5) -> 0 | AG5: =(F6-F5) -> 0 | AH5: =(G6-G5) -> 0 | AI5: =(H6-H5) -> 1 | AJ5: =(I6-I5) -> 0 | ... AO5: =(N6-N5) -> 0 | AQ5: =B5^2 -> 4 | AR5: =C5^2 -> 4 | AS5: =D5^2 -> 4 | AT5: =E5^2 -> 4 | AU5: =F5^2 -> 4 | AV5: =G5^2 -> 4 | AW5: =H5^2 -> 4 | AX5: =I5^2 -> 9 | ... BC5: =N5^2 -> 16 | BE5: 0.00054 | BF5: 0.0007 | BG5: 0.001 | BH5: 0.00141 | BI5: 0.00174 | BJ5: 0.002078 | BK5: 0.002563 | BL5: 0.003636 | BM5: 0.004881 | BN5: 0.005954 | BO5: 0.007592 | BP5: 0.010718 | BQ5: 0.017906
A6: 4 | B6: 2 | C6: 2 | D6: 2 | E6: 2 | F6: 2 | G6: 2 | H6: 3 | I6: 3 | J6: 3 | K6: 4 | L6: 4 | M6: 4 | N6: 4 | P6: =(B6-C6) -> 0 | Q6: =(C6-D6) -> 0 | R6: =(D6-E6) -> 0 | S6: =(E6-F6) -> 0 | T6: =(F6-G6) -> 0 | U6: =(G6-H6) -> -1 | V6: =(H6-I6) -> 0 | W6: =(I6-J6) -> 0 | ... AA6: =(M6-N6) -> 0 | AC6: =(B7-B6) -> 0 | AD6: =(C7-C6) -> 0 | AE6: =(D7-D6) -> 0 | AF6: =(E7-E6) -> 0 | AG6: =(F7-F6) -> 1 | AH6: =(G7-G6) -> 1 | AI6: =(H7-H6) -> 0 | AJ6: =(I7-I6) -> 1 | ... AO6: =(N7-N6) -> 1 | AQ6: =B6^2 -> 4 | AR6: =C6^2 -> 4 | AS6: =D6^2 -> 4 | AT6: =E6^2 -> 4 | AU6: =F6^2 -> 4 | AV6: =G6^2 -> 4 | AW6: =H6^2 -> 9 | AX6: =I6^2 -> 9 | ... BC6: =N6^2 -> 16 | BE6: 0.00097 | BF6: 0.00119 | BG6: 0.00156 | BH6: 0.002 | BI6: 0.00232 | BJ6: 0.00271 | BK6: 0.003665 | BL6: 0.005645 | BM6: 0.007775 | BN6: 0.009753 | BO6: 0.012953 | BP6: 0.018753 | BQ6: 0.030377
A7: 5 | B7: 2 | C7: 2 | D7: 2 | E7: 2 | F7: 3 | G7: 3 | H7: 3 | I7: 4 | J7: 4 | K7: 4 | L7: 4 | M7: 4 | N7: 5 | P7: =(B7-C7) -> 0 | Q7: =(C7-D7) -> 0 | R7: =(D7-E7) -> 0 | S7: =(E7-F7) -> -1 | T7: =(F7-G7) -> 0 | U7: =(G7-H7) -> 0 | V7: =(H7-I7) -> -1 | W7: =(I7-J7) -> 0 | ... AA7: =(M7-N7) -> -1 | AC7: =(B8-B7) -> 1 | AD7: =(C8-C7) -> 1 | AE7: =(D8-D7) -> 1 | AF7: =(E8-E7) -> 1 | AG7: =(F8-F7) -> 0 | AH7: =(G8-G7) -> 0 | AI7: =(H8-H7) -> 1 | AJ7: =(I8-I7) -> 0 | ... AO7: =(N8-N7) -> 1 | AQ7: =B7^2 -> 4 | AR7: =C7^2 -> 4 | AS7: =D7^2 -> 4 | AT7: =E7^2 -> 4 | AU7: =F7^2 -> 9 | AV7: =G7^2 -> 9 | AW7: =H7^2 -> 9 | AX7: =I7^2 -> 16 | ... BC7: =N7^2 -> 25 | BE7: 0.0016 | BF7: 0.00186 | BG7: 0.00226 | BH7: 0.00267 | BI7: 0.00299 | BJ7: 0.003612 | BK7: 0.00545 | BL7: 0.008647 | BM7: 0.011947 | BN7: 0.015228 | BO7: 0.020604 | BP7: 0.029675 | BQ7: 0.045584
A8: 6 | B8: 3 | C8: 3 | D8: 3 | E8: 3 | F8: 3 | G8: 3 | H8: 4 | I8: 4 | J8: 4 | K8: 5 | L8: 5 | M8: 5 | N8: 6 | P8: =(B8-C8) -> 0 | Q8: =(C8-D8) -> 0 | R8: =(D8-E8) -> 0 | S8: =(E8-F8) -> 0 | T8: =(F8-G8) -> 0 | U8: =(G8-H8) -> -1 | V8: =(H8-I8) -> 0 | W8: =(I8-J8) -> 0 | ... AA8: =(M8-N8) -> -1 | AC8: =(B9-B8) -> 0 | AD8: =(C9-C8) -> 0 | AE8: =(D9-D8) -> 0 | AF8: =(E9-E8) -> 0 | AG8: =(F9-F8) -> 1 | AH8: =(G9-G8) -> 1 | AI8: =(H9-H8) -> 0 | AJ8: =(I9-I8) -> 1 | ... AO8: =(N9-N8) -> 1 | AQ8: =B8^2 -> 9 | AR8: =C8^2 -> 9 | AS8: =D8^2 -> 9 | AT8: =E8^2 -> 9 | AU8: =F8^2 -> 9 | AV8: =G8^2 -> 9 | AW8: =H8^2 -> 16 | AX8: =I8^2 -> 16 | ... BC8: =N8^2 -> 36 | BE8: 0.00251 | BF8: 0.00278 | BG8: 0.00315 | BH8: 0.00357 | BI8: 0.00402 | BJ8: 0.005227 | BK8: 0.008366 | BL8: 0.012935 | BM8: 0.017669 | BN8: 0.022656 | BO8: 0.030649 | BP8: 0.042978 | BQ8: 0.061724
A9: 7 | B9: 3 | C9: 3 | D9: 3 | E9: 3 | F9: 4 | G9: 4 | H9: 4 | I9: 5 | J9: 5 | K9: 5 | L9: 6 | M9: 6 | N9: 7 | P9: =(B9-C9) -> 0 | Q9: =(C9-D9) -> 0 | R9: =(D9-E9) -> 0 | S9: =(E9-F9) -> -1 | T9: =(F9-G9) -> 0 | U9: =(G9-H9) -> 0 | V9: =(H9-I9) -> -1 | W9: =(I9-J9) -> 0 | ... AA9: =(M9-N9) -> -1 | AC9: =(B10-B9) -> 1 | AD9: =(C10-C9) -> 1 | AE9: =(D10-D9) -> 1 | AF9: =(E10-E9) -> 1 | AG9: =(F10-F9) -> 0 | AH9: =(G10-G9) -> 0 | AI9: =(H10-H9) -> 1 | AJ9: =(I10-I9) -> 0 | ... AO9: =(N10-N9) -> 1 | AQ9: =B9^2 -> 9 | AR9: =C9^2 -> 9 | AS9: =D9^2 -> 9 | AT9: =E9^2 -> 9 | AU9: =F9^2 -> 16 | AV9: =G9^2 -> 16 | AW9: =H9^2 -> 16 | AX9: =I9^2 -> 25 | ... BC9: =N9^2 -> 49 | BE9: 0.00392 | BF9: 0.00419 | BG9: 0.00459 | BH9: 0.00517 | BI9: 0.00603 | BJ9: 0.008242 | BK9: 0.012858 | BL9: 0.018703 | BM9: 0.025112 | BN9: 0.032104 | BO9: 0.042738 | BP9: 0.057452 | BQ9: 0.076413
A10: 8 | B10: 4 | C10: 4 | D10: 4 | E10: 4 | F10: 4 | G10: 4 | H10: 5 | I10: 5 | J10: 6 | K10: 6 | L10: 7 | M10: 7 | N10: 8 | P10: =(B10-C10) -> 0 | Q10: =(C10-D10) -> 0 | R10: =(D10-E10) -> 0 | S10: =(E10-F10) -> 0 | T10: =(F10-G10) -> 0 | U10: =(G10-H10) -> -1 | V10: =(H10-I10) -> 0 | W10: =(I10-J10) -> -1 | ... AA10: =(M10-N10) -> -1 | AC10: =(B11-B10) -> 0 | AD10: =(C11-C10) -> 0 | AE10: =(D11-D10) -> 0 | AF10: =(E11-E10) -> 0 | AG10: =(F11-F10) -> 1 | AH10: =(G11-G10) -> 1 | AI10: =(H11-H10) -> 0 | AJ10: =(I11-I10) -> 1 | ... AO10: =(N11-N10) -> 1 | AQ10: =B10^2 -> 16 | AR10: =C10^2 -> 16 | AS10: =D10^2 -> 16 | AT10: =E10^2 -> 16 | AU10: =F10^2 -> 16 | AV10: =G10^2 -> 16 | AW10: =H10^2 -> 25 | AX10: =I10^2 -> 25 | ... BC10: =N10^2 -> 64 | BE10: 0.00635 | BF10: 0.00668 | BG10: 0.00726 | BH10: 0.00833 | BI10: 0.00991 | BJ10: 0.013352 | BK10: 0.019139 | BL10: 0.025965 | BM10: 0.034263 | BN10: 0.043309 | BO10: 0.055994 | BP10: 0.071351 | BQ10: 0.087392
A11: 9 | B11: 4 | C11: 4 | D11: 4 | E11: 4 | F11: 5 | G11: 5 | H11: 5 | I11: 6 | J11: 7 | K11: 7 | L11: 7 | M11: 8 | N11: 9 | P11: =(B11-C11) -> 0 | Q11: =(C11-D11) -> 0 | R11: =(D11-E11) -> 0 | S11: =(E11-F11) -> -1 | T11: =(F11-G11) -> 0 | U11: =(G11-H11) -> 0 | V11: =(H11-I11) -> -1 | W11: =(I11-J11) -> -1 | ... AA11: =(M11-N11) -> -1 | AC11: =(B12-B11) -> 1 | AD11: =(C12-C11) -> 1 | AE11: =(D12-D11) -> 1 | AF11: =(E12-E11) -> 1 | AG11: =(F12-F11) -> 0 | AH11: =(G12-G11) -> 1 | AI11: =(H12-H11) -> 1 | AJ11: =(I12-I11) -> 1 | ... AO11: =(N12-N11) -> 1 | AQ11: =B11^2 -> 16 | AR11: =C11^2 -> 16 | AS11: =D11^2 -> 16 | AT11: =E11^2 -> 16 | AU11: =F11^2 -> 25 | AV11: =G11^2 -> 25 | AW11: =H11^2 -> 25 | AX11: =I11^2 -> 36 | ... BC11: =N11^2 -> 81 | BE11: 0.01064 | BF11: 0.01115 | BG11: 0.01215 | BH11: 0.01401 | BI11: 0.01644 | BJ11: 0.020825 | BK11: 0.02697 | BL11: 0.034515 | BM11: 0.044847 | BN11: 0.055595 | BO11: 0.069065 | BP11: 0.082792 | BQ11: 0.09322
A12: 10 | B12: 5 | C12: 5 | D12: 5 | E12: 5 | F12: 5 | G12: 6 | H12: 6 | I12: 7 | J12: 7 | K12: 8 | L12: 8 | M12: 9 | N12: 10 | P12: =(B12-C12) -> 0 | Q12: =(C12-D12) -> 0 | R12: =(D12-E12) -> 0 | S12: =(E12-F12) -> 0 | T12: =(F12-G12) -> -1 | U12: =(G12-H12) -> 0 | V12: =(H12-I12) -> -1 | W12: =(I12-J12) -> 0 | ... AA12: =(M12-N12) -> -1 | AC12: =(B13-B12) -> 0 | AD12: =(C13-C12) -> 0 | AE12: =(D13-D12) -> 0 | AF12: =(E13-E12) -> 1 | AG12: =(F13-F12) -> 1 | AH12: =(G13-G12) -> 1 | AI12: =(H13-H12) -> 1 | AJ12: =(I13-I12) -> 0 | ... AO12: =(N13-N12) -> 0 | AQ12: =B12^2 -> 25 | AR12: =C12^2 -> 25 | AS12: =D12^2 -> 25 | AT12: =E12^2 -> 25 | AU12: =F12^2 -> 25 | AV12: =G12^2 -> 36 | AW12: =H12^2 -> 36 | AX12: =I12^2 -> 49 | ... BC12: =N12^2 -> 100 | BE12: 0.01762 | BF12: 0.01841 | BG12: 0.01998 | BH12: 0.02262 | BI12: 0.0256 | BJ12: 0.030096 | BK12: 0.035645 | BL12: 0.043974 | BM12: 0.05629 | BN12: 0.067878 | BO12: 0.08035 | BP12: 0.090227 | BQ12: 0.093612
A13: 11 | B13: 5 | C13: 5 | D13: 5 | E13: 6 | F13: 6 | G13: 7 | H13: 7 | I13: 7 | J13: 8 | K13: 8 | L13: 9 | M13: 10 | N13: 10 | P13: =(B13-C13) -> 0 | Q13: =(C13-D13) -> 0 | R13: =(D13-E13) -> -1 | S13: =(E13-F13) -> 0 | T13: =(F13-G13) -> -1 | U13: =(G13-H13) -> 0 | V13: =(H13-I13) -> 0 | W13: =(I13-J13) -> -1 | ... AA13: =(M13-N13) -> 0 | AC13: =(B14-B13) -> 1 | AD13: =(C14-C13) -> 1 | AE13: =(D14-D13) -> 1 | AF13: =(E14-E13) -> 0 | AG13: =(F14-F13) -> 1 | AH13: =(G14-G13) -> 0 | AI13: =(H14-H13) -> 0 | AJ13: =(I14-I13) -> 1 | ... AO13: =(N14-N13) -> 1 | AQ13: =B13^2 -> 25 | AR13: =C13^2 -> 25 | AS13: =D13^2 -> 25 | AT13: =E13^2 -> 36 | AU13: =F13^2 -> 36 | AV13: =G13^2 -> 49 | AW13: =H13^2 -> 49 | AX13: =I13^2 -> 49 | ... BC13: =N13^2 -> 100 | BE13: 0.02757 | BF13: 0.02857 | BG13: 0.03049 | BH13: 0.0334 | BI13: 0.03621 | BJ13: 0.039754 | BK13: 0.044259 | BL13: 0.053892 | BM13: 0.067707 | BN13: 0.078786 | BO13: 0.088331 | BP13: 0.092803 | BQ13: 0.089307
... A27: 25 | B27: 17 | C27: 17 | D27: 17 | E27: 17 | F27: 18 | G27: 18 | H27: 18 | I27: 18 | J27: 18 | K27: 19 | L27: 19 | M27: 19 | N27: 19 | P27: =(B27-C27) -> 0 | Q27: =(C27-D27) -> 0 | R27: =(D27-E27) -> 0 | S27: =(E27-F27) -> -1 | T27: =(F27-G27) -> 0 | U27: =(G27-H27) -> 0 | V27: =(H27-I27) -> 0 | W27: =(I27-J27) -> 0 | ... AA27: =(M27-N27) -> 0 | AC27: =(B28-B27) -> 2 | AD27: =(C28-C27) -> 2 | AE27: =(D28-D27) -> 2 | AF27: =(E28-E27) -> 2 | AG27: =(F28-F27) -> 1 | AH27: =(G28-G27) -> 1 | AI27: =(H28-H27) -> 1 | AJ27: =(I28-I27) -> 1 | ... AO27: =(N28-N27) -> 0 | AQ27: =B27^2 -> 289 | AR27: =C27^2 -> 289 | AS27: =D27^2 -> 289 | AT27: =E27^2 -> 289 | AU27: =F27^2 -> 324 | AV27: =G27^2 -> 324 | AW27: =H27^2 -> 324 | AX27: =I27^2 -> 324 | ... BC27: =N27^2 -> 361 | BE27: 0 | BF27: 0 | BG27: 0 | BH27: 0 | BI27: 0 | BJ27: 0 | BK27: 0 | BL27: 0.001191 | BM27: 0.002541 | BN27: 0.00227 | BO27: 0.001839 | BP27: 0.001347 | BQ27: 0.00089
A28: 26 | B28: 19 | C28: 19 | D28: 19 | E28: 19 | F28: 19 | G28: 19 | H28: 19 | I28: 19 | J28: 19 | K28: 19 | L28: 19 | M28: 19 | N28: 19 | P28: =(B28-C28) -> 0 | Q28: =(C28-D28) -> 0 | R28: =(D28-E28) -> 0 | S28: =(E28-F28) -> 0 | T28: =(F28-G28) -> 0 | U28: =(G28-H28) -> 0 | V28: =(H28-I28) -> 0 | W28: =(I28-J28) -> 0 | ... AA28: =(M28-N28) -> 0 | AQ28: =B28^2 -> 361 | AR28: =C28^2 -> 361 | AS28: =D28^2 -> 361 | AT28: =E28^2 -> 361 | AU28: =F28^2 -> 361 | AV28: =G28^2 -> 361 | AW28: =H28^2 -> 361 | AX28: =I28^2 -> 361 | ... BC28: =N28^2 -> 361 | BE28: 0 | BF28: 0 | BG28: 0 | BH28: 0 | BI28: 0 | BJ28: 0 | BK28: 0 | BL28: 0 | BM28: 0.001443 | BN28: 0.002101 | BO28: 0.001601 | BP28: 0.001017 | BQ28: 0.000598
A29: N | B29: =ROUND(SUM(BE2:BE28),0) -> 1 | C29: =ROUND(SUM(BF2:BF28),0) -> 1 | D29: =ROUND(SUM(BG2:BG28),0) -> 1 | E29: =ROUND(SUM(BH2:BH28),0) -> 1 | F29: =ROUND(SUM(BI2:BI28),0) -> 1 | G29: =ROUND(SUM(BJ2:BJ28),0) -> 1 | H29: =ROUND(SUM(BK2:BK28),0) -> 1 | I29: =ROUND(SUM(BL2:BL28),0) -> 1 | ... N29: =ROUND(SUM(BQ2:BQ28),0) -> 1 | BE29: . | BF29: . | BG29: . | BH29: . | BI29: . | BJ29: . | BK29: . | BL29: . | BM29: . | BN29: . | BO29: . | BP29: . | BQ29: .
A30: mean | B30: =SUMPRODUCT(B2:B28,BE2:BE28)/B29 -> 9.8678 | C30: =SUMPRODUCT(C2:C28,BF2:BF28)/C29 -> 9.89605 | D30: =SUMPRODUCT(D2:D28,BG2:BG28)/D29 -> 9.9225 | E30: =SUMPRODUCT(E2:E28,BH2:BH28)/E29 -> 9.94069 | F30: =SUMPRODUCT(F2:F28,BI2:BI28)/F29 -> 10.00452 | G30: =SUMPRODUCT(G2:G28,BJ2:BJ28)/G29 -> 10.510044 | H30: =SUMPRODUCT(H2:H28,BK2:BK28)/H29 -> 10.328069 | I30: =SUMPRODUCT(I2:I28,BL2:BL28)/I29 -> 10.295492 | ... N30: =SUMPRODUCT(N2:N28,BQ2:BQ28)/N29 -> 9.913958 | BE30: . | BF30: . | BG30: . | BH30: . | BI30: . | BJ30: . | BK30: . | BL30: . | BM30: . | BN30: . | BO30: . | BP30: . | BQ30: .
A31: sd | B31: =ROUND(SQRT(SUMPRODUCT(AQ2:AQ28,BE2:BE28)/B29-B30^2),2) -> 2.78 | C31: =ROUND(SQRT(SUMPRODUCT(AR2:AR28,BF2:BF28)/C29-C30^2),2) -> 2.84 | D31: =ROUND(SQRT(SUMPRODUCT(AS2:AS28,BG2:BG28)/D29-D30^2),2) -> 2.93 | E31: =ROUND(SQRT(SUMPRODUCT(AT2:AT28,BH2:BH28)/E29-E30^2),2) -> 2.99 | F31: =ROUND(SQRT(SUMPRODUCT(AU2:AU28,BI2:BI28)/F29-F30^2),2) -> 2.95 | G31: =ROUND(SQRT(SUMPRODUCT(AV2:AV28,BJ2:BJ28)/G29-G30^2),2) -> 3.2 | H31: =ROUND(SQRT(SUMPRODUCT(AW2:AW28,BK2:BK28)/H29-H30^2),2) -> 3.2 | I31: =ROUND(SQRT(SUMPRODUCT(AX2:AX28,BL2:BL28)/I29-I30^2),2) -> 3.2 | ... N31: =ROUND(SQRT(SUMPRODUCT(BC2:BC28,BQ2:BQ28)/N29-N30^2),2) -> 3.32 | BE31: . | BF31: . | BG31: . | BH31: . | BI31: . | BJ31: . | BK31: . | BL31: . | BM31: . | BN31: . | BO31: . | BP31: . | BQ31: .
A32: ideal | B32: =0.3-ABS(10-ROUND(B30,2)) -> 0.17 | C32: =0.3-ABS(10-ROUND(C30,2)) -> 0.2 | D32: =0.3-ABS(10-ROUND(D30,2)) -> 0.22 | E32: =0.3-ABS(10-ROUND(E30,2)) -> 0.24 | F32: =0.3-ABS(10-ROUND(F30,2)) -> 0.3 | G32: =0.3-ABS(10-ROUND(G30,2)) -> -0.21 | H32: =0.3-ABS(10-ROUND(H30,2)) -> -0.03 | I32: =0.3-ABS(10-ROUND(I30,2)) -> -7.2164497e-16 | ... N32: =0.3-ABS(10-ROUND(N30,2)) -> 0.21 | BE32: . | BF32: . | BG32: . | BH32: . | BI32: . | BJ32: . | BK32: . | BL32: . | BM32: . | BN32: . | BO32: . | BP32: . | BQ32: .
B33: =0.3-ABS(3-B31) -> 0.08 | C33: =0.3-ABS(3-C31) -> 0.14 | D33: =0.3-ABS(3-D31) -> 0.23 | E33: =0.3-ABS(3-E31) -> 0.29 | F33: =0.3-ABS(3-F31) -> 0.25 | G33: =0.3-ABS(3-G31) -> 0.1 | H33: =0.3-ABS(3-H31) -> 0.1 | I33: =0.3-ABS(3-I31) -> 0.1 | ... N33: =0.3-ABS(3-N31) -> -0.02 | BE33: . | BF33: . | BG33: . | BH33: . | BI33: . | BJ33: . | BK33: . | BL33: . | BM33: . | BN33: . | BO33: . | BP33: . | BQ33: .
A34: standard | B34: =0.6-ABS(10-ROUND(B30,2)) -> 0.47 | C34: =0.6-ABS(10-ROUND(C30,2)) -> 0.5 | D34: =0.6-ABS(10-ROUND(D30,2)) -> 0.52 | E34: =0.6-ABS(10-ROUND(E30,2)) -> 0.54 | F34: =0.6-ABS(10-ROUND(F30,2)) -> 0.6 | G34: =0.6-ABS(10-ROUND(G30,2)) -> 0.09 | H34: =0.6-ABS(10-ROUND(H30,2)) -> 0.27 | I34: =0.6-ABS(10-ROUND(I30,2)) -> 0.3 | ... N34: =0.6-ABS(10-ROUND(N30,2)) -> 0.51 | BE34: . | BF34: . | BG34: . | BH34: . | BI34: . | BJ34: . | BK34: . | BL34: . | BM34: . | BN34: . | BO34: . | BP34: . | BQ34: .
B35: =0.3-ABS(3-B31) -> 0.08 | C35: =0.3-ABS(3-C31) -> 0.14 | D35: =0.3-ABS(3-D31) -> 0.23 | E35: =0.3-ABS(3-E31) -> 0.29 | F35: =0.3-ABS(3-F31) -> 0.25 | G35: =0.3-ABS(3-G31) -> 0.1 | H35: =0.3-ABS(3-H31) -> 0.1 | I35: =0.3-ABS(3-I31) -> 0.1 | ... N35: =0.3-ABS(3-N31) -> -0.02 | BE35: . | BF35: . | BG35: . | BH35: . | BI35: . | BJ35: . | BK35: . | BL35: . | BM35: . | BN35: . | BO35: . | BP35: . | BQ35: .
A36: exception | B36: =0.9-ABS(10-ROUND(B30,2)) -> 0.77 | C36: =0.9-ABS(10-ROUND(C30,2)) -> 0.8 | D36: =0.9-ABS(10-ROUND(D30,2)) -> 0.82 | E36: =0.9-ABS(10-ROUND(E30,2)) -> 0.84 | F36: =0.9-ABS(10-ROUND(F30,2)) -> 0.9 | G36: =0.9-ABS(10-ROUND(G30,2)) -> 0.39 | H36: =0.9-ABS(10-ROUND(H30,2)) -> 0.57 | I36: =0.9-ABS(10-ROUND(I30,2)) -> 0.6 | ... N36: =0.9-ABS(10-ROUND(N30,2)) -> 0.81 | BE36: . | BF36: . | BG36: . | BH36: . | BI36: . | BJ36: . | BK36: . | BL36: . | BM36: . | BN36: . | BO36: . | BP36: . | BQ36: .
B37: =0.45-ABS(3-B31) -> 0.23 | C37: =0.45-ABS(3-C31) -> 0.29 | D37: =0.45-ABS(3-D31) -> 0.38 | E37: =0.45-ABS(3-E31) -> 0.44 | F37: =0.45-ABS(3-F31) -> 0.4 | G37: =0.45-ABS(3-G31) -> 0.25 | H37: =0.45-ABS(3-H31) -> 0.25 | I37: =0.45-ABS(3-I31) -> 0.25 | ... N37: =0.45-ABS(3-N31) -> 0.13 | BE37: . | BF37: . | BG37: . | BH37: . | BI37: . | BJ37: . | BK37: . | BL37: . | BM37: . | BN37: . | BO37: . | BP37: . | BQ37: .

Sheet QA
A1: Overall mean | D1: Before | I1: Overall mean | L1: After
A3: The MEANS Procedure | I3: The MEANS Procedure
A5: Analysis Variable : wais5_mr_ss | I5: Analysis Variable : wais5_mr_ss
A6: stdz | B6: N | C6: Mean | D6: Std Dev | E6: Minimum | F6: Maximum | I6: stdz | J6: N | K6: Mean | L6: Std Dev | M6: Minimum | N6: Maximum | Q6: 10 | R6: 3
A7: stdz | B7: 2020 | C7: 9.94 | D7: 2.9 | E7: 1 | F7: 19 | I7: stdz | J7: 2020 | K7: 10 | L7: 3 | M7: 1 | N7: 19 | Q7: =K7-$Q$6 -> 0 | R7: =L7-$R$6 -> 0
A12: wais5 overall pct | I12: wais5 overall pct
Q13: 4 | R13: 7 | S13: 10 | T13: 13 | U13: 16
A14: stdz | B14: P_02 | C14: P_16 | D14: P_50 | E14: P_84 | F14: P_98 | I14: stdz | J14: P_02 | K14: P_16 | L14: P_50 | M14: P_84 | N14: P_98
A15: stdz | B15: 4 | C15: 7 | D15: 10 | E15: 13 | F15: 16 | I15: stdz | J15: 4 | K15: 7 | L15: 10 | M15: 13 | N15: 16 | Q15: =J15-$Q$13 -> 0 | R15: =K15-$R$13 -> 0 | S15: =L15-$S$13 -> 0 | T15: =M15-$T$13 -> 0 | U15: =N15-$U$13 -> 0
A20: Group mean by agegrp | I20: Group mean by agegrp
A22: The MEANS Procedure | I22: The MEANS Procedure
A24: Analysis Variable : wais5_mr_ss | I24: Analysis Variable : wais5_mr_ss
A25: agegrp | B25: ageband | C25: N | D25: Mean | E25: Std Dev | F25: Minimum | G25: Maximum | I25: agegrp | J25: ageband | K25: N | L25: Mean | M25: Std Dev | N25: Minimum | O25: Maximum
A26: 1 | B26: 16-17 | C26: 180 | D26: 9.56 | E26: 2.83 | F26: 2 | G26: 18 | I26: 1 | J26: 16-17 | K26: 180 | L26: 9.56 | M26: 2.72 | N26: 3 | O26: 16 | Q26: =L26-$Q$6 -> -0.44 | R26: =M26-$R$6 -> -0.28
A27: 2 | B27: 18-19 | C27: 180 | D27: 10.12 | E27: 3.13 | F27: 2 | G27: 18 | I27: 2 | J27: 18-19 | K27: 180 | L27: 10.03 | M27: 2.91 | N27: 3 | O27: 16 | Q27: =L27-$Q$6 -> 0.03 | R27: =M27-$R$6 -> -0.09
A28: 3 | B28: 20-24 | C28: 180 | D28: 9.85 | E28: 2.8 | F28: 1 | G28: 18 | I28: 3 | J28: 20-24 | K28: 180 | L28: 9.8 | M28: 2.76 | N28: 1 | O28: 16 | Q28: =L28-$Q$6 -> -0.2 | R28: =M28-$R$6 -> -0.24
A29: 4 | B29: 25-29 | C29: 180 | D29: 9.95 | E29: 2.62 | F29: 2 | G29: 18 | I29: 4 | J29: 25-29 | K29: 180 | L29: 10.03 | M29: 2.61 | N29: 2 | O29: 16 | Q29: =L29-$Q$6 -> 0.03 | R29: =M29-$R$6 -> -0.39
A30: 5 | B30: 30-34 | C30: 180 | D30: 10.18 | E30: 3.03 | F30: 1 | G30: 19 | I30: 5 | J30: 30-34 | K30: 180 | L30: 10.16 | M30: 2.97 | N30: 1 | O30: 19 | Q30: =L30-$Q$6 -> 0.16 | R30: =M30-$R$6 -> -0.03
A31: 6 | B31: 35-44 | C31: 180 | D31: 9.67 | E31: 2.83 | F31: 2 | G31: 18 | I31: 6 | J31: 35-44 | K31: 180 | L31: 10.24 | M31: 3.07 | N31: 1 | O31: 17 | Q31: =L31-$Q$6 -> 0.24 | R31: =M31-$R$6 -> 0.07
A32: 7 | B32: 45-54 | C32: 180 | D32: 10.07 | E32: 2.86 | F32: 3 | G32: 19 | I32: 7 | J32: 45-54 | K32: 180 | L32: 10.29 | M32: 3.05 | N32: 3 | O32: 18 | Q32: =L32-$Q$6 -> 0.29 | R32: =M32-$R$6 -> 0.05
A33: 8 | B33: 55-64 | C33: 180 | D33: 9.52 | E33: 2.96 | F33: 2 | G33: 15 | I33: 8 | J33: 55-64 | K33: 180 | L33: 9.79 | M33: 3.25 | N33: 2 | O33: 16 | Q33: =L33-$Q$6 -> -0.21 | R33: =M33-$R$6 -> 0.25
A34: 9 | B34: 65-69 | C34: 180 | D34: 10.23 | E34: 2.91 | F34: 4 | G34: 17 | I34: 9 | J34: 65-69 | K34: 180 | L34: 10.07 | M34: 3.02 | N34: 3 | O34: 18 | Q34: =L34-$Q$6 -> 0.07 | R34: =M34-$R$6 -> 0.02
A35: 10 | B35: 70-74 | C35: 100 | D35: 10.1 | E35: 3.01 | F35: 4 | G35: 15 | I35: 10 | J35: 70-74 | K35: 100 | L35: 10.1 | M35: 3.11 | N35: 4 | O35: 16 | Q35: =L35-$Q$6 -> 0.1 | R35: =M35-$R$6 -> 0.11
A36: 11 | B36: 75-79 | C36: 100 | D36: 10.23 | E36: 3.17 | F36: 3 | G36: 16 | I36: 11 | J36: 75-79 | K36: 100 | L36: 10.23 | M36: 3.34 | N36: 3 | O36: 17 | Q36: =L36-$Q$6 -> 0.23 | R36: =M36-$R$6 -> 0.34
A37: 12 | B37: 80-84 | C37: 100 | D37: 9.94 | E37: 2.89 | F37: 5 | G37: 16 | I37: 12 | J37: 80-84 | K37: 100 | L37: 9.73 | M37: 3.42 | N37: 4 | O37: 17 | Q37: =L37-$Q$6 -> -0.27 | R37: =M37-$R$6 -> 0.42
A38: 13 | B38: 85-90 | C38: 100 | D38: 10.12 | E38: 2.7 | F38: 3 | G38: 16 | I38: 13 | J38: 85-90 | K38: 100 | L38: 10.04 | M38: 3.24 | N38: 3 | O38: 17 | Q38: =L38-$Q$6 -> 0.04 | R38: =M38-$R$6 -> 0.24
A39: 14 | B39: IDMI | C39: 44 | D39: 3.89 | E39: 2.3 | F39: 1 | G39: 10 | I39: 14 | J39: IDMI | K39: 44 | L39: 3.95 | M39: 2.29 | N39: 1 | O39: 10
A40: 15 | B40: IDMO | C40: 26 | D40: 3 | E40: 1.3 | F40: 1 | G40: 6 | I40: 15 | J40: IDMO | K40: 26 | L40: 2.96 | M40: 1.31 | N40: 1 | O40: 5
A41: 16 | B41: ADHD | C41: 32 | D41: 10.78 | E41: 2.04 | F41: 7 | G41: 15 | I41: 16 | J41: ADHD | K41: 32 | L41: 10.88 | M41: 2.23 | N41: 7 | O41: 15
A42: 17 | B42: GT | C42: 68 | D42: 13.71 | E42: 2.44 | F42: 9 | G42: 19 | I42: 17 | J42: GT | K42: 68 | L42: 13.66 | M42: 2.04 | N42: 9 | O42: 18
A47: wais5 pct by agegrp: Age Norm | I47: wais5 pct by agegrp: Age Norm
A49: agegrp | B49: ageband | C49: P_02 | D49: P_16 | E49: P_50 | F49: P_84 | G49: P_98 | I49: agegrp | J49: ageband | K49: P_02 | L49: P_16 | M49: P_50 | N49: P_84 | O49: P_98
A50: 1 | B50: 16-17 | C50: 3 | D50: 7 | E50: 10 | F50: 12 | G50: 14 | I50: 1 | J50: 16-17 | K50: 4 | L50: 7 | M50: 10 | N50: 12 | O50: 14 | Q50: =K50-$Q$13 -> 0 | R50: =L50-$R$13 -> 0 | S50: =M50-$S$13 -> 0 | T50: =N50-$T$13 -> -1 | U50: =O50-$U$13 -> -2
A51: 2 | B51: 18-19 | C51: 4 | D51: 7 | E51: 10 | F51: 13 | G51: 18 | I51: 2 | J51: 18-19 | K51: 4 | L51: 7 | M51: 10 | N51: 13 | O51: 16 | Q51: =K51-$Q$13 -> 0 | R51: =L51-$R$13 -> 0 | S51: =M51-$S$13 -> 0 | T51: =N51-$T$13 -> 0 | U51: =O51-$U$13 -> 0
A52: 3 | B52: 20-24 | C52: 4 | D52: 8 | E52: 9.5 | F52: 12 | G52: 16 | I52: 3 | J52: 20-24 | K52: 4 | L52: 7 | M52: 10 | N52: 12 | O52: 15 | Q52: =K52-$Q$13 -> 0 | R52: =L52-$R$13 -> 0 | S52: =M52-$S$13 -> 0 | T52: =N52-$T$13 -> -1 | U52: =O52-$U$13 -> -1
A53: 4 | B53: 25-29 | C53: 4 | D53: 8 | E53: 10 | F53: 13 | G53: 14 | I53: 4 | J53: 25-29 | K53: 4 | L53: 7 | M53: 10 | N53: 13 | O53: 14 | Q53: =K53-$Q$13 -> 0 | R53: =L53-$R$13 -> 0 | S53: =M53-$S$13 -> 0 | T53: =N53-$T$13 -> 0 | U53: =O53-$U$13 -> -2
A54: 5 | B54: 30-34 | C54: 3 | D54: 8 | E54: 10 | F54: 13 | G54: 18 | I54: 5 | J54: 30-34 | K54: 3 | L54: 8 | M54: 10 | N54: 13 | O54: 17 | Q54: =K54-$Q$13 -> -1 | R54: =L54-$R$13 -> 1 | S54: =M54-$S$13 -> 0 | T54: =N54-$T$13 -> 0 | U54: =O54-$U$13 -> 1
A55: 6 | B55: 35-44 | C55: 3 | D55: 6 | E55: 10 | F55: 12 | G55: 16 | I55: 6 | J55: 35-44 | K55: 3 | L55: 7 | M55: 11 | N55: 13 | O55: 16 | Q55: =K55-$Q$13 -> -1 | R55: =L55-$R$13 -> 0 | S55: =M55-$S$13 -> 1 | T55: =N55-$T$13 -> 0 | U55: =O55-$U$13 -> 0
A56: 7 | B56: 45-54 | C56: 4 | D56: 7 | E56: 10 | F56: 13 | G56: 15 | I56: 7 | J56: 45-54 | K56: 4 | L56: 7 | M56: 10 | N56: 13 | O56: 15 | Q56: =K56-$Q$13 -> 0 | R56: =L56-$R$13 -> 0 | S56: =M56-$S$13 -> 0 | T56: =N56-$T$13 -> 0 | U56: =O56-$U$13 -> -1
A57: 8 | B57: 55-64 | C57: 3 | D57: 6 | E57: 10 | F57: 13 | G57: 14 | I57: 8 | J57: 55-64 | K57: 3 | L57: 6 | M57: 10 | N57: 13 | O57: 15 | Q57: =K57-$Q$13 -> -1 | R57: =L57-$R$13 -> -1 | S57: =M57-$S$13 -> 0 | T57: =N57-$T$13 -> 0 | U57: =O57-$U$13 -> -1
...

Sheet checksmooth
B1: g1 | C1: g2 | D1: g3 | E1: g4 | F1: g5 | G1: g6 | H1: g7 | I1: g8 | J1: g9 | K1: g10 | L1: g11 | M1: g12 | N1: g13 | Q1: g1 | R1: g2 | S1: g3 | T1: g4 | U1: g5 | V1: g6 | W1: g7 | X1: g8 | Y1: g9 | Z1: g10 | AA1: g11 | AB1: g12 | AF1: g1 | AG1: g2 | AH1: g3 | AI1: g4 | AJ1: g5 | AK1: g6 | AL1: g7 | AM1: g8 | AN1: g9 | AO1: g10 | AP1: g11 | AQ1: g12 | AR1: g13
A2: 1 | B2: =COUNTIF(handsmth!B$2:B$28,$A2) -> 3 | C2: =COUNTIF(handsmth!C$2:C$28,$A2) -> 3 | D2: =COUNTIF(handsmth!D$2:D$28,$A2) -> 3 | E2: =COUNTIF(handsmth!E$2:E$28,$A2) -> 3 | F2: =COUNTIF(handsmth!F$2:F$28,$A2) -> 3 | G2: =COUNTIF(handsmth!G$2:G$28,$A2) -> 3 | H2: =COUNTIF(handsmth!H$2:H$28,$A2) -> 2 | I2: =COUNTIF(handsmth!I$2:I$28,$A2) -> 1 | ... N2: =COUNTIF(handsmth!N$2:N$28,$A2) -> 1 | P2: 1 | Q2: =B2-C2 -> 0 | R2: =C2-D2 -> 0 | S2: =D2-E2 -> 0 | T2: =E2-F2 -> 0 | U2: =F2-G2 -> 0 | V2: =G2-H2 -> 1 | W2: =H2-I2 -> 1 | X2: =I2-J2 -> 0 | ... AB2: =M2-N2 -> 0 | AE2: 1 | AF2: =B3-B2 -> 0 | AG2: =C3-C2 -> 0 | AH2: =D3-D2 -> 0 | AI2: =E3-E2 -> 0 | AJ2: =F3-F2 -> -1 | AK2: =G3-G2 -> -1 | AL2: =H3-H2 -> 0 | AM2: =I3-I2 -> 1 | ... AR2: =N3-N2 -> 0
A3: 2 | B3: =COUNTIF(handsmth!B$2:B$28,$A3) -> 3 | C3: =COUNTIF(handsmth!C$2:C$28,$A3) -> 3 | D3: =COUNTIF(handsmth!D$2:D$28,$A3) -> 3 | E3: =COUNTIF(handsmth!E$2:E$28,$A3) -> 3 | F3: =COUNTIF(handsmth!F$2:F$28,$A3) -> 2 | G3: =COUNTIF(handsmth!G$2:G$28,$A3) -> 2 | H3: =COUNTIF(handsmth!H$2:H$28,$A3) -> 2 | I3: =COUNTIF(handsmth!I$2:I$28,$A3) -> 2 | ... N3: =COUNTIF(handsmth!N$2:N$28,$A3) -> 1 | P3: 2 | Q3: =B3-C3 -> 0 | R3: =C3-D3 -> 0 | S3: =D3-E3 -> 0 | T3: =E3-F3 -> 1 | U3: =F3-G3 -> 0 | V3: =G3-H3 -> 0 | W3: =H3-I3 -> 0 | X3: =I3-J3 -> 0 | ... AB3: =M3-N3 -> 1 | AE3: 2 | AF3: =B4-B3 -> -1 | AG3: =C4-C3 -> -1 | AH3: =D4-D3 -> -1 | AI3: =E4-E3 -> -1 | AJ3: =F4-F3 -> 0 | AK3: =G4-G3 -> 0 | AL3: =H4-H3 -> 0 | AM3: =I4-I3 -> 0 | ... AR3: =N4-N3 -> 0
A4: 3 | B4: =COUNTIF(handsmth!B$2:B$28,$A4) -> 2 | C4: =COUNTIF(handsmth!C$2:C$28,$A4) -> 2 | D4: =COUNTIF(handsmth!D$2:D$28,$A4) -> 2 | E4: =COUNTIF(handsmth!E$2:E$28,$A4) -> 2 | F4: =COUNTIF(handsmth!F$2:F$28,$A4) -> 2 | G4: =COUNTIF(handsmth!G$2:G$28,$A4) -> 2 | H4: =COUNTIF(handsmth!H$2:H$28,$A4) -> 2 | I4: =COUNTIF(handsmth!I$2:I$28,$A4) -> 2 | ... N4: =COUNTIF(handsmth!N$2:N$28,$A4) -> 1 | P4: 3 | Q4: =B4-C4 -> 0 | R4: =C4-D4 -> 0 | S4: =D4-E4 -> 0 | T4: =E4-F4 -> 0 | U4: =F4-G4 -> 0 | V4: =G4-H4 -> 0 | W4: =H4-I4 -> 0 | X4: =I4-J4 -> 0 | ... AB4: =M4-N4 -> 0 | AE4: 3 | AF4: =B5-B4 -> 0 | AG4: =C5-C4 -> 0 | AH4: =D5-D4 -> 0 | AI4: =E5-E4 -> 0 | AJ4: =F5-F4 -> 0 | AK4: =G5-G4 -> 0 | AL4: =H5-H4 -> 0 | AM4: =I5-I4 -> 0 | ... AR4: =N5-N4 -> 1
A5: 4 | B5: =COUNTIF(handsmth!B$2:B$28,$A5) -> 2 | C5: =COUNTIF(handsmth!C$2:C$28,$A5) -> 2 | D5: =COUNTIF(handsmth!D$2:D$28,$A5) -> 2 | E5: =COUNTIF(handsmth!E$2:E$28,$A5) -> 2 | F5: =COUNTIF(handsmth!F$2:F$28,$A5) -> 2 | G5: =COUNTIF(handsmth!G$2:G$28,$A5) -> 2 | H5: =COUNTIF(handsmth!H$2:H$28,$A5) -> 2 | I5: =COUNTIF(handsmth!I$2:I$28,$A5) -> 2 | ... N5: =COUNTIF(handsmth!N$2:N$28,$A5) -> 2 | P5: 4 | Q5: =B5-C5 -> 0 | R5: =C5-D5 -> 0 | S5: =D5-E5 -> 0 | T5: =E5-F5 -> 0 | U5: =F5-G5 -> 0 | V5: =G5-H5 -> 0 | W5: =H5-I5 -> 0 | X5: =I5-J5 -> 0 | ... AB5: =M5-N5 -> 0 | AE5: 4 | AF5: =B6-B5 -> 0 | AG5: =C6-C5 -> 0 | AH5: =D6-D5 -> 0 | AI5: =E6-E5 -> -1 | AJ5: =F6-F5 -> 0 | AK5: =G6-G5 -> -1 | AL5: =H6-H5 -> 0 | AM5: =I6-I5 -> 0 | ... AR5: =N6-N5 -> -1
A6: 5 | B6: =COUNTIF(handsmth!B$2:B$28,$A6) -> 2 | C6: =COUNTIF(handsmth!C$2:C$28,$A6) -> 2 | D6: =COUNTIF(handsmth!D$2:D$28,$A6) -> 2 | E6: =COUNTIF(handsmth!E$2:E$28,$A6) -> 1 | F6: =COUNTIF(handsmth!F$2:F$28,$A6) -> 2 | G6: =COUNTIF(handsmth!G$2:G$28,$A6) -> 1 | H6: =COUNTIF(handsmth!H$2:H$28,$A6) -> 2 | I6: =COUNTIF(handsmth!I$2:I$28,$A6) -> 2 | ... N6: =COUNTIF(handsmth!N$2:N$28,$A6) -> 1 | P6: 5 | Q6: =B6-C6 -> 0 | R6: =C6-D6 -> 0 | S6: =D6-E6 -> 1 | T6: =E6-F6 -> -1 | U6: =F6-G6 -> 1 | V6: =G6-H6 -> -1 | W6: =H6-I6 -> 0 | X6: =I6-J6 -> 1 | ... AB6: =M6-N6 -> 0 | AE6: 5 | AF6: =B7-B6 -> -1 | AG6: =C7-C6 -> -1 | AH6: =D7-D6 -> -1 | AI6: =E7-E6 -> 1 | AJ6: =F7-F6 -> -1 | AK6: =G7-G6 -> 0 | AL6: =H7-H6 -> -1 | AM6: =I7-I6 -> -1 | ... AR6: =N7-N6 -> 0
A7: 6 | B7: =COUNTIF(handsmth!B$2:B$28,$A7) -> 1 | C7: =COUNTIF(handsmth!C$2:C$28,$A7) -> 1 | D7: =COUNTIF(handsmth!D$2:D$28,$A7) -> 1 | E7: =COUNTIF(handsmth!E$2:E$28,$A7) -> 2 | F7: =COUNTIF(handsmth!F$2:F$28,$A7) -> 1 | G7: =COUNTIF(handsmth!G$2:G$28,$A7) -> 1 | H7: =COUNTIF(handsmth!H$2:H$28,$A7) -> 1 | I7: =COUNTIF(handsmth!I$2:I$28,$A7) -> 1 | ... N7: =COUNTIF(handsmth!N$2:N$28,$A7) -> 1 | P7: 6 | Q7: =B7-C7 -> 0 | R7: =C7-D7 -> 0 | S7: =D7-E7 -> -1 | T7: =E7-F7 -> 1 | U7: =F7-G7 -> 0 | V7: =G7-H7 -> 0 | W7: =H7-I7 -> 0 | X7: =I7-J7 -> 0 | ... AB7: =M7-N7 -> 0 | AE7: 6 | AF7: =B8-B7 -> 1 | AG7: =C8-C7 -> 1 | AH7: =D8-D7 -> 1 | AI7: =E8-E7 -> 0 | AJ7: =F8-F7 -> 1 | AK7: =G8-G7 -> 1 | AL7: =H8-H7 -> 1 | AM7: =I8-I7 -> 1 | ... AR7: =N8-N7 -> 0
A8: 7 | B8: =COUNTIF(handsmth!B$2:B$28,$A8) -> 2 | C8: =COUNTIF(handsmth!C$2:C$28,$A8) -> 2 | D8: =COUNTIF(handsmth!D$2:D$28,$A8) -> 2 | E8: =COUNTIF(handsmth!E$2:E$28,$A8) -> 2 | F8: =COUNTIF(handsmth!F$2:F$28,$A8) -> 2 | G8: =COUNTIF(handsmth!G$2:G$28,$A8) -> 2 | H8: =COUNTIF(handsmth!H$2:H$28,$A8) -> 2 | I8: =COUNTIF(handsmth!I$2:I$28,$A8) -> 2 | ... N8: =COUNTIF(handsmth!N$2:N$28,$A8) -> 1 | P8: 7 | Q8: =B8-C8 -> 0 | R8: =C8-D8 -> 0 | S8: =D8-E8 -> 0 | T8: =E8-F8 -> 0 | U8: =F8-G8 -> 0 | V8: =G8-H8 -> 0 | W8: =H8-I8 -> 0 | X8: =I8-J8 -> 0 | ... AB8: =M8-N8 -> 0 | AE8: 7 | AF8: =B9-B8 -> -1 | AG8: =C9-C8 -> -1 | AH8: =D9-D8 -> -1 | AI8: =E9-E8 -> -1 | AJ8: =F9-F8 -> 0 | AK8: =G9-G8 -> 0 | AL8: =H9-H8 -> -1 | AM8: =I9-I8 -> -1 | ... AR8: =N9-N8 -> 0
A9: 8 | B9: =COUNTIF(handsmth!B$2:B$28,$A9) -> 1 | C9: =COUNTIF(handsmth!C$2:C$28,$A9) -> 1 | D9: =COUNTIF(handsmth!D$2:D$28,$A9) -> 1 | E9: =COUNTIF(handsmth!E$2:E$28,$A9) -> 1 | F9: =COUNTIF(handsmth!F$2:F$28,$A9) -> 2 | G9: =COUNTIF(handsmth!G$2:G$28,$A9) -> 2 | H9: =COUNTIF(handsmth!H$2:H$28,$A9) -> 1 | I9: =COUNTIF(handsmth!I$2:I$28,$A9) -> 1 | ... N9: =COUNTIF(handsmth!N$2:N$28,$A9) -> 1 | P9: 8 | Q9: =B9-C9 -> 0 | R9: =C9-D9 -> 0 | S9: =D9-E9 -> 0 | T9: =E9-F9 -> -1 | U9: =F9-G9 -> 0 | V9: =G9-H9 -> 1 | W9: =H9-I9 -> 0 | X9: =I9-J9 -> -1 | ... AB9: =M9-N9 -> 0 | AE9: 8 | AF9: =B10-B9 -> 0 | AG9: =C10-C9 -> 0 | AH9: =D10-D9 -> 0 | AI9: =E10-E9 -> 0 | AJ9: =F10-F9 -> -1 | AK9: =G10-G9 -> -1 | AL9: =H10-H9 -> 1 | AM9: =I10-I9 -> 1 | ... AR9: =N10-N9 -> 0
A10: 9 | B10: =COUNTIF(handsmth!B$2:B$28,$A10) -> 1 | C10: =COUNTIF(handsmth!C$2:C$28,$A10) -> 1 | D10: =COUNTIF(handsmth!D$2:D$28,$A10) -> 1 | E10: =COUNTIF(handsmth!E$2:E$28,$A10) -> 1 | F10: =COUNTIF(handsmth!F$2:F$28,$A10) -> 1 | G10: =COUNTIF(handsmth!G$2:G$28,$A10) -> 1 | H10: =COUNTIF(handsmth!H$2:H$28,$A10) -> 2 | I10: =COUNTIF(handsmth!I$2:I$28,$A10) -> 2 | ... N10: =COUNTIF(handsmth!N$2:N$28,$A10) -> 1 | P10: 9 | Q10: =B10-C10 -> 0 | R10: =C10-D10 -> 0 | S10: =D10-E10 -> 0 | T10: =E10-F10 -> 0 | U10: =F10-G10 -> 0 | V10: =G10-H10 -> -1 | W10: =H10-I10 -> 0 | X10: =I10-J10 -> 1 | ... AB10: =M10-N10 -> 0 | AE10: 9 | AF10: =B11-B10 -> 1 | AG10: =C11-C10 -> 1 | AH10: =D11-D10 -> 1 | AI10: =E11-E10 -> 1 | AJ10: =F11-F10 -> 1 | AK10: =G11-G10 -> 1 | AL10: =H11-H10 -> -1 | AM10: =I11-I10 -> -1 | ... AR10: =N11-N10 -> 1
A11: 10 | B11: =COUNTIF(handsmth!B$2:B$28,$A11) -> 2 | C11: =COUNTIF(handsmth!C$2:C$28,$A11) -> 2 | D11: =COUNTIF(handsmth!D$2:D$28,$A11) -> 2 | E11: =COUNTIF(handsmth!E$2:E$28,$A11) -> 2 | F11: =COUNTIF(handsmth!F$2:F$28,$A11) -> 2 | G11: =COUNTIF(handsmth!G$2:G$28,$A11) -> 2 | H11: =COUNTIF(handsmth!H$2:H$28,$A11) -> 1 | I11: =COUNTIF(handsmth!I$2:I$28,$A11) -> 1 | ... N11: =COUNTIF(handsmth!N$2:N$28,$A11) -> 2 | P11: 10 | Q11: =B11-C11 -> 0 | R11: =C11-D11 -> 0 | S11: =D11-E11 -> 0 | T11: =E11-F11 -> 0 | U11: =F11-G11 -> 0 | V11: =G11-H11 -> 1 | W11: =H11-I11 -> 0 | X11: =I11-J11 -> -1 | ... AB11: =M11-N11 -> 0 | AE11: 10 | AF11: =B12-B11 -> -1 | AG11: =C12-C11 -> -1 | AH11: =D12-D11 -> -1 | AI11: =E12-E11 -> -1 | AJ11: =F12-F11 -> -1 | AK11: =G12-G11 -> -1 | AL11: =H12-H11 -> 0 | AM11: =I12-I11 -> 0 | ... AR11: =N12-N11 -> -1
A12: 11 | B12: =COUNTIF(handsmth!B$2:B$28,$A12) -> 1 | C12: =COUNTIF(handsmth!C$2:C$28,$A12) -> 1 | D12: =COUNTIF(handsmth!D$2:D$28,$A12) -> 1 | E12: =COUNTIF(handsmth!E$2:E$28,$A12) -> 1 | F12: =COUNTIF(handsmth!F$2:F$28,$A12) -> 1 | G12: =COUNTIF(handsmth!G$2:G$28,$A12) -> 1 | H12: =COUNTIF(handsmth!H$2:H$28,$A12) -> 1 | I12: =COUNTIF(handsmth!I$2:I$28,$A12) -> 1 | ... N12: =COUNTIF(handsmth!N$2:N$28,$A12) -> 1 | P12: 11 | Q12: =B12-C12 -> 0 | R12: =C12-D12 -> 0 | S12: =D12-E12 -> 0 | T12: =E12-F12 -> 0 | U12: =F12-G12 -> 0 | V12: =G12-H12 -> 0 | W12: =H12-I12 -> 0 | X12: =I12-J12 -> 0 | ... AB12: =M12-N12 -> 0 | AE12: 11 | AF12: =B13-B12 -> 0 | AG12: =C13-C12 -> 0 | AH12: =D13-D12 -> 0 | AI12: =E13-E12 -> 0 | AJ12: =F13-F12 -> 0 | AK12: =G13-G12 -> 0 | AL12: =H13-H12 -> 0 | AM12: =I13-I12 -> 0 | ... AR12: =N13-N12 -> 0
A13: 12 | B13: =COUNTIF(handsmth!B$2:B$28,$A13) -> 1 | C13: =COUNTIF(handsmth!C$2:C$28,$A13) -> 1 | D13: =COUNTIF(handsmth!D$2:D$28,$A13) -> 1 | E13: =COUNTIF(handsmth!E$2:E$28,$A13) -> 1 | F13: =COUNTIF(handsmth!F$2:F$28,$A13) -> 1 | G13: =COUNTIF(handsmth!G$2:G$28,$A13) -> 1 | H13: =COUNTIF(handsmth!H$2:H$28,$A13) -> 1 | I13: =COUNTIF(handsmth!I$2:I$28,$A13) -> 1 | ... N13: =COUNTIF(handsmth!N$2:N$28,$A13) -> 1 | P13: 12 | Q13: =B13-C13 -> 0 | R13: =C13-D13 -> 0 | S13: =D13-E13 -> 0 | T13: =E13-F13 -> 0 | U13: =F13-G13 -> 0 | V13: =G13-H13 -> 0 | W13: =H13-I13 -> 0 | X13: =I13-J13 -> 0 | ... AB13: =M13-N13 -> 0 | AE13: 12 | AF13: =B14-B13 -> 0 | AG13: =C14-C13 -> 0 | AH13: =D14-D13 -> 0 | AI13: =E14-E13 -> 0 | AJ13: =F14-F13 -> 0 | AK13: =G14-G13 -> 0 | AL13: =H14-H13 -> 1 | AM13: =I14-I13 -> 1 | ... AR13: =N14-N13 -> 1
... A19: 18 | B19: =COUNTIF(handsmth!B$2:B$28,$A19) -> 0 | C19: =COUNTIF(handsmth!C$2:C$28,$A19) -> 0 | D19: =COUNTIF(handsmth!D$2:D$28,$A19) -> 0 | E19: =COUNTIF(handsmth!E$2:E$28,$A19) -> 0 | F19: =COUNTIF(handsmth!F$2:F$28,$A19) -> 1 | G19: =COUNTIF(handsmth!G$2:G$28,$A19) -> 1 | H19: =COUNTIF(handsmth!H$2:H$28,$A19) -> 1 | I19: =COUNTIF(handsmth!I$2:I$28,$A19) -> 1 | ... N19: =COUNTIF(handsmth!N$2:N$28,$A19) -> 2 | P19: 18 | Q19: =B19-C19 -> 0 | R19: =C19-D19 -> 0 | S19: =D19-E19 -> 0 | T19: =E19-F19 -> -1 | U19: =F19-G19 -> 0 | V19: =G19-H19 -> 0 | W19: =H19-I19 -> 0 | X19: =I19-J19 -> -1 | ... AB19: =M19-N19 -> 0 | AE19: 18 | AF19: =B20-B19 -> 1 | AG19: =C20-C19 -> 1 | AH19: =D20-D19 -> 1 | AI19: =E20-E19 -> 1 | AJ19: =F20-F19 -> 0 | AK19: =G20-G19 -> 0 | AL19: =H20-H19 -> 0 | AM19: =I20-I19 -> 0 | ... AR19: =N20-N19 -> 1
A20: 19 | B20: =COUNTIF(handsmth!B$2:B$28,$A20) -> 1 | C20: =COUNTIF(handsmth!C$2:C$28,$A20) -> 1 | D20: =COUNTIF(handsmth!D$2:D$28,$A20) -> 1 | E20: =COUNTIF(handsmth!E$2:E$28,$A20) -> 1 | F20: =COUNTIF(handsmth!F$2:F$28,$A20) -> 1 | G20: =COUNTIF(handsmth!G$2:G$28,$A20) -> 1 | H20: =COUNTIF(handsmth!H$2:H$28,$A20) -> 1 | I20: =COUNTIF(handsmth!I$2:I$28,$A20) -> 1 | ... N20: =COUNTIF(handsmth!N$2:N$28,$A20) -> 3 | P20: 19 | Q20: =B20-C20 -> 0 | R20: =C20-D20 -> 0 | S20: =D20-E20 -> 0 | T20: =E20-F20 -> 0 | U20: =F20-G20 -> 0 | V20: =G20-H20 -> 0 | W20: =H20-I20 -> 0 | X20: =I20-J20 -> 0 | ... AB20: =M20-N20 -> 0

Sheet out
A1: =handsmth!A1 -> wais5_mr_raw | B1: =handsmth!B1 -> ss1 | C1: =handsmth!C1 -> ss2 | D1: =handsmth!D1 -> ss3 | E1: =handsmth!E1 -> ss4 | F1: =handsmth!F1 -> ss5 | G1: =handsmth!G1 -> ss6 | H1: =handsmth!H1 -> ss7 | ... N1: =handsmth!N1 -> ss13
A2: =handsmth!A2 -> 0 | B2: =handsmth!B2 -> 1 | C2: =handsmth!C2 -> 1 | D2: =handsmth!D2 -> 1 | E2: =handsmth!E2 -> 1 | F2: =handsmth!F2 -> 1 | G2: =handsmth!G2 -> 1 | H2: =handsmth!H2 -> 1 | ... N2: =handsmth!N2 -> 1
A3: =handsmth!A3 -> 1 | B3: =handsmth!B3 -> 1 | C3: =handsmth!C3 -> 1 | D3: =handsmth!D3 -> 1 | E3: =handsmth!E3 -> 1 | F3: =handsmth!F3 -> 1 | G3: =handsmth!G3 -> 1 | H3: =handsmth!H3 -> 1 | ... N3: =handsmth!N3 -> 2
A4: =handsmth!A4 -> 2 | B4: =handsmth!B4 -> 1 | C4: =handsmth!C4 -> 1 | D4: =handsmth!D4 -> 1 | E4: =handsmth!E4 -> 1 | F4: =handsmth!F4 -> 1 | G4: =handsmth!G4 -> 1 | H4: =handsmth!H4 -> 2 | ... N4: =handsmth!N4 -> 3
A5: =handsmth!A5 -> 3 | B5: =handsmth!B5 -> 2 | C5: =handsmth!C5 -> 2 | D5: =handsmth!D5 -> 2 | E5: =handsmth!E5 -> 2 | F5: =handsmth!F5 -> 2 | G5: =handsmth!G5 -> 2 | H5: =handsmth!H5 -> 2 | ... N5: =handsmth!N5 -> 4
A6: =handsmth!A6 -> 4 | B6: =handsmth!B6 -> 2 | C6: =handsmth!C6 -> 2 | D6: =handsmth!D6 -> 2 | E6: =handsmth!E6 -> 2 | F6: =handsmth!F6 -> 2 | G6: =handsmth!G6 -> 2 | H6: =handsmth!H6 -> 3 | ... N6: =handsmth!N6 -> 4
A7: =handsmth!A7 -> 5 | B7: =handsmth!B7 -> 2 | C7: =handsmth!C7 -> 2 | D7: =handsmth!D7 -> 2 | E7: =handsmth!E7 -> 2 | F7: =handsmth!F7 -> 3 | G7: =handsmth!G7 -> 3 | H7: =handsmth!H7 -> 3 | ... N7: =handsmth!N7 -> 5
A8: =handsmth!A8 -> 6 | B8: =handsmth!B8 -> 3 | C8: =handsmth!C8 -> 3 | D8: =handsmth!D8 -> 3 | E8: =handsmth!E8 -> 3 | F8: =handsmth!F8 -> 3 | G8: =handsmth!G8 -> 3 | H8: =handsmth!H8 -> 4 | ... N8: =handsmth!N8 -> 6
A9: =handsmth!A9 -> 7 | B9: =handsmth!B9 -> 3 | C9: =handsmth!C9 -> 3 | D9: =handsmth!D9 -> 3 | E9: =handsmth!E9 -> 3 | F9: =handsmth!F9 -> 4 | G9: =handsmth!G9 -> 4 | H9: =handsmth!H9 -> 4 | ... N9: =handsmth!N9 -> 7
A10: =handsmth!A10 -> 8 | B10: =handsmth!B10 -> 4 | C10: =handsmth!C10 -> 4 | D10: =handsmth!D10 -> 4 | E10: =handsmth!E10 -> 4 | F10: =handsmth!F10 -> 4 | G10: =handsmth!G10 -> 4 | H10: =handsmth!H10 -> 5 | ... N10: =handsmth!N10 -> 8
A11: =handsmth!A11 -> 9 | B11: =handsmth!B11 -> 4 | C11: =handsmth!C11 -> 4 | D11: =handsmth!D11 -> 4 | E11: =handsmth!E11 -> 4 | F11: =handsmth!F11 -> 5 | G11: =handsmth!G11 -> 5 | H11: =handsmth!H11 -> 5 | ... N11: =handsmth!N11 -> 9
A12: =handsmth!A12 -> 10 | B12: =handsmth!B12 -> 5 | C12: =handsmth!C12 -> 5 | D12: =handsmth!D12 -> 5 | E12: =handsmth!E12 -> 5 | F12: =handsmth!F12 -> 5 | G12: =handsmth!G12 -> 6 | H12: =handsmth!H12 -> 6 | ... N12: =handsmth!N12 -> 10
... A28: =handsmth!A28 -> 26 | B28: =handsmth!B28 -> 19 | C28: =handsmth!C28 -> 19 | D28: =handsmth!D28 -> 19 | E28: =handsmth!E28 -> 19 | F28: =handsmth!F28 -> 19 | G28: =handsmth!G28 -> 19 | H28: =handsmth!H28 -> 19 | ... N28: =handsmth!N28 -> 19

Sheet freq
A1: rawtot | B1: F_1 | C1: F_2 | D1: F_3 | E1: F_4 | F1: F_5 | G1: F_6 | H1: F_7 | I1: F_8 | J1: F_9 | K1: F_10 | L1: F_11 | M1: F_12 | N1: F_13
A2: 0
A3: 1 | D3: 1 | F3: 1 | I3: 2
A4: 2 | G4: 1 | I4: 1 | N4: 1
A5: 3 | I5: 1 | L5: 1
A6: 4 | H6: 1 | I6: 1 | J6: 3 | K6: 1 | L6: 1 | N6: 1
A7: 5 | D7: 1 | F7: 1 | G7: 1 | H7: 1 | K7: 3 | M7: 2
A8: 6 | B8: 1 | D8: 1 | F8: 4 | G8: 2 | H8: 1 | I8: 1 | J8: 4 | K8: 1 | L8: 3 | M8: 8 | N8: 10
A9: 7 | B9: 2 | C9: 1 | E9: 2 | G9: 4 | H9: 2 | I9: 9 | J9: 6 | K9: 3 | L9: 11 | M9: 10 | N9: 12
A10: 8 | B10: 3 | D10: 2 | F10: 2 | G10: 3 | H10: 2 | I10: 6 | J10: 6 | K10: 6 | L10: 7 | M10: 13 | N10: 9
A11: 9 | B11: 2 | C11: 3 | D11: 1 | E11: 2 | F11: 1 | G11: 3 | H11: 8 | I11: 8 | J11: 9 | K11: 6 | L11: 7 | M11: 8 | N11: 8
A12: 10 | B12: 1 | C12: 8 | E12: 4 | F12: 3 | G12: 7 | H12: 8 | I12: 11 | J12: 11 | K12: 7 | L12: 5 | M12: 9 | N12: 8
A13: 11 | B13: 10 | C13: 7 | D13: 4 | E13: 6 | F13: 3 | G13: 9 | H13: 2 | I13: 12 | J13: 13 | K13: 6 | L13: 7 | M13: 5 | N13: 4
A14: 12 | B14: 4 | C14: 2 | D14: 8 | E14: 2 | F14: 4 | G14: 6 | H14: 10 | I14: 11 | J14: 8 | K14: 10 | L14: 5 | M14: 4 | N14: 11
A15: 13 | B15: 4 | C15: 6 | D15: 7 | E15: 8 | F15: 7 | G15: 6 | H15: 9 | I15: 11 | J15: 14 | K15: 9 | L15: 5 | M15: 5 | N15: 5
A16: 14 | B16: 17 | C16: 10 | D16: 16 | E16: 7 | F16: 9 | G16: 9 | H16: 13 | I16: 8 | J16: 10 | K16: 6 | L16: 5 | M16: 6 | N16: 9
A17: 15 | B17: 13 | C17: 11 | D17: 16 | E17: 14 | F17: 11 | G17: 10 | H17: 20 | I17: 17 | J17: 15 | K17: 7 | L17: 9 | M17: 6 | N17: 2
A18: 16 | B18: 17 | C18: 17 | D18: 12 | E18: 8 | F18: 15 | G18: 10 | H18: 18 | I18: 13 | J18: 19 | K18: 6 | L18: 9 | M18: 10 | N18: 5
A19: 17 | B19: 22 | C19: 19 | D19: 21 | E19: 23 | F19: 15 | G19: 18 | H19: 15 | I19: 18 | J19: 13 | K19: 6 | L19: 5 | M19: 3 | N19: 7
A20: 18 | B20: 20 | C20: 11 | D20: 21 | E20: 24 | F20: 22 | G20: 20 | H20: 12 | I20: 16 | J20: 22 | K20: 8 | L20: 7 | M20: 4
A21: 19 | B21: 17 | C21: 28 | D21: 20 | E21: 27 | F21: 21 | G21: 24 | H21: 23 | I21: 13 | J21: 10 | K21: 7 | L21: 5 | M21: 2 | N21: 1
A22: 20 | B22: 21 | C22: 24 | D22: 21 | E22: 20 | F22: 28 | G22: 30 | H22: 11 | I22: 11 | J22: 7 | K22: 5 | L22: 5 | M22: 3 | N22: 3
A23: 21 | B23: 18 | C23: 14 | D23: 13 | E23: 15 | F23: 14 | G23: 7 | H23: 12 | I23: 6 | J23: 5 | K23: 3 | L23: 1 | M23: 1
A24: 22 | B24: 6 | C24: 6 | D24: 8 | E24: 15 | F24: 11 | G24: 5 | H24: 9 | I24: 3 | J24: 3 | L24: 2
A25: 23 | C25: 7 | D25: 4 | F25: 2 | G25: 3 | H25: 2 | J25: 1
A26: 24 | B26: 2 | C26: 5 | D26: 3 | E26: 1 | F26: 2 | G26: 2 | J26: 1
A27: 25 | F27: 2 | H27: 1
A28: 26 | F28: 1
